dv - | INFO flwr 2024-10-23 14:14:30,217 | server_app.py:88 | file writing: True
dv - | INFO flwr 2024-10-23 14:14:30,218 | server_app.py:89 | running in fed_acc
dv - | INFO flwr 2024-10-23 14:14:30,218 | server_app.py:90 | min num clients 2
dv - | INFO flwr 2024-10-23 14:14:30,218 | server_app.py:91 | num server rounds 1
dv - | INFO flwr 2024-10-23 14:14:30,218 | server_app.py:92 | config num local epochs 1
dv - | INFO flwr 2024-10-23 14:14:30,219 | server_app.py:93 | advanced logging False
dv - | INFO flwr 2024-10-23 14:14:30,219 | server_app.py:94 | partition: iid
dv - | INFO flwr 2024-10-23 14:14:30,220 | app.py:74 | Starting Flower ServerApp, config: num_rounds=1, no round_timeout
dv - | INFO flwr 2024-10-23 14:14:30,220 | app.py:79 | 
dv - | INFO flwr 2024-10-23 14:14:30,221 | server.py:92 | [INIT]
dv - | INFO flwr 2024-10-23 14:14:30,222 | server.py:277 | Using initial global parameters provided by strategy
dv - | INFO flwr 2024-10-23 14:14:30,222 | server.py:94 | Starting evaluation of initial global parameters
dv - | INFO flwr 2024-10-23 14:14:30,222 | server.py:106 | Evaluation returned no results (`None`)
dv - | INFO flwr 2024-10-23 14:14:30,223 | server.py:112 | 
dv - | INFO flwr 2024-10-23 14:14:30,223 | server.py:113 | [ROUND 1]
dv - | INFO flwr 2024-10-23 14:14:30,224 | server.py:226 | configure_fit: strategy sampled 3 clients (out of 3)
dv - | DEBUG flwr 2024-10-23 14:14:34,232 | raybackend.py:136 | Constructed ActorPool with: 4 actors
dv - | DEBUG flwr 2024-10-23 14:14:34,233 | state_factory.py:50 | Using InMemoryState
dv - | INFO flwr 2024-10-23 14:15:15,595 | server.py:240 | aggregate_fit: received 3 results and 0 failures
dv - | ERROR flwr 2024-10-23 14:15:15,600 | run_simulation.py:344 | ServerApp thread raised an exception: 'labels'
dv - | ERROR flwr 2024-10-23 14:15:15,663 | run_simulation.py:345 | Traceback (most recent call last):
  File "C:\Users\hughj\Documents\GitHub\asfl\env\lib\site-packages\flwr\simulation\run_simulation.py", line 336, in server_th_with_start_checks
    run_server_app(
  File "C:\Users\hughj\Documents\GitHub\asfl\env\lib\site-packages\flwr\server\run_serverapp.py", line 88, in run
    server_app(driver=driver, context=context)
  File "C:\Users\hughj\Documents\GitHub\asfl\env\lib\site-packages\flwr\server\server_app.py", line 120, in __call__
    start_driver(
  File "C:\Users\hughj\Documents\GitHub\asfl\env\lib\site-packages\flwr\server\compat\app.py", line 87, in start_driver
    hist = run_fl(
  File "C:\Users\hughj\Documents\GitHub\asfl\env\lib\site-packages\flwr\server\server.py", line 492, in run_fl
    hist, elapsed_time = server.fit(
  File "C:\Users\hughj\Documents\GitHub\asfl\env\lib\site-packages\flwr\server\server.py", line 115, in fit
    res_fit = self.fit_round(
  File "C:\Users\hughj\Documents\GitHub\asfl\env\lib\site-packages\flwr\server\server.py", line 251, in fit_round
    ] = self.strategy.aggregate_fit(server_round, results, failures)
  File "C:\Users\hughj\Documents\GitHub\asfl\asfl\strats\fed_acc.py", line 48, in aggregate_fit
    log(INFO, str(metrics['labels']))
  File "C:\Users\hughj\Documents\GitHub\asfl\env\lib\site-packages\flwr\common\record\typeddict.py", line 49, in __getitem__
    return cast(Dict[K, V], self.__dict__["_data"])[item]
KeyError: 'labels'

dv - | DEBUG flwr 2024-10-23 14:15:15,668 | run_simulation.py:349 | ServerApp finished running.
dv - | DEBUG flwr 2024-10-23 14:15:15,668 | run_simulation.py:353 | Triggered stop event for Simulation Engine.
dv - | DEBUG flwr 2024-10-23 14:15:16,603 | ray_actor.py:450 | Terminated 4 actors
dv - | DEBUG flwr 2024-10-23 14:15:17,290 | raybackend.py:184 | Terminated RayBackend
dv - | INFO flwr 2024-10-23 14:15:46,743 | server_app.py:88 | file writing: True
dv - | INFO flwr 2024-10-23 14:15:46,743 | server_app.py:89 | running in fed_acc
dv - | INFO flwr 2024-10-23 14:15:46,744 | server_app.py:90 | min num clients 2
dv - | INFO flwr 2024-10-23 14:15:46,744 | server_app.py:91 | num server rounds 1
dv - | INFO flwr 2024-10-23 14:15:46,744 | server_app.py:92 | config num local epochs 1
dv - | INFO flwr 2024-10-23 14:15:46,744 | server_app.py:93 | advanced logging False
dv - | INFO flwr 2024-10-23 14:15:46,746 | server_app.py:94 | partition: iid
dv - | INFO flwr 2024-10-23 14:15:46,746 | app.py:74 | Starting Flower ServerApp, config: num_rounds=1, no round_timeout
dv - | INFO flwr 2024-10-23 14:15:46,746 | app.py:79 | 
dv - | INFO flwr 2024-10-23 14:15:46,747 | server.py:92 | [INIT]
dv - | INFO flwr 2024-10-23 14:15:46,748 | server.py:277 | Using initial global parameters provided by strategy
dv - | INFO flwr 2024-10-23 14:15:46,748 | server.py:94 | Starting evaluation of initial global parameters
dv - | INFO flwr 2024-10-23 14:15:46,751 | server.py:106 | Evaluation returned no results (`None`)
dv - | INFO flwr 2024-10-23 14:15:46,751 | server.py:112 | 
dv - | INFO flwr 2024-10-23 14:15:46,752 | server.py:113 | [ROUND 1]
dv - | INFO flwr 2024-10-23 14:15:46,752 | server.py:226 | configure_fit: strategy sampled 3 clients (out of 3)
dv - | DEBUG flwr 2024-10-23 14:15:50,550 | raybackend.py:136 | Constructed ActorPool with: 4 actors
dv - | DEBUG flwr 2024-10-23 14:15:50,550 | state_factory.py:50 | Using InMemoryState
dv - | INFO flwr 2024-10-23 14:16:35,002 | server.py:240 | aggregate_fit: received 3 results and 0 failures
dv - | INFO flwr 2024-10-23 14:16:35,007 | fed_acc.py:48 | 5
dv - | INFO flwr 2024-10-23 14:16:35,008 | fed_acc.py:48 | 5
dv - | INFO flwr 2024-10-23 14:16:35,009 | fed_acc.py:48 | 5
dv - | INFO flwr 2024-10-23 14:16:35,009 | dat.py:19 | weighted test: [0.10557888422315537, 0.10827834433113377, 0.10377924415116976]
dv - | INFO flwr 2024-10-23 14:16:35,049 | server.py:178 | configure_evaluate: strategy sampled 3 clients (out of 3)
dv - | INFO flwr 2024-10-23 14:16:38,086 | server.py:192 | aggregate_evaluate: received 3 results and 0 failures
dv - | INFO flwr 2024-10-23 14:16:38,087 | fed_custom.py:227 | aggregated accuracy: 0.10087982403519297
dv - | INFO flwr 2024-10-23 14:16:38,088 | server.py:496 | 
dv - | INFO flwr 2024-10-23 14:16:38,089 | server.py:497 | [SUMMARY]
dv - | INFO flwr 2024-10-23 14:16:38,090 | server.py:498 | Run finished 1 round(s) in 51.34s
dv - | INFO flwr 2024-10-23 14:16:38,091 | server.py:500 | 	History (loss, distributed):
dv - | INFO flwr 2024-10-23 14:16:38,092 | server.py:500 | 		round 1: 241.2993487517039
dv - | INFO flwr 2024-10-23 14:16:38,093 | server.py:500 | 	History (metrics, distributed, evaluate):
dv - | INFO flwr 2024-10-23 14:16:38,093 | server.py:500 | 	{'accuracy': [(1, 0.10087982403519297)], 'count': [(1, 3)]}
dv - | INFO flwr 2024-10-23 14:16:38,094 | server.py:501 | 
dv - | DEBUG flwr 2024-10-23 14:16:38,097 | run_serverapp.py:90 | ServerApp finished running.
dv - | DEBUG flwr 2024-10-23 14:16:38,097 | run_simulation.py:349 | ServerApp finished running.
dv - | DEBUG flwr 2024-10-23 14:16:38,098 | run_simulation.py:353 | Triggered stop event for Simulation Engine.
dv - | DEBUG flwr 2024-10-23 14:16:39,002 | ray_actor.py:450 | Terminated 4 actors
dv - | DEBUG flwr 2024-10-23 14:16:39,627 | raybackend.py:184 | Terminated RayBackend
dv - | DEBUG flwr 2024-10-23 14:16:39,627 | run_simulation.py:452 | Stopping Simulation Engine now.
dv - | INFO flwr 2024-10-23 14:29:26,038 | server_app.py:88 | file writing: True
dv - | INFO flwr 2024-10-23 14:29:26,039 | server_app.py:89 | running in fed_acc
dv - | INFO flwr 2024-10-23 14:29:26,040 | server_app.py:90 | min num clients 2
dv - | INFO flwr 2024-10-23 14:29:26,040 | server_app.py:91 | num server rounds 1
dv - | INFO flwr 2024-10-23 14:29:26,042 | server_app.py:92 | config num local epochs 1
dv - | INFO flwr 2024-10-23 14:29:26,042 | server_app.py:93 | advanced logging False
dv - | INFO flwr 2024-10-23 14:29:26,043 | server_app.py:94 | partition: iid
dv - | INFO flwr 2024-10-23 14:29:26,044 | app.py:74 | Starting Flower ServerApp, config: num_rounds=1, no round_timeout
dv - | INFO flwr 2024-10-23 14:29:26,045 | app.py:79 | 
dv - | INFO flwr 2024-10-23 14:29:26,047 | server.py:92 | [INIT]
dv - | INFO flwr 2024-10-23 14:29:26,048 | server.py:277 | Using initial global parameters provided by strategy
dv - | INFO flwr 2024-10-23 14:29:26,049 | server.py:94 | Starting evaluation of initial global parameters
dv - | INFO flwr 2024-10-23 14:29:26,050 | server.py:106 | Evaluation returned no results (`None`)
dv - | INFO flwr 2024-10-23 14:29:26,059 | server.py:112 | 
dv - | INFO flwr 2024-10-23 14:29:26,061 | server.py:113 | [ROUND 1]
dv - | INFO flwr 2024-10-23 14:29:26,061 | server.py:226 | configure_fit: strategy sampled 3 clients (out of 3)
dv - | DEBUG flwr 2024-10-23 14:29:30,258 | raybackend.py:136 | Constructed ActorPool with: 4 actors
dv - | DEBUG flwr 2024-10-23 14:29:30,258 | state_factory.py:50 | Using InMemoryState
dv - | INFO flwr 2024-10-23 14:30:59,525 | server_app.py:88 | file writing: True
dv - | INFO flwr 2024-10-23 14:30:59,526 | server_app.py:89 | running in fed_acc
dv - | INFO flwr 2024-10-23 14:30:59,526 | server_app.py:90 | min num clients 2
dv - | INFO flwr 2024-10-23 14:30:59,527 | server_app.py:91 | num server rounds 1
dv - | INFO flwr 2024-10-23 14:30:59,527 | server_app.py:92 | config num local epochs 1
dv - | INFO flwr 2024-10-23 14:30:59,527 | server_app.py:93 | advanced logging False
dv - | INFO flwr 2024-10-23 14:30:59,528 | server_app.py:94 | partition: iid
dv - | INFO flwr 2024-10-23 14:30:59,528 | app.py:74 | Starting Flower ServerApp, config: num_rounds=1, no round_timeout
dv - | INFO flwr 2024-10-23 14:30:59,535 | app.py:79 | 
dv - | INFO flwr 2024-10-23 14:30:59,537 | server.py:92 | [INIT]
dv - | INFO flwr 2024-10-23 14:30:59,537 | server.py:277 | Using initial global parameters provided by strategy
dv - | INFO flwr 2024-10-23 14:30:59,538 | server.py:94 | Starting evaluation of initial global parameters
dv - | INFO flwr 2024-10-23 14:30:59,538 | server.py:106 | Evaluation returned no results (`None`)
dv - | INFO flwr 2024-10-23 14:30:59,540 | server.py:112 | 
dv - | INFO flwr 2024-10-23 14:30:59,541 | server.py:113 | [ROUND 1]
dv - | INFO flwr 2024-10-23 14:30:59,542 | server.py:226 | configure_fit: strategy sampled 3 clients (out of 3)
dv - | DEBUG flwr 2024-10-23 14:31:03,484 | raybackend.py:136 | Constructed ActorPool with: 4 actors
dv - | DEBUG flwr 2024-10-23 14:31:03,484 | state_factory.py:50 | Using InMemoryState
dv - | INFO flwr 2024-10-23 14:31:42,843 | server.py:240 | aggregate_fit: received 3 results and 0 failures
dv - | INFO flwr 2024-10-23 14:31:42,845 | fed_acc.py:48 | 5
dv - | INFO flwr 2024-10-23 14:31:42,845 | fed_acc.py:48 | 5
dv - | INFO flwr 2024-10-23 14:31:42,846 | fed_acc.py:48 | 5
dv - | INFO flwr 2024-10-23 14:31:42,846 | dat.py:19 | weighted test: [0.11217756448710257, 0.10137972405518897, 0.10167966406718656]
dv - | INFO flwr 2024-10-23 14:31:42,847 | server.py:178 | configure_evaluate: strategy sampled 3 clients (out of 3)
dv - | INFO flwr 2024-10-23 14:31:44,868 | server.py:192 | aggregate_evaluate: received 3 results and 0 failures
dv - | INFO flwr 2024-10-23 14:31:44,869 | fed_custom.py:227 | aggregated accuracy: 0.1251749650069986
dv - | INFO flwr 2024-10-23 14:31:44,869 | server.py:496 | 
dv - | INFO flwr 2024-10-23 14:31:44,870 | server.py:497 | [SUMMARY]
dv - | INFO flwr 2024-10-23 14:31:44,870 | server.py:498 | Run finished 1 round(s) in 45.33s
dv - | INFO flwr 2024-10-23 14:31:44,870 | server.py:500 | 	History (loss, distributed):
dv - | INFO flwr 2024-10-23 14:31:44,870 | server.py:500 | 		round 1: 241.44557444254556
dv - | INFO flwr 2024-10-23 14:31:44,871 | server.py:500 | 	History (metrics, distributed, evaluate):
dv - | INFO flwr 2024-10-23 14:31:44,871 | server.py:500 | 	{'accuracy': [(1, 0.1251749650069986)], 'count': [(1, 3)]}
dv - | INFO flwr 2024-10-23 14:31:44,871 | server.py:501 | 
dv - | DEBUG flwr 2024-10-23 14:31:44,873 | run_serverapp.py:90 | ServerApp finished running.
dv - | DEBUG flwr 2024-10-23 14:31:44,873 | run_simulation.py:349 | ServerApp finished running.
dv - | DEBUG flwr 2024-10-23 14:31:44,873 | run_simulation.py:353 | Triggered stop event for Simulation Engine.
dv - | DEBUG flwr 2024-10-23 14:31:45,335 | ray_actor.py:450 | Terminated 4 actors
dv - | DEBUG flwr 2024-10-23 14:31:45,979 | raybackend.py:184 | Terminated RayBackend
dv - | DEBUG flwr 2024-10-23 14:31:45,980 | run_simulation.py:452 | Stopping Simulation Engine now.
dv - | INFO flwr 2024-10-23 14:41:51,923 | server_app.py:88 | file writing: True
dv - | INFO flwr 2024-10-23 14:41:51,923 | server_app.py:89 | running in fed_acc
dv - | INFO flwr 2024-10-23 14:41:51,924 | server_app.py:90 | min num clients 2
dv - | INFO flwr 2024-10-23 14:41:51,924 | server_app.py:91 | num server rounds 1
dv - | INFO flwr 2024-10-23 14:41:51,925 | server_app.py:92 | config num local epochs 1
dv - | INFO flwr 2024-10-23 14:41:51,925 | server_app.py:93 | advanced logging False
dv - | INFO flwr 2024-10-23 14:41:51,926 | server_app.py:94 | partition: iid
dv - | INFO flwr 2024-10-23 14:41:51,926 | app.py:74 | Starting Flower ServerApp, config: num_rounds=1, no round_timeout
dv - | INFO flwr 2024-10-23 14:41:51,928 | app.py:79 | 
dv - | INFO flwr 2024-10-23 14:41:51,929 | server.py:92 | [INIT]
dv - | INFO flwr 2024-10-23 14:41:51,930 | server.py:277 | Using initial global parameters provided by strategy
dv - | INFO flwr 2024-10-23 14:41:51,930 | server.py:94 | Starting evaluation of initial global parameters
dv - | INFO flwr 2024-10-23 14:41:51,931 | server.py:106 | Evaluation returned no results (`None`)
dv - | INFO flwr 2024-10-23 14:41:51,931 | server.py:112 | 
dv - | INFO flwr 2024-10-23 14:41:51,932 | server.py:113 | [ROUND 1]
dv - | INFO flwr 2024-10-23 14:41:51,932 | server.py:226 | configure_fit: strategy sampled 3 clients (out of 3)
dv - | DEBUG flwr 2024-10-23 14:41:55,092 | raybackend.py:136 | Constructed ActorPool with: 4 actors
dv - | DEBUG flwr 2024-10-23 14:41:55,092 | state_factory.py:50 | Using InMemoryState
dv - | INFO flwr 2024-10-23 14:42:24,306 | server.py:240 | aggregate_fit: received 3 results and 0 failures
dv - | INFO flwr 2024-10-23 14:42:24,308 | fed_acc.py:48 | 4
dv - | INFO flwr 2024-10-23 14:42:24,309 | fed_acc.py:48 | 4
dv - | INFO flwr 2024-10-23 14:42:24,310 | fed_acc.py:48 | 4
dv - | INFO flwr 2024-10-23 14:42:24,311 | dat.py:19 | weighted test: [0.16256748650269945, 0.15686862627474504, 0.14187162567486503]
dv - | INFO flwr 2024-10-23 14:42:24,313 | server.py:178 | configure_evaluate: strategy sampled 3 clients (out of 3)
dv - | INFO flwr 2024-10-23 14:42:26,338 | server.py:192 | aggregate_evaluate: received 3 results and 0 failures
dv - | INFO flwr 2024-10-23 14:42:26,339 | fed_custom.py:227 | aggregated accuracy: 0.16026794641071784
dv - | INFO flwr 2024-10-23 14:42:26,340 | server.py:496 | 
dv - | INFO flwr 2024-10-23 14:42:26,341 | server.py:497 | [SUMMARY]
dv - | INFO flwr 2024-10-23 14:42:26,342 | server.py:498 | Run finished 1 round(s) in 34.41s
dv - | INFO flwr 2024-10-23 14:42:26,343 | server.py:500 | 	History (loss, distributed):
dv - | INFO flwr 2024-10-23 14:42:26,343 | server.py:500 | 		round 1: 241.20342779159546
dv - | INFO flwr 2024-10-23 14:42:26,344 | server.py:500 | 	History (metrics, distributed, evaluate):
dv - | INFO flwr 2024-10-23 14:42:26,344 | server.py:500 | 	{'accuracy': [(1, 0.16026794641071784)], 'count': [(1, 3)]}
dv - | INFO flwr 2024-10-23 14:42:26,344 | server.py:501 | 
dv - | DEBUG flwr 2024-10-23 14:42:26,347 | run_serverapp.py:90 | ServerApp finished running.
dv - | DEBUG flwr 2024-10-23 14:42:26,347 | run_simulation.py:349 | ServerApp finished running.
dv - | DEBUG flwr 2024-10-23 14:42:26,347 | run_simulation.py:353 | Triggered stop event for Simulation Engine.
dv - | DEBUG flwr 2024-10-23 14:42:26,820 | ray_actor.py:450 | Terminated 4 actors
dv - | DEBUG flwr 2024-10-23 14:42:27,415 | raybackend.py:184 | Terminated RayBackend
dv - | DEBUG flwr 2024-10-23 14:42:27,416 | run_simulation.py:452 | Stopping Simulation Engine now.
dv - | INFO flwr 2024-10-23 14:47:34,596 | server_app.py:88 | file writing: True
dv - | INFO flwr 2024-10-23 14:47:34,596 | server_app.py:89 | running in fed_acc
dv - | INFO flwr 2024-10-23 14:47:34,597 | server_app.py:90 | min num clients 2
dv - | INFO flwr 2024-10-23 14:47:34,597 | server_app.py:91 | num server rounds 1
dv - | INFO flwr 2024-10-23 14:47:34,597 | server_app.py:92 | config num local epochs 1
dv - | INFO flwr 2024-10-23 14:47:34,598 | server_app.py:93 | advanced logging False
dv - | INFO flwr 2024-10-23 14:47:34,598 | server_app.py:94 | partition: iid
dv - | INFO flwr 2024-10-23 14:47:34,598 | app.py:74 | Starting Flower ServerApp, config: num_rounds=1, no round_timeout
dv - | INFO flwr 2024-10-23 14:47:34,599 | app.py:79 | 
dv - | INFO flwr 2024-10-23 14:47:34,599 | server.py:92 | [INIT]
dv - | INFO flwr 2024-10-23 14:47:34,599 | server.py:277 | Using initial global parameters provided by strategy
dv - | INFO flwr 2024-10-23 14:47:34,600 | server.py:94 | Starting evaluation of initial global parameters
dv - | INFO flwr 2024-10-23 14:47:34,600 | server.py:106 | Evaluation returned no results (`None`)
dv - | INFO flwr 2024-10-23 14:47:34,601 | server.py:112 | 
dv - | INFO flwr 2024-10-23 14:47:34,601 | server.py:113 | [ROUND 1]
dv - | INFO flwr 2024-10-23 14:47:34,602 | server.py:226 | configure_fit: strategy sampled 3 clients (out of 3)
dv - | DEBUG flwr 2024-10-23 14:47:37,599 | raybackend.py:136 | Constructed ActorPool with: 4 actors
dv - | DEBUG flwr 2024-10-23 14:47:37,600 | state_factory.py:50 | Using InMemoryState
dv - | INFO flwr 2024-10-23 14:48:04,856 | server.py:240 | aggregate_fit: received 3 results and 0 failures
dv - | INFO flwr 2024-10-23 14:48:04,859 | fed_acc.py:48 | 4
dv - | INFO flwr 2024-10-23 14:48:04,860 | fed_acc.py:48 | 4
dv - | INFO flwr 2024-10-23 14:48:04,861 | fed_acc.py:48 | 4
dv - | INFO flwr 2024-10-23 14:48:04,861 | dat.py:19 | weighted test: [0.15686862627474504, 0.16916616676664667, 0.17246550689862028]
dv - | INFO flwr 2024-10-23 14:48:04,863 | server.py:178 | configure_evaluate: strategy sampled 3 clients (out of 3)
dv - | INFO flwr 2024-10-23 14:48:06,890 | server.py:192 | aggregate_evaluate: received 3 results and 0 failures
dv - | INFO flwr 2024-10-23 14:48:06,892 | fed_custom.py:227 | aggregated accuracy: 0.17796440711857628
dv - | INFO flwr 2024-10-23 14:48:06,892 | server.py:496 | 
dv - | INFO flwr 2024-10-23 14:48:06,893 | server.py:497 | [SUMMARY]
dv - | INFO flwr 2024-10-23 14:48:06,893 | server.py:498 | Run finished 1 round(s) in 32.29s
dv - | INFO flwr 2024-10-23 14:48:06,894 | server.py:500 | 	History (loss, distributed):
dv - | INFO flwr 2024-10-23 14:48:06,894 | server.py:500 | 		round 1: 241.10607544581094
dv - | INFO flwr 2024-10-23 14:48:06,895 | server.py:500 | 	History (metrics, distributed, evaluate):
dv - | INFO flwr 2024-10-23 14:48:06,895 | server.py:500 | 	{'accuracy': [(1, 0.17796440711857628)], 'count': [(1, 3)]}
dv - | INFO flwr 2024-10-23 14:48:06,896 | server.py:501 | 
dv - | DEBUG flwr 2024-10-23 14:48:06,899 | run_serverapp.py:90 | ServerApp finished running.
dv - | DEBUG flwr 2024-10-23 14:48:06,899 | run_simulation.py:349 | ServerApp finished running.
dv - | DEBUG flwr 2024-10-23 14:48:06,899 | run_simulation.py:353 | Triggered stop event for Simulation Engine.
dv - | DEBUG flwr 2024-10-23 14:48:07,894 | ray_actor.py:450 | Terminated 4 actors
dv - | DEBUG flwr 2024-10-23 14:48:08,657 | raybackend.py:184 | Terminated RayBackend
dv - | DEBUG flwr 2024-10-23 14:48:08,658 | run_simulation.py:452 | Stopping Simulation Engine now.
dv - | INFO flwr 2024-10-23 14:49:22,072 | server_app.py:88 | file writing: True
dv - | INFO flwr 2024-10-23 14:49:22,073 | server_app.py:89 | running in fed_acc
dv - | INFO flwr 2024-10-23 14:49:22,073 | server_app.py:90 | min num clients 2
dv - | INFO flwr 2024-10-23 14:49:22,073 | server_app.py:91 | num server rounds 1
dv - | INFO flwr 2024-10-23 14:49:22,073 | server_app.py:92 | config num local epochs 1
dv - | INFO flwr 2024-10-23 14:49:22,074 | server_app.py:93 | advanced logging False
dv - | INFO flwr 2024-10-23 14:49:22,074 | server_app.py:94 | partition: dirlichet
dv - | INFO flwr 2024-10-23 14:49:22,074 | app.py:74 | Starting Flower ServerApp, config: num_rounds=1, no round_timeout
dv - | INFO flwr 2024-10-23 14:49:22,074 | app.py:79 | 
dv - | INFO flwr 2024-10-23 14:49:22,076 | server.py:92 | [INIT]
dv - | INFO flwr 2024-10-23 14:49:22,077 | server.py:277 | Using initial global parameters provided by strategy
dv - | INFO flwr 2024-10-23 14:49:22,078 | server.py:94 | Starting evaluation of initial global parameters
dv - | INFO flwr 2024-10-23 14:49:22,078 | server.py:106 | Evaluation returned no results (`None`)
dv - | INFO flwr 2024-10-23 14:49:22,080 | server.py:112 | 
dv - | INFO flwr 2024-10-23 14:49:22,080 | server.py:113 | [ROUND 1]
dv - | INFO flwr 2024-10-23 14:49:22,081 | server.py:226 | configure_fit: strategy sampled 3 clients (out of 3)
dv - | DEBUG flwr 2024-10-23 14:49:25,637 | raybackend.py:136 | Constructed ActorPool with: 4 actors
dv - | DEBUG flwr 2024-10-23 14:49:25,637 | state_factory.py:50 | Using InMemoryState
dv - | ERROR flwr 2024-10-23 14:49:32,283 | raybackend.py:171 | An exception was raised when processing a message by RayBackend
dv - | ERROR flwr 2024-10-23 14:49:32,284 | raybackend.py:171 | An exception was raised when processing a message by RayBackend
dv - | ERROR flwr 2024-10-23 14:49:32,284 | vce_api.py:123 | [36mray::ClientAppActor.run()[39m (pid=7592, ip=127.0.0.1, actor_id=421e763c9414f647b864e34701000000, repr=<flwr.simulation.ray_transport.ray_actor.ClientAppActor object at 0x0000024C836E0940>)
  File "C:\Users\hughj\Documents\GitHub\asfl\env\lib\site-packages\flwr\client\client_app.py", line 143, in __call__
    return self._call(message, context)
  File "C:\Users\hughj\Documents\GitHub\asfl\env\lib\site-packages\flwr\client\client_app.py", line 126, in ffn
    out_message = handle_legacy_message_from_msgtype(
  File "C:\Users\hughj\Documents\GitHub\asfl\env\lib\site-packages\flwr\client\message_handler\message_handler.py", line 95, in handle_legacy_message_from_msgtype
    client = client_fn(context)
  File "C:\Users\hughj\Documents\GitHub\asfl\asfl\client_app.py", line 80, in client_fn
    trainloader, valloader = load_data(context.run_config, partition_id, num_partitions)
  File "C:\Users\hughj\Documents\GitHub\asfl\asfl\task.py", line 72, in load_data
    raise ValueError("Invalid partitioner")
ValueError: Invalid partitioner

The above exception was the direct cause of the following exception:

[36mray::ClientAppActor.run()[39m (pid=7592, ip=127.0.0.1, actor_id=421e763c9414f647b864e34701000000, repr=<flwr.simulation.ray_transport.ray_actor.ClientAppActor object at 0x0000024C836E0940>)
  File "python\ray\_raylet.pyx", line 1883, in ray._raylet.execute_task
  File "python\ray\_raylet.pyx", line 1984, in ray._raylet.execute_task
  File "python\ray\_raylet.pyx", line 1889, in ray._raylet.execute_task
  File "python\ray\_raylet.pyx", line 1830, in ray._raylet.execute_task.function_executor
  File "C:\Users\hughj\Documents\GitHub\asfl\env\lib\site-packages\ray\_private\function_manager.py", line 724, in actor_method_executor
    return method(__ray_actor, *args, **kwargs)
  File "C:\Users\hughj\Documents\GitHub\asfl\env\lib\site-packages\ray\util\tracing\tracing_helper.py", line 467, in _resume_span
    return method(self, *_args, **_kwargs)
  File "C:\Users\hughj\Documents\GitHub\asfl\env\lib\site-packages\flwr\simulation\ray_transport\ray_actor.py", line 63, in run
    raise ClientAppException(str(ex)) from ex
flwr.client.client_app.ClientAppException: 
Exception ClientAppException occurred. Message: Invalid partitioner
dv - | ERROR flwr 2024-10-23 14:49:32,284 | vce_api.py:123 | [36mray::ClientAppActor.run()[39m (pid=9248, ip=127.0.0.1, actor_id=79377813a47c6c0562b20fe201000000, repr=<flwr.simulation.ray_transport.ray_actor.ClientAppActor object at 0x0000017E6D7B0940>)
  File "C:\Users\hughj\Documents\GitHub\asfl\env\lib\site-packages\flwr\client\client_app.py", line 143, in __call__
    return self._call(message, context)
  File "C:\Users\hughj\Documents\GitHub\asfl\env\lib\site-packages\flwr\client\client_app.py", line 126, in ffn
    out_message = handle_legacy_message_from_msgtype(
  File "C:\Users\hughj\Documents\GitHub\asfl\env\lib\site-packages\flwr\client\message_handler\message_handler.py", line 95, in handle_legacy_message_from_msgtype
    client = client_fn(context)
  File "C:\Users\hughj\Documents\GitHub\asfl\asfl\client_app.py", line 80, in client_fn
    trainloader, valloader = load_data(context.run_config, partition_id, num_partitions)
  File "C:\Users\hughj\Documents\GitHub\asfl\asfl\task.py", line 72, in load_data
    raise ValueError("Invalid partitioner")
ValueError: Invalid partitioner

The above exception was the direct cause of the following exception:

[36mray::ClientAppActor.run()[39m (pid=9248, ip=127.0.0.1, actor_id=79377813a47c6c0562b20fe201000000, repr=<flwr.simulation.ray_transport.ray_actor.ClientAppActor object at 0x0000017E6D7B0940>)
  File "python\ray\_raylet.pyx", line 1883, in ray._raylet.execute_task
  File "python\ray\_raylet.pyx", line 1984, in ray._raylet.execute_task
  File "python\ray\_raylet.pyx", line 1889, in ray._raylet.execute_task
  File "python\ray\_raylet.pyx", line 1830, in ray._raylet.execute_task.function_executor
  File "C:\Users\hughj\Documents\GitHub\asfl\env\lib\site-packages\ray\_private\function_manager.py", line 724, in actor_method_executor
    return method(__ray_actor, *args, **kwargs)
  File "C:\Users\hughj\Documents\GitHub\asfl\env\lib\site-packages\ray\util\tracing\tracing_helper.py", line 467, in _resume_span
    return method(self, *_args, **_kwargs)
  File "C:\Users\hughj\Documents\GitHub\asfl\env\lib\site-packages\flwr\simulation\ray_transport\ray_actor.py", line 63, in run
    raise ClientAppException(str(ex)) from ex
flwr.client.client_app.ClientAppException: 
Exception ClientAppException occurred. Message: Invalid partitioner
dv - | ERROR flwr 2024-10-23 14:49:32,289 | vce_api.py:124 | Traceback (most recent call last):
  File "C:\Users\hughj\Documents\GitHub\asfl\env\lib\site-packages\flwr\server\superlink\fleet\vce\vce_api.py", line 112, in worker
    out_mssg, updated_context = backend.process_message(message, context)
  File "C:\Users\hughj\Documents\GitHub\asfl\env\lib\site-packages\flwr\server\superlink\fleet\vce\backend\raybackend.py", line 178, in process_message
    raise ex
  File "C:\Users\hughj\Documents\GitHub\asfl\env\lib\site-packages\flwr\server\superlink\fleet\vce\backend\raybackend.py", line 166, in process_message
    ) = self.pool.fetch_result_and_return_actor_to_pool(future)
  File "C:\Users\hughj\Documents\GitHub\asfl\env\lib\site-packages\flwr\simulation\ray_transport\ray_actor.py", line 477, in fetch_result_and_return_actor_to_pool
    _, out_mssg, updated_context = ray.get(future)
  File "C:\Users\hughj\Documents\GitHub\asfl\env\lib\site-packages\ray\_private\auto_init_hook.py", line 21, in auto_init_wrapper
    return fn(*args, **kwargs)
  File "C:\Users\hughj\Documents\GitHub\asfl\env\lib\site-packages\ray\_private\client_mode_hook.py", line 103, in wrapper
    return func(*args, **kwargs)
  File "C:\Users\hughj\Documents\GitHub\asfl\env\lib\site-packages\ray\_private\worker.py", line 2667, in get
    values, debugger_breakpoint = worker.get_objects(object_refs, timeout=timeout)
  File "C:\Users\hughj\Documents\GitHub\asfl\env\lib\site-packages\ray\_private\worker.py", line 864, in get_objects
    raise value.as_instanceof_cause()
ray.exceptions.RayTaskError(ClientAppException): [36mray::ClientAppActor.run()[39m (pid=9248, ip=127.0.0.1, actor_id=79377813a47c6c0562b20fe201000000, repr=<flwr.simulation.ray_transport.ray_actor.ClientAppActor object at 0x0000017E6D7B0940>)
  File "C:\Users\hughj\Documents\GitHub\asfl\env\lib\site-packages\flwr\client\client_app.py", line 143, in __call__
    return self._call(message, context)
  File "C:\Users\hughj\Documents\GitHub\asfl\env\lib\site-packages\flwr\client\client_app.py", line 126, in ffn
    out_message = handle_legacy_message_from_msgtype(
  File "C:\Users\hughj\Documents\GitHub\asfl\env\lib\site-packages\flwr\client\message_handler\message_handler.py", line 95, in handle_legacy_message_from_msgtype
    client = client_fn(context)
  File "C:\Users\hughj\Documents\GitHub\asfl\asfl\client_app.py", line 80, in client_fn
    trainloader, valloader = load_data(context.run_config, partition_id, num_partitions)
  File "C:\Users\hughj\Documents\GitHub\asfl\asfl\task.py", line 72, in load_data
    raise ValueError("Invalid partitioner")
ValueError: Invalid partitioner

The above exception was the direct cause of the following exception:

[36mray::ClientAppActor.run()[39m (pid=9248, ip=127.0.0.1, actor_id=79377813a47c6c0562b20fe201000000, repr=<flwr.simulation.ray_transport.ray_actor.ClientAppActor object at 0x0000017E6D7B0940>)
  File "python\ray\_raylet.pyx", line 1883, in ray._raylet.execute_task
  File "python\ray\_raylet.pyx", line 1984, in ray._raylet.execute_task
  File "python\ray\_raylet.pyx", line 1889, in ray._raylet.execute_task
  File "python\ray\_raylet.pyx", line 1830, in ray._raylet.execute_task.function_executor
  File "C:\Users\hughj\Documents\GitHub\asfl\env\lib\site-packages\ray\_private\function_manager.py", line 724, in actor_method_executor
    return method(__ray_actor, *args, **kwargs)
  File "C:\Users\hughj\Documents\GitHub\asfl\env\lib\site-packages\ray\util\tracing\tracing_helper.py", line 467, in _resume_span
    return method(self, *_args, **_kwargs)
  File "C:\Users\hughj\Documents\GitHub\asfl\env\lib\site-packages\flwr\simulation\ray_transport\ray_actor.py", line 63, in run
    raise ClientAppException(str(ex)) from ex
flwr.client.client_app.ClientAppException: 
Exception ClientAppException occurred. Message: Invalid partitioner

dv - | ERROR flwr 2024-10-23 14:49:32,289 | vce_api.py:124 | Traceback (most recent call last):
  File "C:\Users\hughj\Documents\GitHub\asfl\env\lib\site-packages\flwr\server\superlink\fleet\vce\vce_api.py", line 112, in worker
    out_mssg, updated_context = backend.process_message(message, context)
  File "C:\Users\hughj\Documents\GitHub\asfl\env\lib\site-packages\flwr\server\superlink\fleet\vce\backend\raybackend.py", line 178, in process_message
    raise ex
  File "C:\Users\hughj\Documents\GitHub\asfl\env\lib\site-packages\flwr\server\superlink\fleet\vce\backend\raybackend.py", line 166, in process_message
    ) = self.pool.fetch_result_and_return_actor_to_pool(future)
  File "C:\Users\hughj\Documents\GitHub\asfl\env\lib\site-packages\flwr\simulation\ray_transport\ray_actor.py", line 477, in fetch_result_and_return_actor_to_pool
    _, out_mssg, updated_context = ray.get(future)
  File "C:\Users\hughj\Documents\GitHub\asfl\env\lib\site-packages\ray\_private\auto_init_hook.py", line 21, in auto_init_wrapper
    return fn(*args, **kwargs)
  File "C:\Users\hughj\Documents\GitHub\asfl\env\lib\site-packages\ray\_private\client_mode_hook.py", line 103, in wrapper
    return func(*args, **kwargs)
  File "C:\Users\hughj\Documents\GitHub\asfl\env\lib\site-packages\ray\_private\worker.py", line 2667, in get
    values, debugger_breakpoint = worker.get_objects(object_refs, timeout=timeout)
  File "C:\Users\hughj\Documents\GitHub\asfl\env\lib\site-packages\ray\_private\worker.py", line 864, in get_objects
    raise value.as_instanceof_cause()
ray.exceptions.RayTaskError(ClientAppException): [36mray::ClientAppActor.run()[39m (pid=7592, ip=127.0.0.1, actor_id=421e763c9414f647b864e34701000000, repr=<flwr.simulation.ray_transport.ray_actor.ClientAppActor object at 0x0000024C836E0940>)
  File "C:\Users\hughj\Documents\GitHub\asfl\env\lib\site-packages\flwr\client\client_app.py", line 143, in __call__
    return self._call(message, context)
  File "C:\Users\hughj\Documents\GitHub\asfl\env\lib\site-packages\flwr\client\client_app.py", line 126, in ffn
    out_message = handle_legacy_message_from_msgtype(
  File "C:\Users\hughj\Documents\GitHub\asfl\env\lib\site-packages\flwr\client\message_handler\message_handler.py", line 95, in handle_legacy_message_from_msgtype
    client = client_fn(context)
  File "C:\Users\hughj\Documents\GitHub\asfl\asfl\client_app.py", line 80, in client_fn
    trainloader, valloader = load_data(context.run_config, partition_id, num_partitions)
  File "C:\Users\hughj\Documents\GitHub\asfl\asfl\task.py", line 72, in load_data
    raise ValueError("Invalid partitioner")
ValueError: Invalid partitioner

The above exception was the direct cause of the following exception:

[36mray::ClientAppActor.run()[39m (pid=7592, ip=127.0.0.1, actor_id=421e763c9414f647b864e34701000000, repr=<flwr.simulation.ray_transport.ray_actor.ClientAppActor object at 0x0000024C836E0940>)
  File "python\ray\_raylet.pyx", line 1883, in ray._raylet.execute_task
  File "python\ray\_raylet.pyx", line 1984, in ray._raylet.execute_task
  File "python\ray\_raylet.pyx", line 1889, in ray._raylet.execute_task
  File "python\ray\_raylet.pyx", line 1830, in ray._raylet.execute_task.function_executor
  File "C:\Users\hughj\Documents\GitHub\asfl\env\lib\site-packages\ray\_private\function_manager.py", line 724, in actor_method_executor
    return method(__ray_actor, *args, **kwargs)
  File "C:\Users\hughj\Documents\GitHub\asfl\env\lib\site-packages\ray\util\tracing\tracing_helper.py", line 467, in _resume_span
    return method(self, *_args, **_kwargs)
  File "C:\Users\hughj\Documents\GitHub\asfl\env\lib\site-packages\flwr\simulation\ray_transport\ray_actor.py", line 63, in run
    raise ClientAppException(str(ex)) from ex
flwr.client.client_app.ClientAppException: 
Exception ClientAppException occurred. Message: Invalid partitioner

dv - | ERROR flwr 2024-10-23 14:49:32,300 | raybackend.py:171 | An exception was raised when processing a message by RayBackend
dv - | ERROR flwr 2024-10-23 14:49:32,300 | vce_api.py:123 | [36mray::ClientAppActor.run()[39m (pid=9836, ip=127.0.0.1, actor_id=5887fc0090d0d7bbbc5da80301000000, repr=<flwr.simulation.ray_transport.ray_actor.ClientAppActor object at 0x000002325B5408B0>)
  File "C:\Users\hughj\Documents\GitHub\asfl\env\lib\site-packages\flwr\client\client_app.py", line 143, in __call__
    return self._call(message, context)
  File "C:\Users\hughj\Documents\GitHub\asfl\env\lib\site-packages\flwr\client\client_app.py", line 126, in ffn
    out_message = handle_legacy_message_from_msgtype(
  File "C:\Users\hughj\Documents\GitHub\asfl\env\lib\site-packages\flwr\client\message_handler\message_handler.py", line 95, in handle_legacy_message_from_msgtype
    client = client_fn(context)
  File "C:\Users\hughj\Documents\GitHub\asfl\asfl\client_app.py", line 80, in client_fn
    trainloader, valloader = load_data(context.run_config, partition_id, num_partitions)
  File "C:\Users\hughj\Documents\GitHub\asfl\asfl\task.py", line 72, in load_data
    raise ValueError("Invalid partitioner")
ValueError: Invalid partitioner

The above exception was the direct cause of the following exception:

[36mray::ClientAppActor.run()[39m (pid=9836, ip=127.0.0.1, actor_id=5887fc0090d0d7bbbc5da80301000000, repr=<flwr.simulation.ray_transport.ray_actor.ClientAppActor object at 0x000002325B5408B0>)
  File "python\ray\_raylet.pyx", line 1883, in ray._raylet.execute_task
  File "python\ray\_raylet.pyx", line 1984, in ray._raylet.execute_task
  File "python\ray\_raylet.pyx", line 1889, in ray._raylet.execute_task
  File "python\ray\_raylet.pyx", line 1830, in ray._raylet.execute_task.function_executor
  File "C:\Users\hughj\Documents\GitHub\asfl\env\lib\site-packages\ray\_private\function_manager.py", line 724, in actor_method_executor
    return method(__ray_actor, *args, **kwargs)
  File "C:\Users\hughj\Documents\GitHub\asfl\env\lib\site-packages\ray\util\tracing\tracing_helper.py", line 467, in _resume_span
    return method(self, *_args, **_kwargs)
  File "C:\Users\hughj\Documents\GitHub\asfl\env\lib\site-packages\flwr\simulation\ray_transport\ray_actor.py", line 63, in run
    raise ClientAppException(str(ex)) from ex
flwr.client.client_app.ClientAppException: 
Exception ClientAppException occurred. Message: Invalid partitioner
dv - | ERROR flwr 2024-10-23 14:49:32,303 | vce_api.py:124 | Traceback (most recent call last):
  File "C:\Users\hughj\Documents\GitHub\asfl\env\lib\site-packages\flwr\server\superlink\fleet\vce\vce_api.py", line 112, in worker
    out_mssg, updated_context = backend.process_message(message, context)
  File "C:\Users\hughj\Documents\GitHub\asfl\env\lib\site-packages\flwr\server\superlink\fleet\vce\backend\raybackend.py", line 178, in process_message
    raise ex
  File "C:\Users\hughj\Documents\GitHub\asfl\env\lib\site-packages\flwr\server\superlink\fleet\vce\backend\raybackend.py", line 166, in process_message
    ) = self.pool.fetch_result_and_return_actor_to_pool(future)
  File "C:\Users\hughj\Documents\GitHub\asfl\env\lib\site-packages\flwr\simulation\ray_transport\ray_actor.py", line 477, in fetch_result_and_return_actor_to_pool
    _, out_mssg, updated_context = ray.get(future)
  File "C:\Users\hughj\Documents\GitHub\asfl\env\lib\site-packages\ray\_private\auto_init_hook.py", line 21, in auto_init_wrapper
    return fn(*args, **kwargs)
  File "C:\Users\hughj\Documents\GitHub\asfl\env\lib\site-packages\ray\_private\client_mode_hook.py", line 103, in wrapper
    return func(*args, **kwargs)
  File "C:\Users\hughj\Documents\GitHub\asfl\env\lib\site-packages\ray\_private\worker.py", line 2667, in get
    values, debugger_breakpoint = worker.get_objects(object_refs, timeout=timeout)
  File "C:\Users\hughj\Documents\GitHub\asfl\env\lib\site-packages\ray\_private\worker.py", line 864, in get_objects
    raise value.as_instanceof_cause()
ray.exceptions.RayTaskError(ClientAppException): [36mray::ClientAppActor.run()[39m (pid=9836, ip=127.0.0.1, actor_id=5887fc0090d0d7bbbc5da80301000000, repr=<flwr.simulation.ray_transport.ray_actor.ClientAppActor object at 0x000002325B5408B0>)
  File "C:\Users\hughj\Documents\GitHub\asfl\env\lib\site-packages\flwr\client\client_app.py", line 143, in __call__
    return self._call(message, context)
  File "C:\Users\hughj\Documents\GitHub\asfl\env\lib\site-packages\flwr\client\client_app.py", line 126, in ffn
    out_message = handle_legacy_message_from_msgtype(
  File "C:\Users\hughj\Documents\GitHub\asfl\env\lib\site-packages\flwr\client\message_handler\message_handler.py", line 95, in handle_legacy_message_from_msgtype
    client = client_fn(context)
  File "C:\Users\hughj\Documents\GitHub\asfl\asfl\client_app.py", line 80, in client_fn
    trainloader, valloader = load_data(context.run_config, partition_id, num_partitions)
  File "C:\Users\hughj\Documents\GitHub\asfl\asfl\task.py", line 72, in load_data
    raise ValueError("Invalid partitioner")
ValueError: Invalid partitioner

The above exception was the direct cause of the following exception:

[36mray::ClientAppActor.run()[39m (pid=9836, ip=127.0.0.1, actor_id=5887fc0090d0d7bbbc5da80301000000, repr=<flwr.simulation.ray_transport.ray_actor.ClientAppActor object at 0x000002325B5408B0>)
  File "python\ray\_raylet.pyx", line 1883, in ray._raylet.execute_task
  File "python\ray\_raylet.pyx", line 1984, in ray._raylet.execute_task
  File "python\ray\_raylet.pyx", line 1889, in ray._raylet.execute_task
  File "python\ray\_raylet.pyx", line 1830, in ray._raylet.execute_task.function_executor
  File "C:\Users\hughj\Documents\GitHub\asfl\env\lib\site-packages\ray\_private\function_manager.py", line 724, in actor_method_executor
    return method(__ray_actor, *args, **kwargs)
  File "C:\Users\hughj\Documents\GitHub\asfl\env\lib\site-packages\ray\util\tracing\tracing_helper.py", line 467, in _resume_span
    return method(self, *_args, **_kwargs)
  File "C:\Users\hughj\Documents\GitHub\asfl\env\lib\site-packages\flwr\simulation\ray_transport\ray_actor.py", line 63, in run
    raise ClientAppException(str(ex)) from ex
flwr.client.client_app.ClientAppException: 
Exception ClientAppException occurred. Message: Invalid partitioner

dv - | INFO flwr 2024-10-23 14:49:32,693 | server.py:240 | aggregate_fit: received 0 results and 3 failures
dv - | INFO flwr 2024-10-23 14:49:32,695 | server.py:178 | configure_evaluate: strategy sampled 3 clients (out of 3)
dv - | ERROR flwr 2024-10-23 14:49:32,768 | raybackend.py:171 | An exception was raised when processing a message by RayBackend
dv - | ERROR flwr 2024-10-23 14:49:32,768 | raybackend.py:171 | An exception was raised when processing a message by RayBackend
dv - | ERROR flwr 2024-10-23 14:49:32,769 | vce_api.py:123 | [36mray::ClientAppActor.run()[39m (pid=9836, ip=127.0.0.1, actor_id=5887fc0090d0d7bbbc5da80301000000, repr=<flwr.simulation.ray_transport.ray_actor.ClientAppActor object at 0x000002325B5408B0>)
  File "C:\Users\hughj\Documents\GitHub\asfl\env\lib\site-packages\flwr\client\client_app.py", line 143, in __call__
    return self._call(message, context)
  File "C:\Users\hughj\Documents\GitHub\asfl\env\lib\site-packages\flwr\client\client_app.py", line 126, in ffn
    out_message = handle_legacy_message_from_msgtype(
  File "C:\Users\hughj\Documents\GitHub\asfl\env\lib\site-packages\flwr\client\message_handler\message_handler.py", line 95, in handle_legacy_message_from_msgtype
    client = client_fn(context)
  File "C:\Users\hughj\Documents\GitHub\asfl\asfl\client_app.py", line 80, in client_fn
    trainloader, valloader = load_data(context.run_config, partition_id, num_partitions)
  File "C:\Users\hughj\Documents\GitHub\asfl\asfl\task.py", line 72, in load_data
    raise ValueError("Invalid partitioner")
ValueError: Invalid partitioner

The above exception was the direct cause of the following exception:

[36mray::ClientAppActor.run()[39m (pid=9836, ip=127.0.0.1, actor_id=5887fc0090d0d7bbbc5da80301000000, repr=<flwr.simulation.ray_transport.ray_actor.ClientAppActor object at 0x000002325B5408B0>)
  File "python\ray\_raylet.pyx", line 1883, in ray._raylet.execute_task
  File "python\ray\_raylet.pyx", line 1984, in ray._raylet.execute_task
  File "python\ray\_raylet.pyx", line 1889, in ray._raylet.execute_task
  File "python\ray\_raylet.pyx", line 1830, in ray._raylet.execute_task.function_executor
  File "C:\Users\hughj\Documents\GitHub\asfl\env\lib\site-packages\ray\_private\function_manager.py", line 724, in actor_method_executor
    return method(__ray_actor, *args, **kwargs)
  File "C:\Users\hughj\Documents\GitHub\asfl\env\lib\site-packages\ray\util\tracing\tracing_helper.py", line 467, in _resume_span
    return method(self, *_args, **_kwargs)
  File "C:\Users\hughj\Documents\GitHub\asfl\env\lib\site-packages\flwr\simulation\ray_transport\ray_actor.py", line 63, in run
    raise ClientAppException(str(ex)) from ex
flwr.client.client_app.ClientAppException: 
Exception ClientAppException occurred. Message: Invalid partitioner
dv - | ERROR flwr 2024-10-23 14:49:32,769 | vce_api.py:123 | [36mray::ClientAppActor.run()[39m (pid=7592, ip=127.0.0.1, actor_id=421e763c9414f647b864e34701000000, repr=<flwr.simulation.ray_transport.ray_actor.ClientAppActor object at 0x0000024C836E0940>)
  File "C:\Users\hughj\Documents\GitHub\asfl\env\lib\site-packages\flwr\client\client_app.py", line 143, in __call__
    return self._call(message, context)
  File "C:\Users\hughj\Documents\GitHub\asfl\env\lib\site-packages\flwr\client\client_app.py", line 126, in ffn
    out_message = handle_legacy_message_from_msgtype(
  File "C:\Users\hughj\Documents\GitHub\asfl\env\lib\site-packages\flwr\client\message_handler\message_handler.py", line 95, in handle_legacy_message_from_msgtype
    client = client_fn(context)
  File "C:\Users\hughj\Documents\GitHub\asfl\asfl\client_app.py", line 80, in client_fn
    trainloader, valloader = load_data(context.run_config, partition_id, num_partitions)
  File "C:\Users\hughj\Documents\GitHub\asfl\asfl\task.py", line 72, in load_data
    raise ValueError("Invalid partitioner")
ValueError: Invalid partitioner

The above exception was the direct cause of the following exception:

[36mray::ClientAppActor.run()[39m (pid=7592, ip=127.0.0.1, actor_id=421e763c9414f647b864e34701000000, repr=<flwr.simulation.ray_transport.ray_actor.ClientAppActor object at 0x0000024C836E0940>)
  File "python\ray\_raylet.pyx", line 1883, in ray._raylet.execute_task
  File "python\ray\_raylet.pyx", line 1984, in ray._raylet.execute_task
  File "python\ray\_raylet.pyx", line 1889, in ray._raylet.execute_task
  File "python\ray\_raylet.pyx", line 1830, in ray._raylet.execute_task.function_executor
  File "C:\Users\hughj\Documents\GitHub\asfl\env\lib\site-packages\ray\_private\function_manager.py", line 724, in actor_method_executor
    return method(__ray_actor, *args, **kwargs)
  File "C:\Users\hughj\Documents\GitHub\asfl\env\lib\site-packages\ray\util\tracing\tracing_helper.py", line 467, in _resume_span
    return method(self, *_args, **_kwargs)
  File "C:\Users\hughj\Documents\GitHub\asfl\env\lib\site-packages\flwr\simulation\ray_transport\ray_actor.py", line 63, in run
    raise ClientAppException(str(ex)) from ex
flwr.client.client_app.ClientAppException: 
Exception ClientAppException occurred. Message: Invalid partitioner
dv - | ERROR flwr 2024-10-23 14:49:32,770 | raybackend.py:171 | An exception was raised when processing a message by RayBackend
dv - | ERROR flwr 2024-10-23 14:49:32,775 | vce_api.py:124 | Traceback (most recent call last):
  File "C:\Users\hughj\Documents\GitHub\asfl\env\lib\site-packages\flwr\server\superlink\fleet\vce\vce_api.py", line 112, in worker
    out_mssg, updated_context = backend.process_message(message, context)
  File "C:\Users\hughj\Documents\GitHub\asfl\env\lib\site-packages\flwr\server\superlink\fleet\vce\backend\raybackend.py", line 178, in process_message
    raise ex
  File "C:\Users\hughj\Documents\GitHub\asfl\env\lib\site-packages\flwr\server\superlink\fleet\vce\backend\raybackend.py", line 166, in process_message
    ) = self.pool.fetch_result_and_return_actor_to_pool(future)
  File "C:\Users\hughj\Documents\GitHub\asfl\env\lib\site-packages\flwr\simulation\ray_transport\ray_actor.py", line 477, in fetch_result_and_return_actor_to_pool
    _, out_mssg, updated_context = ray.get(future)
  File "C:\Users\hughj\Documents\GitHub\asfl\env\lib\site-packages\ray\_private\auto_init_hook.py", line 21, in auto_init_wrapper
    return fn(*args, **kwargs)
  File "C:\Users\hughj\Documents\GitHub\asfl\env\lib\site-packages\ray\_private\client_mode_hook.py", line 103, in wrapper
    return func(*args, **kwargs)
  File "C:\Users\hughj\Documents\GitHub\asfl\env\lib\site-packages\ray\_private\worker.py", line 2667, in get
    values, debugger_breakpoint = worker.get_objects(object_refs, timeout=timeout)
  File "C:\Users\hughj\Documents\GitHub\asfl\env\lib\site-packages\ray\_private\worker.py", line 864, in get_objects
    raise value.as_instanceof_cause()
ray.exceptions.RayTaskError(ClientAppException): [36mray::ClientAppActor.run()[39m (pid=9836, ip=127.0.0.1, actor_id=5887fc0090d0d7bbbc5da80301000000, repr=<flwr.simulation.ray_transport.ray_actor.ClientAppActor object at 0x000002325B5408B0>)
  File "C:\Users\hughj\Documents\GitHub\asfl\env\lib\site-packages\flwr\client\client_app.py", line 143, in __call__
    return self._call(message, context)
  File "C:\Users\hughj\Documents\GitHub\asfl\env\lib\site-packages\flwr\client\client_app.py", line 126, in ffn
    out_message = handle_legacy_message_from_msgtype(
  File "C:\Users\hughj\Documents\GitHub\asfl\env\lib\site-packages\flwr\client\message_handler\message_handler.py", line 95, in handle_legacy_message_from_msgtype
    client = client_fn(context)
  File "C:\Users\hughj\Documents\GitHub\asfl\asfl\client_app.py", line 80, in client_fn
    trainloader, valloader = load_data(context.run_config, partition_id, num_partitions)
  File "C:\Users\hughj\Documents\GitHub\asfl\asfl\task.py", line 72, in load_data
    raise ValueError("Invalid partitioner")
ValueError: Invalid partitioner

The above exception was the direct cause of the following exception:

[36mray::ClientAppActor.run()[39m (pid=9836, ip=127.0.0.1, actor_id=5887fc0090d0d7bbbc5da80301000000, repr=<flwr.simulation.ray_transport.ray_actor.ClientAppActor object at 0x000002325B5408B0>)
  File "python\ray\_raylet.pyx", line 1883, in ray._raylet.execute_task
  File "python\ray\_raylet.pyx", line 1984, in ray._raylet.execute_task
  File "python\ray\_raylet.pyx", line 1889, in ray._raylet.execute_task
  File "python\ray\_raylet.pyx", line 1830, in ray._raylet.execute_task.function_executor
  File "C:\Users\hughj\Documents\GitHub\asfl\env\lib\site-packages\ray\_private\function_manager.py", line 724, in actor_method_executor
    return method(__ray_actor, *args, **kwargs)
  File "C:\Users\hughj\Documents\GitHub\asfl\env\lib\site-packages\ray\util\tracing\tracing_helper.py", line 467, in _resume_span
    return method(self, *_args, **_kwargs)
  File "C:\Users\hughj\Documents\GitHub\asfl\env\lib\site-packages\flwr\simulation\ray_transport\ray_actor.py", line 63, in run
    raise ClientAppException(str(ex)) from ex
flwr.client.client_app.ClientAppException: 
Exception ClientAppException occurred. Message: Invalid partitioner

dv - | ERROR flwr 2024-10-23 14:49:32,781 | vce_api.py:124 | Traceback (most recent call last):
  File "C:\Users\hughj\Documents\GitHub\asfl\env\lib\site-packages\flwr\server\superlink\fleet\vce\vce_api.py", line 112, in worker
    out_mssg, updated_context = backend.process_message(message, context)
  File "C:\Users\hughj\Documents\GitHub\asfl\env\lib\site-packages\flwr\server\superlink\fleet\vce\backend\raybackend.py", line 178, in process_message
    raise ex
  File "C:\Users\hughj\Documents\GitHub\asfl\env\lib\site-packages\flwr\server\superlink\fleet\vce\backend\raybackend.py", line 166, in process_message
    ) = self.pool.fetch_result_and_return_actor_to_pool(future)
  File "C:\Users\hughj\Documents\GitHub\asfl\env\lib\site-packages\flwr\simulation\ray_transport\ray_actor.py", line 477, in fetch_result_and_return_actor_to_pool
    _, out_mssg, updated_context = ray.get(future)
  File "C:\Users\hughj\Documents\GitHub\asfl\env\lib\site-packages\ray\_private\auto_init_hook.py", line 21, in auto_init_wrapper
    return fn(*args, **kwargs)
  File "C:\Users\hughj\Documents\GitHub\asfl\env\lib\site-packages\ray\_private\client_mode_hook.py", line 103, in wrapper
    return func(*args, **kwargs)
  File "C:\Users\hughj\Documents\GitHub\asfl\env\lib\site-packages\ray\_private\worker.py", line 2667, in get
    values, debugger_breakpoint = worker.get_objects(object_refs, timeout=timeout)
  File "C:\Users\hughj\Documents\GitHub\asfl\env\lib\site-packages\ray\_private\worker.py", line 864, in get_objects
    raise value.as_instanceof_cause()
ray.exceptions.RayTaskError(ClientAppException): [36mray::ClientAppActor.run()[39m (pid=7592, ip=127.0.0.1, actor_id=421e763c9414f647b864e34701000000, repr=<flwr.simulation.ray_transport.ray_actor.ClientAppActor object at 0x0000024C836E0940>)
  File "C:\Users\hughj\Documents\GitHub\asfl\env\lib\site-packages\flwr\client\client_app.py", line 143, in __call__
    return self._call(message, context)
  File "C:\Users\hughj\Documents\GitHub\asfl\env\lib\site-packages\flwr\client\client_app.py", line 126, in ffn
    out_message = handle_legacy_message_from_msgtype(
  File "C:\Users\hughj\Documents\GitHub\asfl\env\lib\site-packages\flwr\client\message_handler\message_handler.py", line 95, in handle_legacy_message_from_msgtype
    client = client_fn(context)
  File "C:\Users\hughj\Documents\GitHub\asfl\asfl\client_app.py", line 80, in client_fn
    trainloader, valloader = load_data(context.run_config, partition_id, num_partitions)
  File "C:\Users\hughj\Documents\GitHub\asfl\asfl\task.py", line 72, in load_data
    raise ValueError("Invalid partitioner")
ValueError: Invalid partitioner

The above exception was the direct cause of the following exception:

[36mray::ClientAppActor.run()[39m (pid=7592, ip=127.0.0.1, actor_id=421e763c9414f647b864e34701000000, repr=<flwr.simulation.ray_transport.ray_actor.ClientAppActor object at 0x0000024C836E0940>)
  File "python\ray\_raylet.pyx", line 1883, in ray._raylet.execute_task
  File "python\ray\_raylet.pyx", line 1984, in ray._raylet.execute_task
  File "python\ray\_raylet.pyx", line 1889, in ray._raylet.execute_task
  File "python\ray\_raylet.pyx", line 1830, in ray._raylet.execute_task.function_executor
  File "C:\Users\hughj\Documents\GitHub\asfl\env\lib\site-packages\ray\_private\function_manager.py", line 724, in actor_method_executor
    return method(__ray_actor, *args, **kwargs)
  File "C:\Users\hughj\Documents\GitHub\asfl\env\lib\site-packages\ray\util\tracing\tracing_helper.py", line 467, in _resume_span
    return method(self, *_args, **_kwargs)
  File "C:\Users\hughj\Documents\GitHub\asfl\env\lib\site-packages\flwr\simulation\ray_transport\ray_actor.py", line 63, in run
    raise ClientAppException(str(ex)) from ex
flwr.client.client_app.ClientAppException: 
Exception ClientAppException occurred. Message: Invalid partitioner

dv - | ERROR flwr 2024-10-23 14:49:32,781 | vce_api.py:123 | [36mray::ClientAppActor.run()[39m (pid=9248, ip=127.0.0.1, actor_id=79377813a47c6c0562b20fe201000000, repr=<flwr.simulation.ray_transport.ray_actor.ClientAppActor object at 0x0000017E6D7B0940>)
  File "C:\Users\hughj\Documents\GitHub\asfl\env\lib\site-packages\flwr\client\client_app.py", line 143, in __call__
    return self._call(message, context)
  File "C:\Users\hughj\Documents\GitHub\asfl\env\lib\site-packages\flwr\client\client_app.py", line 126, in ffn
    out_message = handle_legacy_message_from_msgtype(
  File "C:\Users\hughj\Documents\GitHub\asfl\env\lib\site-packages\flwr\client\message_handler\message_handler.py", line 95, in handle_legacy_message_from_msgtype
    client = client_fn(context)
  File "C:\Users\hughj\Documents\GitHub\asfl\asfl\client_app.py", line 80, in client_fn
    trainloader, valloader = load_data(context.run_config, partition_id, num_partitions)
  File "C:\Users\hughj\Documents\GitHub\asfl\asfl\task.py", line 72, in load_data
    raise ValueError("Invalid partitioner")
ValueError: Invalid partitioner

The above exception was the direct cause of the following exception:

[36mray::ClientAppActor.run()[39m (pid=9248, ip=127.0.0.1, actor_id=79377813a47c6c0562b20fe201000000, repr=<flwr.simulation.ray_transport.ray_actor.ClientAppActor object at 0x0000017E6D7B0940>)
  File "python\ray\_raylet.pyx", line 1883, in ray._raylet.execute_task
  File "python\ray\_raylet.pyx", line 1984, in ray._raylet.execute_task
  File "python\ray\_raylet.pyx", line 1889, in ray._raylet.execute_task
  File "python\ray\_raylet.pyx", line 1830, in ray._raylet.execute_task.function_executor
  File "C:\Users\hughj\Documents\GitHub\asfl\env\lib\site-packages\ray\_private\function_manager.py", line 724, in actor_method_executor
    return method(__ray_actor, *args, **kwargs)
  File "C:\Users\hughj\Documents\GitHub\asfl\env\lib\site-packages\ray\util\tracing\tracing_helper.py", line 467, in _resume_span
    return method(self, *_args, **_kwargs)
  File "C:\Users\hughj\Documents\GitHub\asfl\env\lib\site-packages\flwr\simulation\ray_transport\ray_actor.py", line 63, in run
    raise ClientAppException(str(ex)) from ex
flwr.client.client_app.ClientAppException: 
Exception ClientAppException occurred. Message: Invalid partitioner
dv - | ERROR flwr 2024-10-23 14:49:32,801 | vce_api.py:124 | Traceback (most recent call last):
  File "C:\Users\hughj\Documents\GitHub\asfl\env\lib\site-packages\flwr\server\superlink\fleet\vce\vce_api.py", line 112, in worker
    out_mssg, updated_context = backend.process_message(message, context)
  File "C:\Users\hughj\Documents\GitHub\asfl\env\lib\site-packages\flwr\server\superlink\fleet\vce\backend\raybackend.py", line 178, in process_message
    raise ex
  File "C:\Users\hughj\Documents\GitHub\asfl\env\lib\site-packages\flwr\server\superlink\fleet\vce\backend\raybackend.py", line 166, in process_message
    ) = self.pool.fetch_result_and_return_actor_to_pool(future)
  File "C:\Users\hughj\Documents\GitHub\asfl\env\lib\site-packages\flwr\simulation\ray_transport\ray_actor.py", line 477, in fetch_result_and_return_actor_to_pool
    _, out_mssg, updated_context = ray.get(future)
  File "C:\Users\hughj\Documents\GitHub\asfl\env\lib\site-packages\ray\_private\auto_init_hook.py", line 21, in auto_init_wrapper
    return fn(*args, **kwargs)
  File "C:\Users\hughj\Documents\GitHub\asfl\env\lib\site-packages\ray\_private\client_mode_hook.py", line 103, in wrapper
    return func(*args, **kwargs)
  File "C:\Users\hughj\Documents\GitHub\asfl\env\lib\site-packages\ray\_private\worker.py", line 2667, in get
    values, debugger_breakpoint = worker.get_objects(object_refs, timeout=timeout)
  File "C:\Users\hughj\Documents\GitHub\asfl\env\lib\site-packages\ray\_private\worker.py", line 864, in get_objects
    raise value.as_instanceof_cause()
ray.exceptions.RayTaskError(ClientAppException): [36mray::ClientAppActor.run()[39m (pid=9248, ip=127.0.0.1, actor_id=79377813a47c6c0562b20fe201000000, repr=<flwr.simulation.ray_transport.ray_actor.ClientAppActor object at 0x0000017E6D7B0940>)
  File "C:\Users\hughj\Documents\GitHub\asfl\env\lib\site-packages\flwr\client\client_app.py", line 143, in __call__
    return self._call(message, context)
  File "C:\Users\hughj\Documents\GitHub\asfl\env\lib\site-packages\flwr\client\client_app.py", line 126, in ffn
    out_message = handle_legacy_message_from_msgtype(
  File "C:\Users\hughj\Documents\GitHub\asfl\env\lib\site-packages\flwr\client\message_handler\message_handler.py", line 95, in handle_legacy_message_from_msgtype
    client = client_fn(context)
  File "C:\Users\hughj\Documents\GitHub\asfl\asfl\client_app.py", line 80, in client_fn
    trainloader, valloader = load_data(context.run_config, partition_id, num_partitions)
  File "C:\Users\hughj\Documents\GitHub\asfl\asfl\task.py", line 72, in load_data
    raise ValueError("Invalid partitioner")
ValueError: Invalid partitioner

The above exception was the direct cause of the following exception:

[36mray::ClientAppActor.run()[39m (pid=9248, ip=127.0.0.1, actor_id=79377813a47c6c0562b20fe201000000, repr=<flwr.simulation.ray_transport.ray_actor.ClientAppActor object at 0x0000017E6D7B0940>)
  File "python\ray\_raylet.pyx", line 1883, in ray._raylet.execute_task
  File "python\ray\_raylet.pyx", line 1984, in ray._raylet.execute_task
  File "python\ray\_raylet.pyx", line 1889, in ray._raylet.execute_task
  File "python\ray\_raylet.pyx", line 1830, in ray._raylet.execute_task.function_executor
  File "C:\Users\hughj\Documents\GitHub\asfl\env\lib\site-packages\ray\_private\function_manager.py", line 724, in actor_method_executor
    return method(__ray_actor, *args, **kwargs)
  File "C:\Users\hughj\Documents\GitHub\asfl\env\lib\site-packages\ray\util\tracing\tracing_helper.py", line 467, in _resume_span
    return method(self, *_args, **_kwargs)
  File "C:\Users\hughj\Documents\GitHub\asfl\env\lib\site-packages\flwr\simulation\ray_transport\ray_actor.py", line 63, in run
    raise ClientAppException(str(ex)) from ex
flwr.client.client_app.ClientAppException: 
Exception ClientAppException occurred. Message: Invalid partitioner

dv - | INFO flwr 2024-10-23 14:49:33,704 | server.py:192 | aggregate_evaluate: received 0 results and 3 failures
dv - | INFO flwr 2024-10-23 14:49:33,705 | server.py:496 | 
dv - | INFO flwr 2024-10-23 14:49:33,706 | server.py:497 | [SUMMARY]
dv - | INFO flwr 2024-10-23 14:49:33,707 | server.py:498 | Run finished 1 round(s) in 11.63s
dv - | INFO flwr 2024-10-23 14:49:33,708 | server.py:501 | 
dv - | DEBUG flwr 2024-10-23 14:49:33,711 | run_serverapp.py:90 | ServerApp finished running.
dv - | DEBUG flwr 2024-10-23 14:49:33,711 | run_simulation.py:349 | ServerApp finished running.
dv - | DEBUG flwr 2024-10-23 14:49:33,711 | run_simulation.py:353 | Triggered stop event for Simulation Engine.
dv - | DEBUG flwr 2024-10-23 14:49:33,814 | ray_actor.py:450 | Terminated 4 actors
dv - | DEBUG flwr 2024-10-23 14:49:34,755 | raybackend.py:184 | Terminated RayBackend
dv - | DEBUG flwr 2024-10-23 14:49:34,755 | run_simulation.py:452 | Stopping Simulation Engine now.
dv - | INFO flwr 2024-10-23 14:50:10,859 | server_app.py:88 | file writing: True
dv - | INFO flwr 2024-10-23 14:50:10,859 | server_app.py:89 | running in fed_acc
dv - | INFO flwr 2024-10-23 14:50:10,860 | server_app.py:90 | min num clients 2
dv - | INFO flwr 2024-10-23 14:50:10,864 | server_app.py:91 | num server rounds 1
dv - | INFO flwr 2024-10-23 14:50:10,864 | server_app.py:92 | config num local epochs 1
dv - | INFO flwr 2024-10-23 14:50:10,865 | server_app.py:93 | advanced logging False
dv - | INFO flwr 2024-10-23 14:50:10,865 | server_app.py:94 | partition: dirichlet
dv - | INFO flwr 2024-10-23 14:50:10,865 | app.py:74 | Starting Flower ServerApp, config: num_rounds=1, no round_timeout
dv - | INFO flwr 2024-10-23 14:50:10,866 | app.py:79 | 
dv - | INFO flwr 2024-10-23 14:50:10,867 | server.py:92 | [INIT]
dv - | INFO flwr 2024-10-23 14:50:10,868 | server.py:277 | Using initial global parameters provided by strategy
dv - | INFO flwr 2024-10-23 14:50:10,868 | server.py:94 | Starting evaluation of initial global parameters
dv - | INFO flwr 2024-10-23 14:50:10,868 | server.py:106 | Evaluation returned no results (`None`)
dv - | INFO flwr 2024-10-23 14:50:10,869 | server.py:112 | 
dv - | INFO flwr 2024-10-23 14:50:10,869 | server.py:113 | [ROUND 1]
dv - | INFO flwr 2024-10-23 14:50:10,870 | server.py:226 | configure_fit: strategy sampled 3 clients (out of 3)
dv - | DEBUG flwr 2024-10-23 14:50:14,116 | raybackend.py:136 | Constructed ActorPool with: 4 actors
dv - | DEBUG flwr 2024-10-23 14:50:14,117 | state_factory.py:50 | Using InMemoryState
dv - | ERROR flwr 2024-10-23 14:50:20,277 | raybackend.py:171 | An exception was raised when processing a message by RayBackend
dv - | ERROR flwr 2024-10-23 14:50:20,278 | vce_api.py:123 | [36mray::ClientAppActor.run()[39m (pid=28636, ip=127.0.0.1, actor_id=58b1e7b39a525ad984048d6a01000000, repr=<flwr.simulation.ray_transport.ray_actor.ClientAppActor object at 0x0000029803A009A0>)
  File "C:\Users\hughj\Documents\GitHub\asfl\env\lib\site-packages\flwr\client\client_app.py", line 143, in __call__
    return self._call(message, context)
  File "C:\Users\hughj\Documents\GitHub\asfl\env\lib\site-packages\flwr\client\client_app.py", line 126, in ffn
    out_message = handle_legacy_message_from_msgtype(
  File "C:\Users\hughj\Documents\GitHub\asfl\env\lib\site-packages\flwr\client\message_handler\message_handler.py", line 95, in handle_legacy_message_from_msgtype
    client = client_fn(context)
  File "C:\Users\hughj\Documents\GitHub\asfl\asfl\client_app.py", line 80, in client_fn
    trainloader, valloader = load_data(context.run_config, partition_id, num_partitions)
  File "C:\Users\hughj\Documents\GitHub\asfl\asfl\task.py", line 72, in load_data
    raise ValueError("Invalid partitioner")
ValueError: Invalid partitioner

The above exception was the direct cause of the following exception:

[36mray::ClientAppActor.run()[39m (pid=28636, ip=127.0.0.1, actor_id=58b1e7b39a525ad984048d6a01000000, repr=<flwr.simulation.ray_transport.ray_actor.ClientAppActor object at 0x0000029803A009A0>)
  File "python\ray\_raylet.pyx", line 1883, in ray._raylet.execute_task
  File "python\ray\_raylet.pyx", line 1984, in ray._raylet.execute_task
  File "python\ray\_raylet.pyx", line 1889, in ray._raylet.execute_task
  File "python\ray\_raylet.pyx", line 1830, in ray._raylet.execute_task.function_executor
  File "C:\Users\hughj\Documents\GitHub\asfl\env\lib\site-packages\ray\_private\function_manager.py", line 724, in actor_method_executor
    return method(__ray_actor, *args, **kwargs)
  File "C:\Users\hughj\Documents\GitHub\asfl\env\lib\site-packages\ray\util\tracing\tracing_helper.py", line 467, in _resume_span
    return method(self, *_args, **_kwargs)
  File "C:\Users\hughj\Documents\GitHub\asfl\env\lib\site-packages\flwr\simulation\ray_transport\ray_actor.py", line 63, in run
    raise ClientAppException(str(ex)) from ex
flwr.client.client_app.ClientAppException: 
Exception ClientAppException occurred. Message: Invalid partitioner
dv - | ERROR flwr 2024-10-23 14:50:20,282 | vce_api.py:124 | Traceback (most recent call last):
  File "C:\Users\hughj\Documents\GitHub\asfl\env\lib\site-packages\flwr\server\superlink\fleet\vce\vce_api.py", line 112, in worker
    out_mssg, updated_context = backend.process_message(message, context)
  File "C:\Users\hughj\Documents\GitHub\asfl\env\lib\site-packages\flwr\server\superlink\fleet\vce\backend\raybackend.py", line 178, in process_message
    raise ex
  File "C:\Users\hughj\Documents\GitHub\asfl\env\lib\site-packages\flwr\server\superlink\fleet\vce\backend\raybackend.py", line 166, in process_message
    ) = self.pool.fetch_result_and_return_actor_to_pool(future)
  File "C:\Users\hughj\Documents\GitHub\asfl\env\lib\site-packages\flwr\simulation\ray_transport\ray_actor.py", line 477, in fetch_result_and_return_actor_to_pool
    _, out_mssg, updated_context = ray.get(future)
  File "C:\Users\hughj\Documents\GitHub\asfl\env\lib\site-packages\ray\_private\auto_init_hook.py", line 21, in auto_init_wrapper
    return fn(*args, **kwargs)
  File "C:\Users\hughj\Documents\GitHub\asfl\env\lib\site-packages\ray\_private\client_mode_hook.py", line 103, in wrapper
    return func(*args, **kwargs)
  File "C:\Users\hughj\Documents\GitHub\asfl\env\lib\site-packages\ray\_private\worker.py", line 2667, in get
    values, debugger_breakpoint = worker.get_objects(object_refs, timeout=timeout)
  File "C:\Users\hughj\Documents\GitHub\asfl\env\lib\site-packages\ray\_private\worker.py", line 864, in get_objects
    raise value.as_instanceof_cause()
ray.exceptions.RayTaskError(ClientAppException): [36mray::ClientAppActor.run()[39m (pid=28636, ip=127.0.0.1, actor_id=58b1e7b39a525ad984048d6a01000000, repr=<flwr.simulation.ray_transport.ray_actor.ClientAppActor object at 0x0000029803A009A0>)
  File "C:\Users\hughj\Documents\GitHub\asfl\env\lib\site-packages\flwr\client\client_app.py", line 143, in __call__
    return self._call(message, context)
  File "C:\Users\hughj\Documents\GitHub\asfl\env\lib\site-packages\flwr\client\client_app.py", line 126, in ffn
    out_message = handle_legacy_message_from_msgtype(
  File "C:\Users\hughj\Documents\GitHub\asfl\env\lib\site-packages\flwr\client\message_handler\message_handler.py", line 95, in handle_legacy_message_from_msgtype
    client = client_fn(context)
  File "C:\Users\hughj\Documents\GitHub\asfl\asfl\client_app.py", line 80, in client_fn
    trainloader, valloader = load_data(context.run_config, partition_id, num_partitions)
  File "C:\Users\hughj\Documents\GitHub\asfl\asfl\task.py", line 72, in load_data
    raise ValueError("Invalid partitioner")
ValueError: Invalid partitioner

The above exception was the direct cause of the following exception:

[36mray::ClientAppActor.run()[39m (pid=28636, ip=127.0.0.1, actor_id=58b1e7b39a525ad984048d6a01000000, repr=<flwr.simulation.ray_transport.ray_actor.ClientAppActor object at 0x0000029803A009A0>)
  File "python\ray\_raylet.pyx", line 1883, in ray._raylet.execute_task
  File "python\ray\_raylet.pyx", line 1984, in ray._raylet.execute_task
  File "python\ray\_raylet.pyx", line 1889, in ray._raylet.execute_task
  File "python\ray\_raylet.pyx", line 1830, in ray._raylet.execute_task.function_executor
  File "C:\Users\hughj\Documents\GitHub\asfl\env\lib\site-packages\ray\_private\function_manager.py", line 724, in actor_method_executor
    return method(__ray_actor, *args, **kwargs)
  File "C:\Users\hughj\Documents\GitHub\asfl\env\lib\site-packages\ray\util\tracing\tracing_helper.py", line 467, in _resume_span
    return method(self, *_args, **_kwargs)
  File "C:\Users\hughj\Documents\GitHub\asfl\env\lib\site-packages\flwr\simulation\ray_transport\ray_actor.py", line 63, in run
    raise ClientAppException(str(ex)) from ex
flwr.client.client_app.ClientAppException: 
Exception ClientAppException occurred. Message: Invalid partitioner

dv - | ERROR flwr 2024-10-23 14:50:20,294 | raybackend.py:171 | An exception was raised when processing a message by RayBackend
dv - | ERROR flwr 2024-10-23 14:50:20,294 | vce_api.py:123 | [36mray::ClientAppActor.run()[39m (pid=35004, ip=127.0.0.1, actor_id=b9cbabe05acff9d45c35330c01000000, repr=<flwr.simulation.ray_transport.ray_actor.ClientAppActor object at 0x00000294B5D709A0>)
  File "C:\Users\hughj\Documents\GitHub\asfl\env\lib\site-packages\flwr\client\client_app.py", line 143, in __call__
    return self._call(message, context)
  File "C:\Users\hughj\Documents\GitHub\asfl\env\lib\site-packages\flwr\client\client_app.py", line 126, in ffn
    out_message = handle_legacy_message_from_msgtype(
  File "C:\Users\hughj\Documents\GitHub\asfl\env\lib\site-packages\flwr\client\message_handler\message_handler.py", line 95, in handle_legacy_message_from_msgtype
    client = client_fn(context)
  File "C:\Users\hughj\Documents\GitHub\asfl\asfl\client_app.py", line 80, in client_fn
    trainloader, valloader = load_data(context.run_config, partition_id, num_partitions)
  File "C:\Users\hughj\Documents\GitHub\asfl\asfl\task.py", line 72, in load_data
    raise ValueError("Invalid partitioner")
ValueError: Invalid partitioner

The above exception was the direct cause of the following exception:

[36mray::ClientAppActor.run()[39m (pid=35004, ip=127.0.0.1, actor_id=b9cbabe05acff9d45c35330c01000000, repr=<flwr.simulation.ray_transport.ray_actor.ClientAppActor object at 0x00000294B5D709A0>)
  File "python\ray\_raylet.pyx", line 1883, in ray._raylet.execute_task
  File "python\ray\_raylet.pyx", line 1984, in ray._raylet.execute_task
  File "python\ray\_raylet.pyx", line 1889, in ray._raylet.execute_task
  File "python\ray\_raylet.pyx", line 1830, in ray._raylet.execute_task.function_executor
  File "C:\Users\hughj\Documents\GitHub\asfl\env\lib\site-packages\ray\_private\function_manager.py", line 724, in actor_method_executor
    return method(__ray_actor, *args, **kwargs)
  File "C:\Users\hughj\Documents\GitHub\asfl\env\lib\site-packages\ray\util\tracing\tracing_helper.py", line 467, in _resume_span
    return method(self, *_args, **_kwargs)
  File "C:\Users\hughj\Documents\GitHub\asfl\env\lib\site-packages\flwr\simulation\ray_transport\ray_actor.py", line 63, in run
    raise ClientAppException(str(ex)) from ex
flwr.client.client_app.ClientAppException: 
Exception ClientAppException occurred. Message: Invalid partitioner
dv - | ERROR flwr 2024-10-23 14:50:20,296 | vce_api.py:124 | Traceback (most recent call last):
  File "C:\Users\hughj\Documents\GitHub\asfl\env\lib\site-packages\flwr\server\superlink\fleet\vce\vce_api.py", line 112, in worker
    out_mssg, updated_context = backend.process_message(message, context)
  File "C:\Users\hughj\Documents\GitHub\asfl\env\lib\site-packages\flwr\server\superlink\fleet\vce\backend\raybackend.py", line 178, in process_message
    raise ex
  File "C:\Users\hughj\Documents\GitHub\asfl\env\lib\site-packages\flwr\server\superlink\fleet\vce\backend\raybackend.py", line 166, in process_message
    ) = self.pool.fetch_result_and_return_actor_to_pool(future)
  File "C:\Users\hughj\Documents\GitHub\asfl\env\lib\site-packages\flwr\simulation\ray_transport\ray_actor.py", line 477, in fetch_result_and_return_actor_to_pool
    _, out_mssg, updated_context = ray.get(future)
  File "C:\Users\hughj\Documents\GitHub\asfl\env\lib\site-packages\ray\_private\auto_init_hook.py", line 21, in auto_init_wrapper
    return fn(*args, **kwargs)
  File "C:\Users\hughj\Documents\GitHub\asfl\env\lib\site-packages\ray\_private\client_mode_hook.py", line 103, in wrapper
    return func(*args, **kwargs)
  File "C:\Users\hughj\Documents\GitHub\asfl\env\lib\site-packages\ray\_private\worker.py", line 2667, in get
    values, debugger_breakpoint = worker.get_objects(object_refs, timeout=timeout)
  File "C:\Users\hughj\Documents\GitHub\asfl\env\lib\site-packages\ray\_private\worker.py", line 864, in get_objects
    raise value.as_instanceof_cause()
ray.exceptions.RayTaskError(ClientAppException): [36mray::ClientAppActor.run()[39m (pid=35004, ip=127.0.0.1, actor_id=b9cbabe05acff9d45c35330c01000000, repr=<flwr.simulation.ray_transport.ray_actor.ClientAppActor object at 0x00000294B5D709A0>)
  File "C:\Users\hughj\Documents\GitHub\asfl\env\lib\site-packages\flwr\client\client_app.py", line 143, in __call__
    return self._call(message, context)
  File "C:\Users\hughj\Documents\GitHub\asfl\env\lib\site-packages\flwr\client\client_app.py", line 126, in ffn
    out_message = handle_legacy_message_from_msgtype(
  File "C:\Users\hughj\Documents\GitHub\asfl\env\lib\site-packages\flwr\client\message_handler\message_handler.py", line 95, in handle_legacy_message_from_msgtype
    client = client_fn(context)
  File "C:\Users\hughj\Documents\GitHub\asfl\asfl\client_app.py", line 80, in client_fn
    trainloader, valloader = load_data(context.run_config, partition_id, num_partitions)
  File "C:\Users\hughj\Documents\GitHub\asfl\asfl\task.py", line 72, in load_data
    raise ValueError("Invalid partitioner")
ValueError: Invalid partitioner

The above exception was the direct cause of the following exception:

[36mray::ClientAppActor.run()[39m (pid=35004, ip=127.0.0.1, actor_id=b9cbabe05acff9d45c35330c01000000, repr=<flwr.simulation.ray_transport.ray_actor.ClientAppActor object at 0x00000294B5D709A0>)
  File "python\ray\_raylet.pyx", line 1883, in ray._raylet.execute_task
  File "python\ray\_raylet.pyx", line 1984, in ray._raylet.execute_task
  File "python\ray\_raylet.pyx", line 1889, in ray._raylet.execute_task
  File "python\ray\_raylet.pyx", line 1830, in ray._raylet.execute_task.function_executor
  File "C:\Users\hughj\Documents\GitHub\asfl\env\lib\site-packages\ray\_private\function_manager.py", line 724, in actor_method_executor
    return method(__ray_actor, *args, **kwargs)
  File "C:\Users\hughj\Documents\GitHub\asfl\env\lib\site-packages\ray\util\tracing\tracing_helper.py", line 467, in _resume_span
    return method(self, *_args, **_kwargs)
  File "C:\Users\hughj\Documents\GitHub\asfl\env\lib\site-packages\flwr\simulation\ray_transport\ray_actor.py", line 63, in run
    raise ClientAppException(str(ex)) from ex
flwr.client.client_app.ClientAppException: 
Exception ClientAppException occurred. Message: Invalid partitioner

dv - | ERROR flwr 2024-10-23 14:50:20,298 | raybackend.py:171 | An exception was raised when processing a message by RayBackend
dv - | ERROR flwr 2024-10-23 14:50:20,299 | vce_api.py:123 | [36mray::ClientAppActor.run()[39m (pid=14528, ip=127.0.0.1, actor_id=b401871411f2dda3be48ae6d01000000, repr=<flwr.simulation.ray_transport.ray_actor.ClientAppActor object at 0x000001AF19F70940>)
  File "C:\Users\hughj\Documents\GitHub\asfl\env\lib\site-packages\flwr\client\client_app.py", line 143, in __call__
    return self._call(message, context)
  File "C:\Users\hughj\Documents\GitHub\asfl\env\lib\site-packages\flwr\client\client_app.py", line 126, in ffn
    out_message = handle_legacy_message_from_msgtype(
  File "C:\Users\hughj\Documents\GitHub\asfl\env\lib\site-packages\flwr\client\message_handler\message_handler.py", line 95, in handle_legacy_message_from_msgtype
    client = client_fn(context)
  File "C:\Users\hughj\Documents\GitHub\asfl\asfl\client_app.py", line 80, in client_fn
    trainloader, valloader = load_data(context.run_config, partition_id, num_partitions)
  File "C:\Users\hughj\Documents\GitHub\asfl\asfl\task.py", line 72, in load_data
    raise ValueError("Invalid partitioner")
ValueError: Invalid partitioner

The above exception was the direct cause of the following exception:

[36mray::ClientAppActor.run()[39m (pid=14528, ip=127.0.0.1, actor_id=b401871411f2dda3be48ae6d01000000, repr=<flwr.simulation.ray_transport.ray_actor.ClientAppActor object at 0x000001AF19F70940>)
  File "python\ray\_raylet.pyx", line 1883, in ray._raylet.execute_task
  File "python\ray\_raylet.pyx", line 1984, in ray._raylet.execute_task
  File "python\ray\_raylet.pyx", line 1889, in ray._raylet.execute_task
  File "python\ray\_raylet.pyx", line 1830, in ray._raylet.execute_task.function_executor
  File "C:\Users\hughj\Documents\GitHub\asfl\env\lib\site-packages\ray\_private\function_manager.py", line 724, in actor_method_executor
    return method(__ray_actor, *args, **kwargs)
  File "C:\Users\hughj\Documents\GitHub\asfl\env\lib\site-packages\ray\util\tracing\tracing_helper.py", line 467, in _resume_span
    return method(self, *_args, **_kwargs)
  File "C:\Users\hughj\Documents\GitHub\asfl\env\lib\site-packages\flwr\simulation\ray_transport\ray_actor.py", line 63, in run
    raise ClientAppException(str(ex)) from ex
flwr.client.client_app.ClientAppException: 
Exception ClientAppException occurred. Message: Invalid partitioner
dv - | ERROR flwr 2024-10-23 14:50:20,301 | vce_api.py:124 | Traceback (most recent call last):
  File "C:\Users\hughj\Documents\GitHub\asfl\env\lib\site-packages\flwr\server\superlink\fleet\vce\vce_api.py", line 112, in worker
    out_mssg, updated_context = backend.process_message(message, context)
  File "C:\Users\hughj\Documents\GitHub\asfl\env\lib\site-packages\flwr\server\superlink\fleet\vce\backend\raybackend.py", line 178, in process_message
    raise ex
  File "C:\Users\hughj\Documents\GitHub\asfl\env\lib\site-packages\flwr\server\superlink\fleet\vce\backend\raybackend.py", line 166, in process_message
    ) = self.pool.fetch_result_and_return_actor_to_pool(future)
  File "C:\Users\hughj\Documents\GitHub\asfl\env\lib\site-packages\flwr\simulation\ray_transport\ray_actor.py", line 477, in fetch_result_and_return_actor_to_pool
    _, out_mssg, updated_context = ray.get(future)
  File "C:\Users\hughj\Documents\GitHub\asfl\env\lib\site-packages\ray\_private\auto_init_hook.py", line 21, in auto_init_wrapper
    return fn(*args, **kwargs)
  File "C:\Users\hughj\Documents\GitHub\asfl\env\lib\site-packages\ray\_private\client_mode_hook.py", line 103, in wrapper
    return func(*args, **kwargs)
  File "C:\Users\hughj\Documents\GitHub\asfl\env\lib\site-packages\ray\_private\worker.py", line 2667, in get
    values, debugger_breakpoint = worker.get_objects(object_refs, timeout=timeout)
  File "C:\Users\hughj\Documents\GitHub\asfl\env\lib\site-packages\ray\_private\worker.py", line 864, in get_objects
    raise value.as_instanceof_cause()
ray.exceptions.RayTaskError(ClientAppException): [36mray::ClientAppActor.run()[39m (pid=14528, ip=127.0.0.1, actor_id=b401871411f2dda3be48ae6d01000000, repr=<flwr.simulation.ray_transport.ray_actor.ClientAppActor object at 0x000001AF19F70940>)
  File "C:\Users\hughj\Documents\GitHub\asfl\env\lib\site-packages\flwr\client\client_app.py", line 143, in __call__
    return self._call(message, context)
  File "C:\Users\hughj\Documents\GitHub\asfl\env\lib\site-packages\flwr\client\client_app.py", line 126, in ffn
    out_message = handle_legacy_message_from_msgtype(
  File "C:\Users\hughj\Documents\GitHub\asfl\env\lib\site-packages\flwr\client\message_handler\message_handler.py", line 95, in handle_legacy_message_from_msgtype
    client = client_fn(context)
  File "C:\Users\hughj\Documents\GitHub\asfl\asfl\client_app.py", line 80, in client_fn
    trainloader, valloader = load_data(context.run_config, partition_id, num_partitions)
  File "C:\Users\hughj\Documents\GitHub\asfl\asfl\task.py", line 72, in load_data
    raise ValueError("Invalid partitioner")
ValueError: Invalid partitioner

The above exception was the direct cause of the following exception:

[36mray::ClientAppActor.run()[39m (pid=14528, ip=127.0.0.1, actor_id=b401871411f2dda3be48ae6d01000000, repr=<flwr.simulation.ray_transport.ray_actor.ClientAppActor object at 0x000001AF19F70940>)
  File "python\ray\_raylet.pyx", line 1883, in ray._raylet.execute_task
  File "python\ray\_raylet.pyx", line 1984, in ray._raylet.execute_task
  File "python\ray\_raylet.pyx", line 1889, in ray._raylet.execute_task
  File "python\ray\_raylet.pyx", line 1830, in ray._raylet.execute_task.function_executor
  File "C:\Users\hughj\Documents\GitHub\asfl\env\lib\site-packages\ray\_private\function_manager.py", line 724, in actor_method_executor
    return method(__ray_actor, *args, **kwargs)
  File "C:\Users\hughj\Documents\GitHub\asfl\env\lib\site-packages\ray\util\tracing\tracing_helper.py", line 467, in _resume_span
    return method(self, *_args, **_kwargs)
  File "C:\Users\hughj\Documents\GitHub\asfl\env\lib\site-packages\flwr\simulation\ray_transport\ray_actor.py", line 63, in run
    raise ClientAppException(str(ex)) from ex
flwr.client.client_app.ClientAppException: 
Exception ClientAppException occurred. Message: Invalid partitioner

dv - | INFO flwr 2024-10-23 14:50:21,174 | server.py:240 | aggregate_fit: received 0 results and 3 failures
dv - | INFO flwr 2024-10-23 14:50:21,174 | server.py:178 | configure_evaluate: strategy sampled 3 clients (out of 3)
dv - | INFO flwr 2024-10-23 14:50:26,233 | server.py:192 | aggregate_evaluate: received 3 results and 0 failures
dv - | INFO flwr 2024-10-23 14:50:26,234 | fed_custom.py:227 | aggregated accuracy: 0.10308969103089691
dv - | INFO flwr 2024-10-23 14:50:26,235 | server.py:496 | 
dv - | INFO flwr 2024-10-23 14:50:26,235 | server.py:497 | [SUMMARY]
dv - | INFO flwr 2024-10-23 14:50:26,236 | server.py:498 | Run finished 1 round(s) in 15.37s
dv - | INFO flwr 2024-10-23 14:50:26,236 | server.py:500 | 	History (loss, distributed):
dv - | INFO flwr 2024-10-23 14:50:26,237 | server.py:500 | 		round 1: 244.7207015795346
dv - | INFO flwr 2024-10-23 14:50:26,238 | server.py:500 | 	History (metrics, distributed, evaluate):
dv - | INFO flwr 2024-10-23 14:50:26,238 | server.py:500 | 	{'accuracy': [(1, 0.10308969103089691)], 'count': [(1, 3)]}
dv - | INFO flwr 2024-10-23 14:50:26,239 | server.py:501 | 
dv - | DEBUG flwr 2024-10-23 14:50:26,242 | run_serverapp.py:90 | ServerApp finished running.
dv - | DEBUG flwr 2024-10-23 14:50:26,242 | run_simulation.py:349 | ServerApp finished running.
dv - | DEBUG flwr 2024-10-23 14:50:26,242 | run_simulation.py:353 | Triggered stop event for Simulation Engine.
dv - | DEBUG flwr 2024-10-23 14:50:27,248 | ray_actor.py:450 | Terminated 4 actors
dv - | DEBUG flwr 2024-10-23 14:50:27,937 | raybackend.py:184 | Terminated RayBackend
dv - | DEBUG flwr 2024-10-23 14:50:27,937 | run_simulation.py:452 | Stopping Simulation Engine now.
dv - | INFO flwr 2024-10-23 14:51:44,989 | server_app.py:88 | file writing: True
dv - | INFO flwr 2024-10-23 14:51:44,990 | server_app.py:89 | running in fed_acc
dv - | INFO flwr 2024-10-23 14:51:44,990 | server_app.py:90 | min num clients 2
dv - | INFO flwr 2024-10-23 14:51:44,990 | server_app.py:91 | num server rounds 1
dv - | INFO flwr 2024-10-23 14:51:44,991 | server_app.py:92 | config num local epochs 1
dv - | INFO flwr 2024-10-23 14:51:44,992 | server_app.py:93 | advanced logging False
dv - | INFO flwr 2024-10-23 14:51:44,992 | server_app.py:94 | partition: dirichlet
dv - | INFO flwr 2024-10-23 14:51:44,992 | app.py:74 | Starting Flower ServerApp, config: num_rounds=1, no round_timeout
dv - | INFO flwr 2024-10-23 14:51:44,994 | app.py:79 | 
dv - | INFO flwr 2024-10-23 14:51:44,995 | server.py:92 | [INIT]
dv - | INFO flwr 2024-10-23 14:51:44,996 | server.py:277 | Using initial global parameters provided by strategy
dv - | INFO flwr 2024-10-23 14:51:44,996 | server.py:94 | Starting evaluation of initial global parameters
dv - | INFO flwr 2024-10-23 14:51:44,996 | server.py:106 | Evaluation returned no results (`None`)
dv - | INFO flwr 2024-10-23 14:51:44,997 | server.py:112 | 
dv - | INFO flwr 2024-10-23 14:51:44,997 | server.py:113 | [ROUND 1]
dv - | INFO flwr 2024-10-23 14:51:44,998 | server.py:226 | configure_fit: strategy sampled 3 clients (out of 3)
dv - | DEBUG flwr 2024-10-23 14:51:48,040 | raybackend.py:136 | Constructed ActorPool with: 4 actors
dv - | DEBUG flwr 2024-10-23 14:51:48,040 | state_factory.py:50 | Using InMemoryState
dv - | ERROR flwr 2024-10-23 14:51:53,816 | raybackend.py:171 | An exception was raised when processing a message by RayBackend
dv - | ERROR flwr 2024-10-23 14:51:53,817 | vce_api.py:123 | [36mray::ClientAppActor.run()[39m (pid=35100, ip=127.0.0.1, actor_id=504a675a091d2950a9d8c25501000000, repr=<flwr.simulation.ray_transport.ray_actor.ClientAppActor object at 0x000001DD9A610910>)
  File "C:\Users\hughj\Documents\GitHub\asfl\env\lib\site-packages\flwr\client\client_app.py", line 143, in __call__
    return self._call(message, context)
  File "C:\Users\hughj\Documents\GitHub\asfl\env\lib\site-packages\flwr\client\client_app.py", line 126, in ffn
    out_message = handle_legacy_message_from_msgtype(
  File "C:\Users\hughj\Documents\GitHub\asfl\env\lib\site-packages\flwr\client\message_handler\message_handler.py", line 95, in handle_legacy_message_from_msgtype
    client = client_fn(context)
  File "C:\Users\hughj\Documents\GitHub\asfl\asfl\client_app.py", line 80, in client_fn
    trainloader, valloader = load_data(context.run_config, partition_id, num_partitions)
  File "C:\Users\hughj\Documents\GitHub\asfl\asfl\task.py", line 73, in load_data
    raise ValueError("Invalid partitioner")
ValueError: Invalid partitioner

The above exception was the direct cause of the following exception:

[36mray::ClientAppActor.run()[39m (pid=35100, ip=127.0.0.1, actor_id=504a675a091d2950a9d8c25501000000, repr=<flwr.simulation.ray_transport.ray_actor.ClientAppActor object at 0x000001DD9A610910>)
  File "python\ray\_raylet.pyx", line 1883, in ray._raylet.execute_task
  File "python\ray\_raylet.pyx", line 1984, in ray._raylet.execute_task
  File "python\ray\_raylet.pyx", line 1889, in ray._raylet.execute_task
  File "python\ray\_raylet.pyx", line 1830, in ray._raylet.execute_task.function_executor
  File "C:\Users\hughj\Documents\GitHub\asfl\env\lib\site-packages\ray\_private\function_manager.py", line 724, in actor_method_executor
    return method(__ray_actor, *args, **kwargs)
  File "C:\Users\hughj\Documents\GitHub\asfl\env\lib\site-packages\ray\util\tracing\tracing_helper.py", line 467, in _resume_span
    return method(self, *_args, **_kwargs)
  File "C:\Users\hughj\Documents\GitHub\asfl\env\lib\site-packages\flwr\simulation\ray_transport\ray_actor.py", line 63, in run
    raise ClientAppException(str(ex)) from ex
flwr.client.client_app.ClientAppException: 
Exception ClientAppException occurred. Message: Invalid partitioner
dv - | ERROR flwr 2024-10-23 14:51:53,820 | vce_api.py:124 | Traceback (most recent call last):
  File "C:\Users\hughj\Documents\GitHub\asfl\env\lib\site-packages\flwr\server\superlink\fleet\vce\vce_api.py", line 112, in worker
    out_mssg, updated_context = backend.process_message(message, context)
  File "C:\Users\hughj\Documents\GitHub\asfl\env\lib\site-packages\flwr\server\superlink\fleet\vce\backend\raybackend.py", line 178, in process_message
    raise ex
  File "C:\Users\hughj\Documents\GitHub\asfl\env\lib\site-packages\flwr\server\superlink\fleet\vce\backend\raybackend.py", line 166, in process_message
    ) = self.pool.fetch_result_and_return_actor_to_pool(future)
  File "C:\Users\hughj\Documents\GitHub\asfl\env\lib\site-packages\flwr\simulation\ray_transport\ray_actor.py", line 477, in fetch_result_and_return_actor_to_pool
    _, out_mssg, updated_context = ray.get(future)
  File "C:\Users\hughj\Documents\GitHub\asfl\env\lib\site-packages\ray\_private\auto_init_hook.py", line 21, in auto_init_wrapper
    return fn(*args, **kwargs)
  File "C:\Users\hughj\Documents\GitHub\asfl\env\lib\site-packages\ray\_private\client_mode_hook.py", line 103, in wrapper
    return func(*args, **kwargs)
  File "C:\Users\hughj\Documents\GitHub\asfl\env\lib\site-packages\ray\_private\worker.py", line 2667, in get
    values, debugger_breakpoint = worker.get_objects(object_refs, timeout=timeout)
  File "C:\Users\hughj\Documents\GitHub\asfl\env\lib\site-packages\ray\_private\worker.py", line 864, in get_objects
    raise value.as_instanceof_cause()
ray.exceptions.RayTaskError(ClientAppException): [36mray::ClientAppActor.run()[39m (pid=35100, ip=127.0.0.1, actor_id=504a675a091d2950a9d8c25501000000, repr=<flwr.simulation.ray_transport.ray_actor.ClientAppActor object at 0x000001DD9A610910>)
  File "C:\Users\hughj\Documents\GitHub\asfl\env\lib\site-packages\flwr\client\client_app.py", line 143, in __call__
    return self._call(message, context)
  File "C:\Users\hughj\Documents\GitHub\asfl\env\lib\site-packages\flwr\client\client_app.py", line 126, in ffn
    out_message = handle_legacy_message_from_msgtype(
  File "C:\Users\hughj\Documents\GitHub\asfl\env\lib\site-packages\flwr\client\message_handler\message_handler.py", line 95, in handle_legacy_message_from_msgtype
    client = client_fn(context)
  File "C:\Users\hughj\Documents\GitHub\asfl\asfl\client_app.py", line 80, in client_fn
    trainloader, valloader = load_data(context.run_config, partition_id, num_partitions)
  File "C:\Users\hughj\Documents\GitHub\asfl\asfl\task.py", line 73, in load_data
    raise ValueError("Invalid partitioner")
ValueError: Invalid partitioner

The above exception was the direct cause of the following exception:

[36mray::ClientAppActor.run()[39m (pid=35100, ip=127.0.0.1, actor_id=504a675a091d2950a9d8c25501000000, repr=<flwr.simulation.ray_transport.ray_actor.ClientAppActor object at 0x000001DD9A610910>)
  File "python\ray\_raylet.pyx", line 1883, in ray._raylet.execute_task
  File "python\ray\_raylet.pyx", line 1984, in ray._raylet.execute_task
  File "python\ray\_raylet.pyx", line 1889, in ray._raylet.execute_task
  File "python\ray\_raylet.pyx", line 1830, in ray._raylet.execute_task.function_executor
  File "C:\Users\hughj\Documents\GitHub\asfl\env\lib\site-packages\ray\_private\function_manager.py", line 724, in actor_method_executor
    return method(__ray_actor, *args, **kwargs)
  File "C:\Users\hughj\Documents\GitHub\asfl\env\lib\site-packages\ray\util\tracing\tracing_helper.py", line 467, in _resume_span
    return method(self, *_args, **_kwargs)
  File "C:\Users\hughj\Documents\GitHub\asfl\env\lib\site-packages\flwr\simulation\ray_transport\ray_actor.py", line 63, in run
    raise ClientAppException(str(ex)) from ex
flwr.client.client_app.ClientAppException: 
Exception ClientAppException occurred. Message: Invalid partitioner

dv - | ERROR flwr 2024-10-23 14:51:53,835 | raybackend.py:171 | An exception was raised when processing a message by RayBackend
dv - | ERROR flwr 2024-10-23 14:51:53,836 | raybackend.py:171 | An exception was raised when processing a message by RayBackend
dv - | ERROR flwr 2024-10-23 14:51:53,836 | vce_api.py:123 | [36mray::ClientAppActor.run()[39m (pid=28220, ip=127.0.0.1, actor_id=6330965f4226563e50890c1901000000, repr=<flwr.simulation.ray_transport.ray_actor.ClientAppActor object at 0x000002E7B73A0970>)
  File "C:\Users\hughj\Documents\GitHub\asfl\env\lib\site-packages\flwr\client\client_app.py", line 143, in __call__
    return self._call(message, context)
  File "C:\Users\hughj\Documents\GitHub\asfl\env\lib\site-packages\flwr\client\client_app.py", line 126, in ffn
    out_message = handle_legacy_message_from_msgtype(
  File "C:\Users\hughj\Documents\GitHub\asfl\env\lib\site-packages\flwr\client\message_handler\message_handler.py", line 95, in handle_legacy_message_from_msgtype
    client = client_fn(context)
  File "C:\Users\hughj\Documents\GitHub\asfl\asfl\client_app.py", line 80, in client_fn
    trainloader, valloader = load_data(context.run_config, partition_id, num_partitions)
  File "C:\Users\hughj\Documents\GitHub\asfl\asfl\task.py", line 73, in load_data
    raise ValueError("Invalid partitioner")
ValueError: Invalid partitioner

The above exception was the direct cause of the following exception:

[36mray::ClientAppActor.run()[39m (pid=28220, ip=127.0.0.1, actor_id=6330965f4226563e50890c1901000000, repr=<flwr.simulation.ray_transport.ray_actor.ClientAppActor object at 0x000002E7B73A0970>)
  File "python\ray\_raylet.pyx", line 1883, in ray._raylet.execute_task
  File "python\ray\_raylet.pyx", line 1984, in ray._raylet.execute_task
  File "python\ray\_raylet.pyx", line 1889, in ray._raylet.execute_task
  File "python\ray\_raylet.pyx", line 1830, in ray._raylet.execute_task.function_executor
  File "C:\Users\hughj\Documents\GitHub\asfl\env\lib\site-packages\ray\_private\function_manager.py", line 724, in actor_method_executor
    return method(__ray_actor, *args, **kwargs)
  File "C:\Users\hughj\Documents\GitHub\asfl\env\lib\site-packages\ray\util\tracing\tracing_helper.py", line 467, in _resume_span
    return method(self, *_args, **_kwargs)
  File "C:\Users\hughj\Documents\GitHub\asfl\env\lib\site-packages\flwr\simulation\ray_transport\ray_actor.py", line 63, in run
    raise ClientAppException(str(ex)) from ex
flwr.client.client_app.ClientAppException: 
Exception ClientAppException occurred. Message: Invalid partitioner
dv - | ERROR flwr 2024-10-23 14:51:53,837 | vce_api.py:123 | [36mray::ClientAppActor.run()[39m (pid=21704, ip=127.0.0.1, actor_id=70bc2300586553cb6320ce3101000000, repr=<flwr.simulation.ray_transport.ray_actor.ClientAppActor object at 0x000001F7274D0970>)
  File "C:\Users\hughj\Documents\GitHub\asfl\env\lib\site-packages\flwr\client\client_app.py", line 143, in __call__
    return self._call(message, context)
  File "C:\Users\hughj\Documents\GitHub\asfl\env\lib\site-packages\flwr\client\client_app.py", line 126, in ffn
    out_message = handle_legacy_message_from_msgtype(
  File "C:\Users\hughj\Documents\GitHub\asfl\env\lib\site-packages\flwr\client\message_handler\message_handler.py", line 95, in handle_legacy_message_from_msgtype
    client = client_fn(context)
  File "C:\Users\hughj\Documents\GitHub\asfl\asfl\client_app.py", line 80, in client_fn
    trainloader, valloader = load_data(context.run_config, partition_id, num_partitions)
  File "C:\Users\hughj\Documents\GitHub\asfl\asfl\task.py", line 73, in load_data
    raise ValueError("Invalid partitioner")
ValueError: Invalid partitioner

The above exception was the direct cause of the following exception:

[36mray::ClientAppActor.run()[39m (pid=21704, ip=127.0.0.1, actor_id=70bc2300586553cb6320ce3101000000, repr=<flwr.simulation.ray_transport.ray_actor.ClientAppActor object at 0x000001F7274D0970>)
  File "python\ray\_raylet.pyx", line 1883, in ray._raylet.execute_task
  File "python\ray\_raylet.pyx", line 1984, in ray._raylet.execute_task
  File "python\ray\_raylet.pyx", line 1889, in ray._raylet.execute_task
  File "python\ray\_raylet.pyx", line 1830, in ray._raylet.execute_task.function_executor
  File "C:\Users\hughj\Documents\GitHub\asfl\env\lib\site-packages\ray\_private\function_manager.py", line 724, in actor_method_executor
    return method(__ray_actor, *args, **kwargs)
  File "C:\Users\hughj\Documents\GitHub\asfl\env\lib\site-packages\ray\util\tracing\tracing_helper.py", line 467, in _resume_span
    return method(self, *_args, **_kwargs)
  File "C:\Users\hughj\Documents\GitHub\asfl\env\lib\site-packages\flwr\simulation\ray_transport\ray_actor.py", line 63, in run
    raise ClientAppException(str(ex)) from ex
flwr.client.client_app.ClientAppException: 
Exception ClientAppException occurred. Message: Invalid partitioner
dv - | ERROR flwr 2024-10-23 14:51:53,838 | vce_api.py:124 | Traceback (most recent call last):
  File "C:\Users\hughj\Documents\GitHub\asfl\env\lib\site-packages\flwr\server\superlink\fleet\vce\vce_api.py", line 112, in worker
    out_mssg, updated_context = backend.process_message(message, context)
  File "C:\Users\hughj\Documents\GitHub\asfl\env\lib\site-packages\flwr\server\superlink\fleet\vce\backend\raybackend.py", line 178, in process_message
    raise ex
  File "C:\Users\hughj\Documents\GitHub\asfl\env\lib\site-packages\flwr\server\superlink\fleet\vce\backend\raybackend.py", line 166, in process_message
    ) = self.pool.fetch_result_and_return_actor_to_pool(future)
  File "C:\Users\hughj\Documents\GitHub\asfl\env\lib\site-packages\flwr\simulation\ray_transport\ray_actor.py", line 477, in fetch_result_and_return_actor_to_pool
    _, out_mssg, updated_context = ray.get(future)
  File "C:\Users\hughj\Documents\GitHub\asfl\env\lib\site-packages\ray\_private\auto_init_hook.py", line 21, in auto_init_wrapper
    return fn(*args, **kwargs)
  File "C:\Users\hughj\Documents\GitHub\asfl\env\lib\site-packages\ray\_private\client_mode_hook.py", line 103, in wrapper
    return func(*args, **kwargs)
  File "C:\Users\hughj\Documents\GitHub\asfl\env\lib\site-packages\ray\_private\worker.py", line 2667, in get
    values, debugger_breakpoint = worker.get_objects(object_refs, timeout=timeout)
  File "C:\Users\hughj\Documents\GitHub\asfl\env\lib\site-packages\ray\_private\worker.py", line 864, in get_objects
    raise value.as_instanceof_cause()
ray.exceptions.RayTaskError(ClientAppException): [36mray::ClientAppActor.run()[39m (pid=28220, ip=127.0.0.1, actor_id=6330965f4226563e50890c1901000000, repr=<flwr.simulation.ray_transport.ray_actor.ClientAppActor object at 0x000002E7B73A0970>)
  File "C:\Users\hughj\Documents\GitHub\asfl\env\lib\site-packages\flwr\client\client_app.py", line 143, in __call__
    return self._call(message, context)
  File "C:\Users\hughj\Documents\GitHub\asfl\env\lib\site-packages\flwr\client\client_app.py", line 126, in ffn
    out_message = handle_legacy_message_from_msgtype(
  File "C:\Users\hughj\Documents\GitHub\asfl\env\lib\site-packages\flwr\client\message_handler\message_handler.py", line 95, in handle_legacy_message_from_msgtype
    client = client_fn(context)
  File "C:\Users\hughj\Documents\GitHub\asfl\asfl\client_app.py", line 80, in client_fn
    trainloader, valloader = load_data(context.run_config, partition_id, num_partitions)
  File "C:\Users\hughj\Documents\GitHub\asfl\asfl\task.py", line 73, in load_data
    raise ValueError("Invalid partitioner")
ValueError: Invalid partitioner

The above exception was the direct cause of the following exception:

[36mray::ClientAppActor.run()[39m (pid=28220, ip=127.0.0.1, actor_id=6330965f4226563e50890c1901000000, repr=<flwr.simulation.ray_transport.ray_actor.ClientAppActor object at 0x000002E7B73A0970>)
  File "python\ray\_raylet.pyx", line 1883, in ray._raylet.execute_task
  File "python\ray\_raylet.pyx", line 1984, in ray._raylet.execute_task
  File "python\ray\_raylet.pyx", line 1889, in ray._raylet.execute_task
  File "python\ray\_raylet.pyx", line 1830, in ray._raylet.execute_task.function_executor
  File "C:\Users\hughj\Documents\GitHub\asfl\env\lib\site-packages\ray\_private\function_manager.py", line 724, in actor_method_executor
    return method(__ray_actor, *args, **kwargs)
  File "C:\Users\hughj\Documents\GitHub\asfl\env\lib\site-packages\ray\util\tracing\tracing_helper.py", line 467, in _resume_span
    return method(self, *_args, **_kwargs)
  File "C:\Users\hughj\Documents\GitHub\asfl\env\lib\site-packages\flwr\simulation\ray_transport\ray_actor.py", line 63, in run
    raise ClientAppException(str(ex)) from ex
flwr.client.client_app.ClientAppException: 
Exception ClientAppException occurred. Message: Invalid partitioner

dv - | ERROR flwr 2024-10-23 14:51:53,840 | vce_api.py:124 | Traceback (most recent call last):
  File "C:\Users\hughj\Documents\GitHub\asfl\env\lib\site-packages\flwr\server\superlink\fleet\vce\vce_api.py", line 112, in worker
    out_mssg, updated_context = backend.process_message(message, context)
  File "C:\Users\hughj\Documents\GitHub\asfl\env\lib\site-packages\flwr\server\superlink\fleet\vce\backend\raybackend.py", line 178, in process_message
    raise ex
  File "C:\Users\hughj\Documents\GitHub\asfl\env\lib\site-packages\flwr\server\superlink\fleet\vce\backend\raybackend.py", line 166, in process_message
    ) = self.pool.fetch_result_and_return_actor_to_pool(future)
  File "C:\Users\hughj\Documents\GitHub\asfl\env\lib\site-packages\flwr\simulation\ray_transport\ray_actor.py", line 477, in fetch_result_and_return_actor_to_pool
    _, out_mssg, updated_context = ray.get(future)
  File "C:\Users\hughj\Documents\GitHub\asfl\env\lib\site-packages\ray\_private\auto_init_hook.py", line 21, in auto_init_wrapper
    return fn(*args, **kwargs)
  File "C:\Users\hughj\Documents\GitHub\asfl\env\lib\site-packages\ray\_private\client_mode_hook.py", line 103, in wrapper
    return func(*args, **kwargs)
  File "C:\Users\hughj\Documents\GitHub\asfl\env\lib\site-packages\ray\_private\worker.py", line 2667, in get
    values, debugger_breakpoint = worker.get_objects(object_refs, timeout=timeout)
  File "C:\Users\hughj\Documents\GitHub\asfl\env\lib\site-packages\ray\_private\worker.py", line 864, in get_objects
    raise value.as_instanceof_cause()
ray.exceptions.RayTaskError(ClientAppException): [36mray::ClientAppActor.run()[39m (pid=21704, ip=127.0.0.1, actor_id=70bc2300586553cb6320ce3101000000, repr=<flwr.simulation.ray_transport.ray_actor.ClientAppActor object at 0x000001F7274D0970>)
  File "C:\Users\hughj\Documents\GitHub\asfl\env\lib\site-packages\flwr\client\client_app.py", line 143, in __call__
    return self._call(message, context)
  File "C:\Users\hughj\Documents\GitHub\asfl\env\lib\site-packages\flwr\client\client_app.py", line 126, in ffn
    out_message = handle_legacy_message_from_msgtype(
  File "C:\Users\hughj\Documents\GitHub\asfl\env\lib\site-packages\flwr\client\message_handler\message_handler.py", line 95, in handle_legacy_message_from_msgtype
    client = client_fn(context)
  File "C:\Users\hughj\Documents\GitHub\asfl\asfl\client_app.py", line 80, in client_fn
    trainloader, valloader = load_data(context.run_config, partition_id, num_partitions)
  File "C:\Users\hughj\Documents\GitHub\asfl\asfl\task.py", line 73, in load_data
    raise ValueError("Invalid partitioner")
ValueError: Invalid partitioner

The above exception was the direct cause of the following exception:

[36mray::ClientAppActor.run()[39m (pid=21704, ip=127.0.0.1, actor_id=70bc2300586553cb6320ce3101000000, repr=<flwr.simulation.ray_transport.ray_actor.ClientAppActor object at 0x000001F7274D0970>)
  File "python\ray\_raylet.pyx", line 1883, in ray._raylet.execute_task
  File "python\ray\_raylet.pyx", line 1984, in ray._raylet.execute_task
  File "python\ray\_raylet.pyx", line 1889, in ray._raylet.execute_task
  File "python\ray\_raylet.pyx", line 1830, in ray._raylet.execute_task.function_executor
  File "C:\Users\hughj\Documents\GitHub\asfl\env\lib\site-packages\ray\_private\function_manager.py", line 724, in actor_method_executor
    return method(__ray_actor, *args, **kwargs)
  File "C:\Users\hughj\Documents\GitHub\asfl\env\lib\site-packages\ray\util\tracing\tracing_helper.py", line 467, in _resume_span
    return method(self, *_args, **_kwargs)
  File "C:\Users\hughj\Documents\GitHub\asfl\env\lib\site-packages\flwr\simulation\ray_transport\ray_actor.py", line 63, in run
    raise ClientAppException(str(ex)) from ex
flwr.client.client_app.ClientAppException: 
Exception ClientAppException occurred. Message: Invalid partitioner

dv - | INFO flwr 2024-10-23 14:51:54,077 | server.py:240 | aggregate_fit: received 0 results and 3 failures
dv - | INFO flwr 2024-10-23 14:51:54,078 | server.py:178 | configure_evaluate: strategy sampled 3 clients (out of 3)
dv - | INFO flwr 2024-10-23 14:51:59,113 | server.py:192 | aggregate_evaluate: received 3 results and 0 failures
dv - | INFO flwr 2024-10-23 14:51:59,116 | fed_custom.py:227 | aggregated accuracy: 0.10058994100589941
dv - | INFO flwr 2024-10-23 14:51:59,116 | server.py:496 | 
dv - | INFO flwr 2024-10-23 14:51:59,117 | server.py:497 | [SUMMARY]
dv - | INFO flwr 2024-10-23 14:51:59,118 | server.py:498 | Run finished 1 round(s) in 14.12s
dv - | INFO flwr 2024-10-23 14:51:59,119 | server.py:500 | 	History (loss, distributed):
dv - | INFO flwr 2024-10-23 14:51:59,119 | server.py:500 | 		round 1: 244.44329165520756
dv - | INFO flwr 2024-10-23 14:51:59,120 | server.py:500 | 	History (metrics, distributed, evaluate):
dv - | INFO flwr 2024-10-23 14:51:59,121 | server.py:500 | 	{'accuracy': [(1, 0.10058994100589941)], 'count': [(1, 3)]}
dv - | INFO flwr 2024-10-23 14:51:59,121 | server.py:501 | 
dv - | DEBUG flwr 2024-10-23 14:51:59,124 | run_serverapp.py:90 | ServerApp finished running.
dv - | DEBUG flwr 2024-10-23 14:51:59,124 | run_simulation.py:349 | ServerApp finished running.
dv - | DEBUG flwr 2024-10-23 14:51:59,124 | run_simulation.py:353 | Triggered stop event for Simulation Engine.
dv - | DEBUG flwr 2024-10-23 14:52:00,121 | ray_actor.py:450 | Terminated 4 actors
dv - | DEBUG flwr 2024-10-23 14:52:00,857 | raybackend.py:184 | Terminated RayBackend
dv - | DEBUG flwr 2024-10-23 14:52:00,857 | run_simulation.py:452 | Stopping Simulation Engine now.
dv - | INFO flwr 2024-10-23 14:52:43,790 | server_app.py:88 | file writing: True
dv - | INFO flwr 2024-10-23 14:52:43,791 | server_app.py:89 | running in fed_acc
dv - | INFO flwr 2024-10-23 14:52:43,791 | server_app.py:90 | min num clients 2
dv - | INFO flwr 2024-10-23 14:52:43,792 | server_app.py:91 | num server rounds 1
dv - | INFO flwr 2024-10-23 14:52:43,794 | server_app.py:92 | config num local epochs 1
dv - | INFO flwr 2024-10-23 14:52:43,794 | server_app.py:93 | advanced logging False
dv - | INFO flwr 2024-10-23 14:52:43,795 | server_app.py:94 | partition: dirichlet
dv - | INFO flwr 2024-10-23 14:52:43,795 | app.py:74 | Starting Flower ServerApp, config: num_rounds=1, no round_timeout
dv - | INFO flwr 2024-10-23 14:52:43,796 | app.py:79 | 
dv - | INFO flwr 2024-10-23 14:52:43,797 | server.py:92 | [INIT]
dv - | INFO flwr 2024-10-23 14:52:43,798 | server.py:277 | Using initial global parameters provided by strategy
dv - | INFO flwr 2024-10-23 14:52:43,798 | server.py:94 | Starting evaluation of initial global parameters
dv - | INFO flwr 2024-10-23 14:52:43,798 | server.py:106 | Evaluation returned no results (`None`)
dv - | INFO flwr 2024-10-23 14:52:43,799 | server.py:112 | 
dv - | INFO flwr 2024-10-23 14:52:43,799 | server.py:113 | [ROUND 1]
dv - | INFO flwr 2024-10-23 14:52:43,800 | server.py:226 | configure_fit: strategy sampled 3 clients (out of 3)
dv - | DEBUG flwr 2024-10-23 14:52:46,746 | raybackend.py:136 | Constructed ActorPool with: 4 actors
dv - | DEBUG flwr 2024-10-23 14:52:46,746 | state_factory.py:50 | Using InMemoryState
dv - | ERROR flwr 2024-10-23 14:52:52,454 | raybackend.py:171 | An exception was raised when processing a message by RayBackend
dv - | ERROR flwr 2024-10-23 14:52:52,454 | vce_api.py:123 | [36mray::ClientAppActor.run()[39m (pid=23508, ip=127.0.0.1, actor_id=75fcc8cf952a3f94355275ce01000000, repr=<flwr.simulation.ray_transport.ray_actor.ClientAppActor object at 0x000001ED3CBC0910>)
  File "C:\Users\hughj\Documents\GitHub\asfl\env\lib\site-packages\flwr\client\client_app.py", line 143, in __call__
    return self._call(message, context)
  File "C:\Users\hughj\Documents\GitHub\asfl\env\lib\site-packages\flwr\client\client_app.py", line 126, in ffn
    out_message = handle_legacy_message_from_msgtype(
  File "C:\Users\hughj\Documents\GitHub\asfl\env\lib\site-packages\flwr\client\message_handler\message_handler.py", line 95, in handle_legacy_message_from_msgtype
    client = client_fn(context)
  File "C:\Users\hughj\Documents\GitHub\asfl\asfl\client_app.py", line 80, in client_fn
    trainloader, valloader = load_data(context.run_config, partition_id, num_partitions)
  File "C:\Users\hughj\Documents\GitHub\asfl\asfl\task.py", line 73, in load_data
    raise ValueError("Invalid partitioner: " + node_config["partition"])
ValueError: Invalid partitioner: dirichlet

The above exception was the direct cause of the following exception:

[36mray::ClientAppActor.run()[39m (pid=23508, ip=127.0.0.1, actor_id=75fcc8cf952a3f94355275ce01000000, repr=<flwr.simulation.ray_transport.ray_actor.ClientAppActor object at 0x000001ED3CBC0910>)
  File "python\ray\_raylet.pyx", line 1883, in ray._raylet.execute_task
  File "python\ray\_raylet.pyx", line 1984, in ray._raylet.execute_task
  File "python\ray\_raylet.pyx", line 1889, in ray._raylet.execute_task
  File "python\ray\_raylet.pyx", line 1830, in ray._raylet.execute_task.function_executor
  File "C:\Users\hughj\Documents\GitHub\asfl\env\lib\site-packages\ray\_private\function_manager.py", line 724, in actor_method_executor
    return method(__ray_actor, *args, **kwargs)
  File "C:\Users\hughj\Documents\GitHub\asfl\env\lib\site-packages\ray\util\tracing\tracing_helper.py", line 467, in _resume_span
    return method(self, *_args, **_kwargs)
  File "C:\Users\hughj\Documents\GitHub\asfl\env\lib\site-packages\flwr\simulation\ray_transport\ray_actor.py", line 63, in run
    raise ClientAppException(str(ex)) from ex
flwr.client.client_app.ClientAppException: 
Exception ClientAppException occurred. Message: Invalid partitioner: dirichlet
dv - | ERROR flwr 2024-10-23 14:52:52,458 | vce_api.py:124 | Traceback (most recent call last):
  File "C:\Users\hughj\Documents\GitHub\asfl\env\lib\site-packages\flwr\server\superlink\fleet\vce\vce_api.py", line 112, in worker
    out_mssg, updated_context = backend.process_message(message, context)
  File "C:\Users\hughj\Documents\GitHub\asfl\env\lib\site-packages\flwr\server\superlink\fleet\vce\backend\raybackend.py", line 178, in process_message
    raise ex
  File "C:\Users\hughj\Documents\GitHub\asfl\env\lib\site-packages\flwr\server\superlink\fleet\vce\backend\raybackend.py", line 166, in process_message
    ) = self.pool.fetch_result_and_return_actor_to_pool(future)
  File "C:\Users\hughj\Documents\GitHub\asfl\env\lib\site-packages\flwr\simulation\ray_transport\ray_actor.py", line 477, in fetch_result_and_return_actor_to_pool
    _, out_mssg, updated_context = ray.get(future)
  File "C:\Users\hughj\Documents\GitHub\asfl\env\lib\site-packages\ray\_private\auto_init_hook.py", line 21, in auto_init_wrapper
    return fn(*args, **kwargs)
  File "C:\Users\hughj\Documents\GitHub\asfl\env\lib\site-packages\ray\_private\client_mode_hook.py", line 103, in wrapper
    return func(*args, **kwargs)
  File "C:\Users\hughj\Documents\GitHub\asfl\env\lib\site-packages\ray\_private\worker.py", line 2667, in get
    values, debugger_breakpoint = worker.get_objects(object_refs, timeout=timeout)
  File "C:\Users\hughj\Documents\GitHub\asfl\env\lib\site-packages\ray\_private\worker.py", line 864, in get_objects
    raise value.as_instanceof_cause()
ray.exceptions.RayTaskError(ClientAppException): [36mray::ClientAppActor.run()[39m (pid=23508, ip=127.0.0.1, actor_id=75fcc8cf952a3f94355275ce01000000, repr=<flwr.simulation.ray_transport.ray_actor.ClientAppActor object at 0x000001ED3CBC0910>)
  File "C:\Users\hughj\Documents\GitHub\asfl\env\lib\site-packages\flwr\client\client_app.py", line 143, in __call__
    return self._call(message, context)
  File "C:\Users\hughj\Documents\GitHub\asfl\env\lib\site-packages\flwr\client\client_app.py", line 126, in ffn
    out_message = handle_legacy_message_from_msgtype(
  File "C:\Users\hughj\Documents\GitHub\asfl\env\lib\site-packages\flwr\client\message_handler\message_handler.py", line 95, in handle_legacy_message_from_msgtype
    client = client_fn(context)
  File "C:\Users\hughj\Documents\GitHub\asfl\asfl\client_app.py", line 80, in client_fn
    trainloader, valloader = load_data(context.run_config, partition_id, num_partitions)
  File "C:\Users\hughj\Documents\GitHub\asfl\asfl\task.py", line 73, in load_data
    raise ValueError("Invalid partitioner: " + node_config["partition"])
ValueError: Invalid partitioner: dirichlet

The above exception was the direct cause of the following exception:

[36mray::ClientAppActor.run()[39m (pid=23508, ip=127.0.0.1, actor_id=75fcc8cf952a3f94355275ce01000000, repr=<flwr.simulation.ray_transport.ray_actor.ClientAppActor object at 0x000001ED3CBC0910>)
  File "python\ray\_raylet.pyx", line 1883, in ray._raylet.execute_task
  File "python\ray\_raylet.pyx", line 1984, in ray._raylet.execute_task
  File "python\ray\_raylet.pyx", line 1889, in ray._raylet.execute_task
  File "python\ray\_raylet.pyx", line 1830, in ray._raylet.execute_task.function_executor
  File "C:\Users\hughj\Documents\GitHub\asfl\env\lib\site-packages\ray\_private\function_manager.py", line 724, in actor_method_executor
    return method(__ray_actor, *args, **kwargs)
  File "C:\Users\hughj\Documents\GitHub\asfl\env\lib\site-packages\ray\util\tracing\tracing_helper.py", line 467, in _resume_span
    return method(self, *_args, **_kwargs)
  File "C:\Users\hughj\Documents\GitHub\asfl\env\lib\site-packages\flwr\simulation\ray_transport\ray_actor.py", line 63, in run
    raise ClientAppException(str(ex)) from ex
flwr.client.client_app.ClientAppException: 
Exception ClientAppException occurred. Message: Invalid partitioner: dirichlet

dv - | ERROR flwr 2024-10-23 14:52:52,472 | raybackend.py:171 | An exception was raised when processing a message by RayBackend
dv - | ERROR flwr 2024-10-23 14:52:52,472 | vce_api.py:123 | [36mray::ClientAppActor.run()[39m (pid=35148, ip=127.0.0.1, actor_id=5d1f3704494f08d6f9bca2ab01000000, repr=<flwr.simulation.ray_transport.ray_actor.ClientAppActor object at 0x00000207111E0910>)
  File "C:\Users\hughj\Documents\GitHub\asfl\env\lib\site-packages\flwr\client\client_app.py", line 143, in __call__
    return self._call(message, context)
  File "C:\Users\hughj\Documents\GitHub\asfl\env\lib\site-packages\flwr\client\client_app.py", line 126, in ffn
    out_message = handle_legacy_message_from_msgtype(
  File "C:\Users\hughj\Documents\GitHub\asfl\env\lib\site-packages\flwr\client\message_handler\message_handler.py", line 95, in handle_legacy_message_from_msgtype
    client = client_fn(context)
  File "C:\Users\hughj\Documents\GitHub\asfl\asfl\client_app.py", line 80, in client_fn
    trainloader, valloader = load_data(context.run_config, partition_id, num_partitions)
  File "C:\Users\hughj\Documents\GitHub\asfl\asfl\task.py", line 73, in load_data
    raise ValueError("Invalid partitioner: " + node_config["partition"])
ValueError: Invalid partitioner: dirichlet

The above exception was the direct cause of the following exception:

[36mray::ClientAppActor.run()[39m (pid=35148, ip=127.0.0.1, actor_id=5d1f3704494f08d6f9bca2ab01000000, repr=<flwr.simulation.ray_transport.ray_actor.ClientAppActor object at 0x00000207111E0910>)
  File "python\ray\_raylet.pyx", line 1883, in ray._raylet.execute_task
  File "python\ray\_raylet.pyx", line 1984, in ray._raylet.execute_task
  File "python\ray\_raylet.pyx", line 1889, in ray._raylet.execute_task
  File "python\ray\_raylet.pyx", line 1830, in ray._raylet.execute_task.function_executor
  File "C:\Users\hughj\Documents\GitHub\asfl\env\lib\site-packages\ray\_private\function_manager.py", line 724, in actor_method_executor
    return method(__ray_actor, *args, **kwargs)
  File "C:\Users\hughj\Documents\GitHub\asfl\env\lib\site-packages\ray\util\tracing\tracing_helper.py", line 467, in _resume_span
    return method(self, *_args, **_kwargs)
  File "C:\Users\hughj\Documents\GitHub\asfl\env\lib\site-packages\flwr\simulation\ray_transport\ray_actor.py", line 63, in run
    raise ClientAppException(str(ex)) from ex
flwr.client.client_app.ClientAppException: 
Exception ClientAppException occurred. Message: Invalid partitioner: dirichlet
dv - | ERROR flwr 2024-10-23 14:52:52,474 | vce_api.py:124 | Traceback (most recent call last):
  File "C:\Users\hughj\Documents\GitHub\asfl\env\lib\site-packages\flwr\server\superlink\fleet\vce\vce_api.py", line 112, in worker
    out_mssg, updated_context = backend.process_message(message, context)
  File "C:\Users\hughj\Documents\GitHub\asfl\env\lib\site-packages\flwr\server\superlink\fleet\vce\backend\raybackend.py", line 178, in process_message
    raise ex
  File "C:\Users\hughj\Documents\GitHub\asfl\env\lib\site-packages\flwr\server\superlink\fleet\vce\backend\raybackend.py", line 166, in process_message
    ) = self.pool.fetch_result_and_return_actor_to_pool(future)
  File "C:\Users\hughj\Documents\GitHub\asfl\env\lib\site-packages\flwr\simulation\ray_transport\ray_actor.py", line 477, in fetch_result_and_return_actor_to_pool
    _, out_mssg, updated_context = ray.get(future)
  File "C:\Users\hughj\Documents\GitHub\asfl\env\lib\site-packages\ray\_private\auto_init_hook.py", line 21, in auto_init_wrapper
    return fn(*args, **kwargs)
  File "C:\Users\hughj\Documents\GitHub\asfl\env\lib\site-packages\ray\_private\client_mode_hook.py", line 103, in wrapper
    return func(*args, **kwargs)
  File "C:\Users\hughj\Documents\GitHub\asfl\env\lib\site-packages\ray\_private\worker.py", line 2667, in get
    values, debugger_breakpoint = worker.get_objects(object_refs, timeout=timeout)
  File "C:\Users\hughj\Documents\GitHub\asfl\env\lib\site-packages\ray\_private\worker.py", line 864, in get_objects
    raise value.as_instanceof_cause()
ray.exceptions.RayTaskError(ClientAppException): [36mray::ClientAppActor.run()[39m (pid=35148, ip=127.0.0.1, actor_id=5d1f3704494f08d6f9bca2ab01000000, repr=<flwr.simulation.ray_transport.ray_actor.ClientAppActor object at 0x00000207111E0910>)
  File "C:\Users\hughj\Documents\GitHub\asfl\env\lib\site-packages\flwr\client\client_app.py", line 143, in __call__
    return self._call(message, context)
  File "C:\Users\hughj\Documents\GitHub\asfl\env\lib\site-packages\flwr\client\client_app.py", line 126, in ffn
    out_message = handle_legacy_message_from_msgtype(
  File "C:\Users\hughj\Documents\GitHub\asfl\env\lib\site-packages\flwr\client\message_handler\message_handler.py", line 95, in handle_legacy_message_from_msgtype
    client = client_fn(context)
  File "C:\Users\hughj\Documents\GitHub\asfl\asfl\client_app.py", line 80, in client_fn
    trainloader, valloader = load_data(context.run_config, partition_id, num_partitions)
  File "C:\Users\hughj\Documents\GitHub\asfl\asfl\task.py", line 73, in load_data
    raise ValueError("Invalid partitioner: " + node_config["partition"])
ValueError: Invalid partitioner: dirichlet

The above exception was the direct cause of the following exception:

[36mray::ClientAppActor.run()[39m (pid=35148, ip=127.0.0.1, actor_id=5d1f3704494f08d6f9bca2ab01000000, repr=<flwr.simulation.ray_transport.ray_actor.ClientAppActor object at 0x00000207111E0910>)
  File "python\ray\_raylet.pyx", line 1883, in ray._raylet.execute_task
  File "python\ray\_raylet.pyx", line 1984, in ray._raylet.execute_task
  File "python\ray\_raylet.pyx", line 1889, in ray._raylet.execute_task
  File "python\ray\_raylet.pyx", line 1830, in ray._raylet.execute_task.function_executor
  File "C:\Users\hughj\Documents\GitHub\asfl\env\lib\site-packages\ray\_private\function_manager.py", line 724, in actor_method_executor
    return method(__ray_actor, *args, **kwargs)
  File "C:\Users\hughj\Documents\GitHub\asfl\env\lib\site-packages\ray\util\tracing\tracing_helper.py", line 467, in _resume_span
    return method(self, *_args, **_kwargs)
  File "C:\Users\hughj\Documents\GitHub\asfl\env\lib\site-packages\flwr\simulation\ray_transport\ray_actor.py", line 63, in run
    raise ClientAppException(str(ex)) from ex
flwr.client.client_app.ClientAppException: 
Exception ClientAppException occurred. Message: Invalid partitioner: dirichlet

dv - | ERROR flwr 2024-10-23 14:52:52,493 | raybackend.py:171 | An exception was raised when processing a message by RayBackend
dv - | ERROR flwr 2024-10-23 14:52:52,494 | vce_api.py:123 | [36mray::ClientAppActor.run()[39m (pid=33540, ip=127.0.0.1, actor_id=eab08446529413fe9f69fe5f01000000, repr=<flwr.simulation.ray_transport.ray_actor.ClientAppActor object at 0x0000026EEED308E0>)
  File "C:\Users\hughj\Documents\GitHub\asfl\env\lib\site-packages\flwr\client\client_app.py", line 143, in __call__
    return self._call(message, context)
  File "C:\Users\hughj\Documents\GitHub\asfl\env\lib\site-packages\flwr\client\client_app.py", line 126, in ffn
    out_message = handle_legacy_message_from_msgtype(
  File "C:\Users\hughj\Documents\GitHub\asfl\env\lib\site-packages\flwr\client\message_handler\message_handler.py", line 95, in handle_legacy_message_from_msgtype
    client = client_fn(context)
  File "C:\Users\hughj\Documents\GitHub\asfl\asfl\client_app.py", line 80, in client_fn
    trainloader, valloader = load_data(context.run_config, partition_id, num_partitions)
  File "C:\Users\hughj\Documents\GitHub\asfl\asfl\task.py", line 73, in load_data
    raise ValueError("Invalid partitioner: " + node_config["partition"])
ValueError: Invalid partitioner: dirichlet

The above exception was the direct cause of the following exception:

[36mray::ClientAppActor.run()[39m (pid=33540, ip=127.0.0.1, actor_id=eab08446529413fe9f69fe5f01000000, repr=<flwr.simulation.ray_transport.ray_actor.ClientAppActor object at 0x0000026EEED308E0>)
  File "python\ray\_raylet.pyx", line 1883, in ray._raylet.execute_task
  File "python\ray\_raylet.pyx", line 1984, in ray._raylet.execute_task
  File "python\ray\_raylet.pyx", line 1889, in ray._raylet.execute_task
  File "python\ray\_raylet.pyx", line 1830, in ray._raylet.execute_task.function_executor
  File "C:\Users\hughj\Documents\GitHub\asfl\env\lib\site-packages\ray\_private\function_manager.py", line 724, in actor_method_executor
    return method(__ray_actor, *args, **kwargs)
  File "C:\Users\hughj\Documents\GitHub\asfl\env\lib\site-packages\ray\util\tracing\tracing_helper.py", line 467, in _resume_span
    return method(self, *_args, **_kwargs)
  File "C:\Users\hughj\Documents\GitHub\asfl\env\lib\site-packages\flwr\simulation\ray_transport\ray_actor.py", line 63, in run
    raise ClientAppException(str(ex)) from ex
flwr.client.client_app.ClientAppException: 
Exception ClientAppException occurred. Message: Invalid partitioner: dirichlet
dv - | ERROR flwr 2024-10-23 14:52:52,495 | vce_api.py:124 | Traceback (most recent call last):
  File "C:\Users\hughj\Documents\GitHub\asfl\env\lib\site-packages\flwr\server\superlink\fleet\vce\vce_api.py", line 112, in worker
    out_mssg, updated_context = backend.process_message(message, context)
  File "C:\Users\hughj\Documents\GitHub\asfl\env\lib\site-packages\flwr\server\superlink\fleet\vce\backend\raybackend.py", line 178, in process_message
    raise ex
  File "C:\Users\hughj\Documents\GitHub\asfl\env\lib\site-packages\flwr\server\superlink\fleet\vce\backend\raybackend.py", line 166, in process_message
    ) = self.pool.fetch_result_and_return_actor_to_pool(future)
  File "C:\Users\hughj\Documents\GitHub\asfl\env\lib\site-packages\flwr\simulation\ray_transport\ray_actor.py", line 477, in fetch_result_and_return_actor_to_pool
    _, out_mssg, updated_context = ray.get(future)
  File "C:\Users\hughj\Documents\GitHub\asfl\env\lib\site-packages\ray\_private\auto_init_hook.py", line 21, in auto_init_wrapper
    return fn(*args, **kwargs)
  File "C:\Users\hughj\Documents\GitHub\asfl\env\lib\site-packages\ray\_private\client_mode_hook.py", line 103, in wrapper
    return func(*args, **kwargs)
  File "C:\Users\hughj\Documents\GitHub\asfl\env\lib\site-packages\ray\_private\worker.py", line 2667, in get
    values, debugger_breakpoint = worker.get_objects(object_refs, timeout=timeout)
  File "C:\Users\hughj\Documents\GitHub\asfl\env\lib\site-packages\ray\_private\worker.py", line 864, in get_objects
    raise value.as_instanceof_cause()
ray.exceptions.RayTaskError(ClientAppException): [36mray::ClientAppActor.run()[39m (pid=33540, ip=127.0.0.1, actor_id=eab08446529413fe9f69fe5f01000000, repr=<flwr.simulation.ray_transport.ray_actor.ClientAppActor object at 0x0000026EEED308E0>)
  File "C:\Users\hughj\Documents\GitHub\asfl\env\lib\site-packages\flwr\client\client_app.py", line 143, in __call__
    return self._call(message, context)
  File "C:\Users\hughj\Documents\GitHub\asfl\env\lib\site-packages\flwr\client\client_app.py", line 126, in ffn
    out_message = handle_legacy_message_from_msgtype(
  File "C:\Users\hughj\Documents\GitHub\asfl\env\lib\site-packages\flwr\client\message_handler\message_handler.py", line 95, in handle_legacy_message_from_msgtype
    client = client_fn(context)
  File "C:\Users\hughj\Documents\GitHub\asfl\asfl\client_app.py", line 80, in client_fn
    trainloader, valloader = load_data(context.run_config, partition_id, num_partitions)
  File "C:\Users\hughj\Documents\GitHub\asfl\asfl\task.py", line 73, in load_data
    raise ValueError("Invalid partitioner: " + node_config["partition"])
ValueError: Invalid partitioner: dirichlet

The above exception was the direct cause of the following exception:

[36mray::ClientAppActor.run()[39m (pid=33540, ip=127.0.0.1, actor_id=eab08446529413fe9f69fe5f01000000, repr=<flwr.simulation.ray_transport.ray_actor.ClientAppActor object at 0x0000026EEED308E0>)
  File "python\ray\_raylet.pyx", line 1883, in ray._raylet.execute_task
  File "python\ray\_raylet.pyx", line 1984, in ray._raylet.execute_task
  File "python\ray\_raylet.pyx", line 1889, in ray._raylet.execute_task
  File "python\ray\_raylet.pyx", line 1830, in ray._raylet.execute_task.function_executor
  File "C:\Users\hughj\Documents\GitHub\asfl\env\lib\site-packages\ray\_private\function_manager.py", line 724, in actor_method_executor
    return method(__ray_actor, *args, **kwargs)
  File "C:\Users\hughj\Documents\GitHub\asfl\env\lib\site-packages\ray\util\tracing\tracing_helper.py", line 467, in _resume_span
    return method(self, *_args, **_kwargs)
  File "C:\Users\hughj\Documents\GitHub\asfl\env\lib\site-packages\flwr\simulation\ray_transport\ray_actor.py", line 63, in run
    raise ClientAppException(str(ex)) from ex
flwr.client.client_app.ClientAppException: 
Exception ClientAppException occurred. Message: Invalid partitioner: dirichlet

dv - | INFO flwr 2024-10-23 14:52:52,790 | server.py:240 | aggregate_fit: received 0 results and 3 failures
dv - | INFO flwr 2024-10-23 14:52:52,791 | server.py:178 | configure_evaluate: strategy sampled 3 clients (out of 3)
dv - | INFO flwr 2024-10-23 14:52:57,831 | server.py:192 | aggregate_evaluate: received 3 results and 0 failures
dv - | INFO flwr 2024-10-23 14:52:57,832 | fed_custom.py:227 | aggregated accuracy: 0.0993900609939006
dv - | INFO flwr 2024-10-23 14:52:57,833 | server.py:496 | 
dv - | INFO flwr 2024-10-23 14:52:57,833 | server.py:497 | [SUMMARY]
dv - | INFO flwr 2024-10-23 14:52:57,834 | server.py:498 | Run finished 1 round(s) in 14.03s
dv - | INFO flwr 2024-10-23 14:52:57,835 | server.py:500 | 	History (loss, distributed):
dv - | INFO flwr 2024-10-23 14:52:57,835 | server.py:500 | 		round 1: 244.58620981165987
dv - | INFO flwr 2024-10-23 14:52:57,836 | server.py:500 | 	History (metrics, distributed, evaluate):
dv - | INFO flwr 2024-10-23 14:52:57,836 | server.py:500 | 	{'accuracy': [(1, 0.0993900609939006)], 'count': [(1, 3)]}
dv - | INFO flwr 2024-10-23 14:52:57,837 | server.py:501 | 
dv - | DEBUG flwr 2024-10-23 14:52:57,839 | run_serverapp.py:90 | ServerApp finished running.
dv - | DEBUG flwr 2024-10-23 14:52:57,839 | run_simulation.py:349 | ServerApp finished running.
dv - | DEBUG flwr 2024-10-23 14:52:57,839 | run_simulation.py:353 | Triggered stop event for Simulation Engine.
dv - | DEBUG flwr 2024-10-23 14:52:58,844 | ray_actor.py:450 | Terminated 4 actors
dv - | DEBUG flwr 2024-10-23 14:52:59,489 | raybackend.py:184 | Terminated RayBackend
dv - | DEBUG flwr 2024-10-23 14:52:59,490 | run_simulation.py:452 | Stopping Simulation Engine now.
dv - | INFO flwr 2024-10-23 14:53:54,962 | server_app.py:88 | file writing: True
dv - | INFO flwr 2024-10-23 14:53:54,962 | server_app.py:89 | running in fed_acc
dv - | INFO flwr 2024-10-23 14:53:54,963 | server_app.py:90 | min num clients 2
dv - | INFO flwr 2024-10-23 14:53:54,964 | server_app.py:91 | num server rounds 1
dv - | INFO flwr 2024-10-23 14:53:54,965 | server_app.py:92 | config num local epochs 1
dv - | INFO flwr 2024-10-23 14:53:54,965 | server_app.py:93 | advanced logging False
dv - | INFO flwr 2024-10-23 14:53:54,966 | server_app.py:94 | partition: dirichlet
dv - | INFO flwr 2024-10-23 14:53:54,966 | app.py:74 | Starting Flower ServerApp, config: num_rounds=1, no round_timeout
dv - | INFO flwr 2024-10-23 14:53:54,967 | app.py:79 | 
dv - | INFO flwr 2024-10-23 14:53:54,968 | server.py:92 | [INIT]
dv - | INFO flwr 2024-10-23 14:53:54,968 | server.py:277 | Using initial global parameters provided by strategy
dv - | INFO flwr 2024-10-23 14:53:54,969 | server.py:94 | Starting evaluation of initial global parameters
dv - | INFO flwr 2024-10-23 14:53:54,969 | server.py:106 | Evaluation returned no results (`None`)
dv - | INFO flwr 2024-10-23 14:53:54,969 | server.py:112 | 
dv - | INFO flwr 2024-10-23 14:53:54,970 | server.py:113 | [ROUND 1]
dv - | INFO flwr 2024-10-23 14:53:54,971 | server.py:226 | configure_fit: strategy sampled 3 clients (out of 3)
dv - | DEBUG flwr 2024-10-23 14:53:58,004 | raybackend.py:136 | Constructed ActorPool with: 4 actors
dv - | DEBUG flwr 2024-10-23 14:53:58,004 | state_factory.py:50 | Using InMemoryState
dv - | ERROR flwr 2024-10-23 14:54:03,727 | raybackend.py:171 | An exception was raised when processing a message by RayBackend
dv - | ERROR flwr 2024-10-23 14:54:03,728 | vce_api.py:123 | [36mray::ClientAppActor.run()[39m (pid=30452, ip=127.0.0.1, actor_id=9e8d9a0e15aa06a4f472029d01000000, repr=<flwr.simulation.ray_transport.ray_actor.ClientAppActor object at 0x00000262750F0970>)
  File "C:\Users\hughj\Documents\GitHub\asfl\env\lib\site-packages\flwr\client\client_app.py", line 143, in __call__
    return self._call(message, context)
  File "C:\Users\hughj\Documents\GitHub\asfl\env\lib\site-packages\flwr\client\client_app.py", line 126, in ffn
    out_message = handle_legacy_message_from_msgtype(
  File "C:\Users\hughj\Documents\GitHub\asfl\env\lib\site-packages\flwr\client\message_handler\message_handler.py", line 95, in handle_legacy_message_from_msgtype
    client = client_fn(context)
  File "C:\Users\hughj\Documents\GitHub\asfl\asfl\client_app.py", line 80, in client_fn
    trainloader, valloader = load_data(context.run_config, partition_id, num_partitions)
  File "C:\Users\hughj\Documents\GitHub\asfl\asfl\task.py", line 73, in load_data
    raise ValueError("Invalid partitioner: " + node_config["partition"] + " : " + node_config["partition"] == "dirichlet")
ValueError: False

The above exception was the direct cause of the following exception:

[36mray::ClientAppActor.run()[39m (pid=30452, ip=127.0.0.1, actor_id=9e8d9a0e15aa06a4f472029d01000000, repr=<flwr.simulation.ray_transport.ray_actor.ClientAppActor object at 0x00000262750F0970>)
  File "python\ray\_raylet.pyx", line 1883, in ray._raylet.execute_task
  File "python\ray\_raylet.pyx", line 1984, in ray._raylet.execute_task
  File "python\ray\_raylet.pyx", line 1889, in ray._raylet.execute_task
  File "python\ray\_raylet.pyx", line 1830, in ray._raylet.execute_task.function_executor
  File "C:\Users\hughj\Documents\GitHub\asfl\env\lib\site-packages\ray\_private\function_manager.py", line 724, in actor_method_executor
    return method(__ray_actor, *args, **kwargs)
  File "C:\Users\hughj\Documents\GitHub\asfl\env\lib\site-packages\ray\util\tracing\tracing_helper.py", line 467, in _resume_span
    return method(self, *_args, **_kwargs)
  File "C:\Users\hughj\Documents\GitHub\asfl\env\lib\site-packages\flwr\simulation\ray_transport\ray_actor.py", line 63, in run
    raise ClientAppException(str(ex)) from ex
flwr.client.client_app.ClientAppException: 
Exception ClientAppException occurred. Message: False
dv - | ERROR flwr 2024-10-23 14:54:03,728 | raybackend.py:171 | An exception was raised when processing a message by RayBackend
dv - | ERROR flwr 2024-10-23 14:54:03,729 | vce_api.py:123 | [36mray::ClientAppActor.run()[39m (pid=9964, ip=127.0.0.1, actor_id=69a1eb3310d9268ca7c5ccc301000000, repr=<flwr.simulation.ray_transport.ray_actor.ClientAppActor object at 0x000001B5EB890940>)
  File "C:\Users\hughj\Documents\GitHub\asfl\env\lib\site-packages\flwr\client\client_app.py", line 143, in __call__
    return self._call(message, context)
  File "C:\Users\hughj\Documents\GitHub\asfl\env\lib\site-packages\flwr\client\client_app.py", line 126, in ffn
    out_message = handle_legacy_message_from_msgtype(
  File "C:\Users\hughj\Documents\GitHub\asfl\env\lib\site-packages\flwr\client\message_handler\message_handler.py", line 95, in handle_legacy_message_from_msgtype
    client = client_fn(context)
  File "C:\Users\hughj\Documents\GitHub\asfl\asfl\client_app.py", line 80, in client_fn
    trainloader, valloader = load_data(context.run_config, partition_id, num_partitions)
  File "C:\Users\hughj\Documents\GitHub\asfl\asfl\task.py", line 73, in load_data
    raise ValueError("Invalid partitioner: " + node_config["partition"] + " : " + node_config["partition"] == "dirichlet")
ValueError: False

The above exception was the direct cause of the following exception:

[36mray::ClientAppActor.run()[39m (pid=9964, ip=127.0.0.1, actor_id=69a1eb3310d9268ca7c5ccc301000000, repr=<flwr.simulation.ray_transport.ray_actor.ClientAppActor object at 0x000001B5EB890940>)
  File "python\ray\_raylet.pyx", line 1883, in ray._raylet.execute_task
  File "python\ray\_raylet.pyx", line 1984, in ray._raylet.execute_task
  File "python\ray\_raylet.pyx", line 1889, in ray._raylet.execute_task
  File "python\ray\_raylet.pyx", line 1830, in ray._raylet.execute_task.function_executor
  File "C:\Users\hughj\Documents\GitHub\asfl\env\lib\site-packages\ray\_private\function_manager.py", line 724, in actor_method_executor
    return method(__ray_actor, *args, **kwargs)
  File "C:\Users\hughj\Documents\GitHub\asfl\env\lib\site-packages\ray\util\tracing\tracing_helper.py", line 467, in _resume_span
    return method(self, *_args, **_kwargs)
  File "C:\Users\hughj\Documents\GitHub\asfl\env\lib\site-packages\flwr\simulation\ray_transport\ray_actor.py", line 63, in run
    raise ClientAppException(str(ex)) from ex
flwr.client.client_app.ClientAppException: 
Exception ClientAppException occurred. Message: False
dv - | ERROR flwr 2024-10-23 14:54:03,731 | vce_api.py:124 | Traceback (most recent call last):
  File "C:\Users\hughj\Documents\GitHub\asfl\env\lib\site-packages\flwr\server\superlink\fleet\vce\vce_api.py", line 112, in worker
    out_mssg, updated_context = backend.process_message(message, context)
  File "C:\Users\hughj\Documents\GitHub\asfl\env\lib\site-packages\flwr\server\superlink\fleet\vce\backend\raybackend.py", line 178, in process_message
    raise ex
  File "C:\Users\hughj\Documents\GitHub\asfl\env\lib\site-packages\flwr\server\superlink\fleet\vce\backend\raybackend.py", line 166, in process_message
    ) = self.pool.fetch_result_and_return_actor_to_pool(future)
  File "C:\Users\hughj\Documents\GitHub\asfl\env\lib\site-packages\flwr\simulation\ray_transport\ray_actor.py", line 477, in fetch_result_and_return_actor_to_pool
    _, out_mssg, updated_context = ray.get(future)
  File "C:\Users\hughj\Documents\GitHub\asfl\env\lib\site-packages\ray\_private\auto_init_hook.py", line 21, in auto_init_wrapper
    return fn(*args, **kwargs)
  File "C:\Users\hughj\Documents\GitHub\asfl\env\lib\site-packages\ray\_private\client_mode_hook.py", line 103, in wrapper
    return func(*args, **kwargs)
  File "C:\Users\hughj\Documents\GitHub\asfl\env\lib\site-packages\ray\_private\worker.py", line 2667, in get
    values, debugger_breakpoint = worker.get_objects(object_refs, timeout=timeout)
  File "C:\Users\hughj\Documents\GitHub\asfl\env\lib\site-packages\ray\_private\worker.py", line 864, in get_objects
    raise value.as_instanceof_cause()
ray.exceptions.RayTaskError(ClientAppException): [36mray::ClientAppActor.run()[39m (pid=30452, ip=127.0.0.1, actor_id=9e8d9a0e15aa06a4f472029d01000000, repr=<flwr.simulation.ray_transport.ray_actor.ClientAppActor object at 0x00000262750F0970>)
  File "C:\Users\hughj\Documents\GitHub\asfl\env\lib\site-packages\flwr\client\client_app.py", line 143, in __call__
    return self._call(message, context)
  File "C:\Users\hughj\Documents\GitHub\asfl\env\lib\site-packages\flwr\client\client_app.py", line 126, in ffn
    out_message = handle_legacy_message_from_msgtype(
  File "C:\Users\hughj\Documents\GitHub\asfl\env\lib\site-packages\flwr\client\message_handler\message_handler.py", line 95, in handle_legacy_message_from_msgtype
    client = client_fn(context)
  File "C:\Users\hughj\Documents\GitHub\asfl\asfl\client_app.py", line 80, in client_fn
    trainloader, valloader = load_data(context.run_config, partition_id, num_partitions)
  File "C:\Users\hughj\Documents\GitHub\asfl\asfl\task.py", line 73, in load_data
    raise ValueError("Invalid partitioner: " + node_config["partition"] + " : " + node_config["partition"] == "dirichlet")
ValueError: False

The above exception was the direct cause of the following exception:

[36mray::ClientAppActor.run()[39m (pid=30452, ip=127.0.0.1, actor_id=9e8d9a0e15aa06a4f472029d01000000, repr=<flwr.simulation.ray_transport.ray_actor.ClientAppActor object at 0x00000262750F0970>)
  File "python\ray\_raylet.pyx", line 1883, in ray._raylet.execute_task
  File "python\ray\_raylet.pyx", line 1984, in ray._raylet.execute_task
  File "python\ray\_raylet.pyx", line 1889, in ray._raylet.execute_task
  File "python\ray\_raylet.pyx", line 1830, in ray._raylet.execute_task.function_executor
  File "C:\Users\hughj\Documents\GitHub\asfl\env\lib\site-packages\ray\_private\function_manager.py", line 724, in actor_method_executor
    return method(__ray_actor, *args, **kwargs)
  File "C:\Users\hughj\Documents\GitHub\asfl\env\lib\site-packages\ray\util\tracing\tracing_helper.py", line 467, in _resume_span
    return method(self, *_args, **_kwargs)
  File "C:\Users\hughj\Documents\GitHub\asfl\env\lib\site-packages\flwr\simulation\ray_transport\ray_actor.py", line 63, in run
    raise ClientAppException(str(ex)) from ex
flwr.client.client_app.ClientAppException: 
Exception ClientAppException occurred. Message: False

dv - | ERROR flwr 2024-10-23 14:54:03,731 | vce_api.py:124 | Traceback (most recent call last):
  File "C:\Users\hughj\Documents\GitHub\asfl\env\lib\site-packages\flwr\server\superlink\fleet\vce\vce_api.py", line 112, in worker
    out_mssg, updated_context = backend.process_message(message, context)
  File "C:\Users\hughj\Documents\GitHub\asfl\env\lib\site-packages\flwr\server\superlink\fleet\vce\backend\raybackend.py", line 178, in process_message
    raise ex
  File "C:\Users\hughj\Documents\GitHub\asfl\env\lib\site-packages\flwr\server\superlink\fleet\vce\backend\raybackend.py", line 166, in process_message
    ) = self.pool.fetch_result_and_return_actor_to_pool(future)
  File "C:\Users\hughj\Documents\GitHub\asfl\env\lib\site-packages\flwr\simulation\ray_transport\ray_actor.py", line 477, in fetch_result_and_return_actor_to_pool
    _, out_mssg, updated_context = ray.get(future)
  File "C:\Users\hughj\Documents\GitHub\asfl\env\lib\site-packages\ray\_private\auto_init_hook.py", line 21, in auto_init_wrapper
    return fn(*args, **kwargs)
  File "C:\Users\hughj\Documents\GitHub\asfl\env\lib\site-packages\ray\_private\client_mode_hook.py", line 103, in wrapper
    return func(*args, **kwargs)
  File "C:\Users\hughj\Documents\GitHub\asfl\env\lib\site-packages\ray\_private\worker.py", line 2667, in get
    values, debugger_breakpoint = worker.get_objects(object_refs, timeout=timeout)
  File "C:\Users\hughj\Documents\GitHub\asfl\env\lib\site-packages\ray\_private\worker.py", line 864, in get_objects
    raise value.as_instanceof_cause()
ray.exceptions.RayTaskError(ClientAppException): [36mray::ClientAppActor.run()[39m (pid=9964, ip=127.0.0.1, actor_id=69a1eb3310d9268ca7c5ccc301000000, repr=<flwr.simulation.ray_transport.ray_actor.ClientAppActor object at 0x000001B5EB890940>)
  File "C:\Users\hughj\Documents\GitHub\asfl\env\lib\site-packages\flwr\client\client_app.py", line 143, in __call__
    return self._call(message, context)
  File "C:\Users\hughj\Documents\GitHub\asfl\env\lib\site-packages\flwr\client\client_app.py", line 126, in ffn
    out_message = handle_legacy_message_from_msgtype(
  File "C:\Users\hughj\Documents\GitHub\asfl\env\lib\site-packages\flwr\client\message_handler\message_handler.py", line 95, in handle_legacy_message_from_msgtype
    client = client_fn(context)
  File "C:\Users\hughj\Documents\GitHub\asfl\asfl\client_app.py", line 80, in client_fn
    trainloader, valloader = load_data(context.run_config, partition_id, num_partitions)
  File "C:\Users\hughj\Documents\GitHub\asfl\asfl\task.py", line 73, in load_data
    raise ValueError("Invalid partitioner: " + node_config["partition"] + " : " + node_config["partition"] == "dirichlet")
ValueError: False

The above exception was the direct cause of the following exception:

[36mray::ClientAppActor.run()[39m (pid=9964, ip=127.0.0.1, actor_id=69a1eb3310d9268ca7c5ccc301000000, repr=<flwr.simulation.ray_transport.ray_actor.ClientAppActor object at 0x000001B5EB890940>)
  File "python\ray\_raylet.pyx", line 1883, in ray._raylet.execute_task
  File "python\ray\_raylet.pyx", line 1984, in ray._raylet.execute_task
  File "python\ray\_raylet.pyx", line 1889, in ray._raylet.execute_task
  File "python\ray\_raylet.pyx", line 1830, in ray._raylet.execute_task.function_executor
  File "C:\Users\hughj\Documents\GitHub\asfl\env\lib\site-packages\ray\_private\function_manager.py", line 724, in actor_method_executor
    return method(__ray_actor, *args, **kwargs)
  File "C:\Users\hughj\Documents\GitHub\asfl\env\lib\site-packages\ray\util\tracing\tracing_helper.py", line 467, in _resume_span
    return method(self, *_args, **_kwargs)
  File "C:\Users\hughj\Documents\GitHub\asfl\env\lib\site-packages\flwr\simulation\ray_transport\ray_actor.py", line 63, in run
    raise ClientAppException(str(ex)) from ex
flwr.client.client_app.ClientAppException: 
Exception ClientAppException occurred. Message: False

dv - | ERROR flwr 2024-10-23 14:54:03,754 | raybackend.py:171 | An exception was raised when processing a message by RayBackend
dv - | ERROR flwr 2024-10-23 14:54:03,754 | vce_api.py:123 | [36mray::ClientAppActor.run()[39m (pid=34748, ip=127.0.0.1, actor_id=107f68370bf01fee1889ebd701000000, repr=<flwr.simulation.ray_transport.ray_actor.ClientAppActor object at 0x000002A1A0980940>)
  File "C:\Users\hughj\Documents\GitHub\asfl\env\lib\site-packages\flwr\client\client_app.py", line 143, in __call__
    return self._call(message, context)
  File "C:\Users\hughj\Documents\GitHub\asfl\env\lib\site-packages\flwr\client\client_app.py", line 126, in ffn
    out_message = handle_legacy_message_from_msgtype(
  File "C:\Users\hughj\Documents\GitHub\asfl\env\lib\site-packages\flwr\client\message_handler\message_handler.py", line 95, in handle_legacy_message_from_msgtype
    client = client_fn(context)
  File "C:\Users\hughj\Documents\GitHub\asfl\asfl\client_app.py", line 80, in client_fn
    trainloader, valloader = load_data(context.run_config, partition_id, num_partitions)
  File "C:\Users\hughj\Documents\GitHub\asfl\asfl\task.py", line 73, in load_data
    raise ValueError("Invalid partitioner: " + node_config["partition"] + " : " + node_config["partition"] == "dirichlet")
ValueError: False

The above exception was the direct cause of the following exception:

[36mray::ClientAppActor.run()[39m (pid=34748, ip=127.0.0.1, actor_id=107f68370bf01fee1889ebd701000000, repr=<flwr.simulation.ray_transport.ray_actor.ClientAppActor object at 0x000002A1A0980940>)
  File "python\ray\_raylet.pyx", line 1883, in ray._raylet.execute_task
  File "python\ray\_raylet.pyx", line 1984, in ray._raylet.execute_task
  File "python\ray\_raylet.pyx", line 1889, in ray._raylet.execute_task
  File "python\ray\_raylet.pyx", line 1830, in ray._raylet.execute_task.function_executor
  File "C:\Users\hughj\Documents\GitHub\asfl\env\lib\site-packages\ray\_private\function_manager.py", line 724, in actor_method_executor
    return method(__ray_actor, *args, **kwargs)
  File "C:\Users\hughj\Documents\GitHub\asfl\env\lib\site-packages\ray\util\tracing\tracing_helper.py", line 467, in _resume_span
    return method(self, *_args, **_kwargs)
  File "C:\Users\hughj\Documents\GitHub\asfl\env\lib\site-packages\flwr\simulation\ray_transport\ray_actor.py", line 63, in run
    raise ClientAppException(str(ex)) from ex
flwr.client.client_app.ClientAppException: 
Exception ClientAppException occurred. Message: False
dv - | ERROR flwr 2024-10-23 14:54:03,756 | vce_api.py:124 | Traceback (most recent call last):
  File "C:\Users\hughj\Documents\GitHub\asfl\env\lib\site-packages\flwr\server\superlink\fleet\vce\vce_api.py", line 112, in worker
    out_mssg, updated_context = backend.process_message(message, context)
  File "C:\Users\hughj\Documents\GitHub\asfl\env\lib\site-packages\flwr\server\superlink\fleet\vce\backend\raybackend.py", line 178, in process_message
    raise ex
  File "C:\Users\hughj\Documents\GitHub\asfl\env\lib\site-packages\flwr\server\superlink\fleet\vce\backend\raybackend.py", line 166, in process_message
    ) = self.pool.fetch_result_and_return_actor_to_pool(future)
  File "C:\Users\hughj\Documents\GitHub\asfl\env\lib\site-packages\flwr\simulation\ray_transport\ray_actor.py", line 477, in fetch_result_and_return_actor_to_pool
    _, out_mssg, updated_context = ray.get(future)
  File "C:\Users\hughj\Documents\GitHub\asfl\env\lib\site-packages\ray\_private\auto_init_hook.py", line 21, in auto_init_wrapper
    return fn(*args, **kwargs)
  File "C:\Users\hughj\Documents\GitHub\asfl\env\lib\site-packages\ray\_private\client_mode_hook.py", line 103, in wrapper
    return func(*args, **kwargs)
  File "C:\Users\hughj\Documents\GitHub\asfl\env\lib\site-packages\ray\_private\worker.py", line 2667, in get
    values, debugger_breakpoint = worker.get_objects(object_refs, timeout=timeout)
  File "C:\Users\hughj\Documents\GitHub\asfl\env\lib\site-packages\ray\_private\worker.py", line 864, in get_objects
    raise value.as_instanceof_cause()
ray.exceptions.RayTaskError(ClientAppException): [36mray::ClientAppActor.run()[39m (pid=34748, ip=127.0.0.1, actor_id=107f68370bf01fee1889ebd701000000, repr=<flwr.simulation.ray_transport.ray_actor.ClientAppActor object at 0x000002A1A0980940>)
  File "C:\Users\hughj\Documents\GitHub\asfl\env\lib\site-packages\flwr\client\client_app.py", line 143, in __call__
    return self._call(message, context)
  File "C:\Users\hughj\Documents\GitHub\asfl\env\lib\site-packages\flwr\client\client_app.py", line 126, in ffn
    out_message = handle_legacy_message_from_msgtype(
  File "C:\Users\hughj\Documents\GitHub\asfl\env\lib\site-packages\flwr\client\message_handler\message_handler.py", line 95, in handle_legacy_message_from_msgtype
    client = client_fn(context)
  File "C:\Users\hughj\Documents\GitHub\asfl\asfl\client_app.py", line 80, in client_fn
    trainloader, valloader = load_data(context.run_config, partition_id, num_partitions)
  File "C:\Users\hughj\Documents\GitHub\asfl\asfl\task.py", line 73, in load_data
    raise ValueError("Invalid partitioner: " + node_config["partition"] + " : " + node_config["partition"] == "dirichlet")
ValueError: False

The above exception was the direct cause of the following exception:

[36mray::ClientAppActor.run()[39m (pid=34748, ip=127.0.0.1, actor_id=107f68370bf01fee1889ebd701000000, repr=<flwr.simulation.ray_transport.ray_actor.ClientAppActor object at 0x000002A1A0980940>)
  File "python\ray\_raylet.pyx", line 1883, in ray._raylet.execute_task
  File "python\ray\_raylet.pyx", line 1984, in ray._raylet.execute_task
  File "python\ray\_raylet.pyx", line 1889, in ray._raylet.execute_task
  File "python\ray\_raylet.pyx", line 1830, in ray._raylet.execute_task.function_executor
  File "C:\Users\hughj\Documents\GitHub\asfl\env\lib\site-packages\ray\_private\function_manager.py", line 724, in actor_method_executor
    return method(__ray_actor, *args, **kwargs)
  File "C:\Users\hughj\Documents\GitHub\asfl\env\lib\site-packages\ray\util\tracing\tracing_helper.py", line 467, in _resume_span
    return method(self, *_args, **_kwargs)
  File "C:\Users\hughj\Documents\GitHub\asfl\env\lib\site-packages\flwr\simulation\ray_transport\ray_actor.py", line 63, in run
    raise ClientAppException(str(ex)) from ex
flwr.client.client_app.ClientAppException: 
Exception ClientAppException occurred. Message: False

dv - | INFO flwr 2024-10-23 14:54:04,031 | server.py:240 | aggregate_fit: received 0 results and 3 failures
dv - | INFO flwr 2024-10-23 14:54:04,032 | server.py:178 | configure_evaluate: strategy sampled 3 clients (out of 3)
dv - | INFO flwr 2024-10-23 14:54:09,087 | server.py:192 | aggregate_evaluate: received 3 results and 0 failures
dv - | INFO flwr 2024-10-23 14:54:09,089 | fed_custom.py:227 | aggregated accuracy: 0.100989901009899
dv - | INFO flwr 2024-10-23 14:54:09,089 | server.py:496 | 
dv - | INFO flwr 2024-10-23 14:54:09,090 | server.py:497 | [SUMMARY]
dv - | INFO flwr 2024-10-23 14:54:09,091 | server.py:498 | Run finished 1 round(s) in 14.12s
dv - | INFO flwr 2024-10-23 14:54:09,092 | server.py:500 | 	History (loss, distributed):
dv - | INFO flwr 2024-10-23 14:54:09,092 | server.py:500 | 		round 1: 244.59677016092604
dv - | INFO flwr 2024-10-23 14:54:09,093 | server.py:500 | 	History (metrics, distributed, evaluate):
dv - | INFO flwr 2024-10-23 14:54:09,093 | server.py:500 | 	{'accuracy': [(1, 0.100989901009899)], 'count': [(1, 3)]}
dv - | INFO flwr 2024-10-23 14:54:09,094 | server.py:501 | 
dv - | DEBUG flwr 2024-10-23 14:54:09,097 | run_serverapp.py:90 | ServerApp finished running.
dv - | DEBUG flwr 2024-10-23 14:54:09,097 | run_simulation.py:349 | ServerApp finished running.
dv - | DEBUG flwr 2024-10-23 14:54:09,097 | run_simulation.py:353 | Triggered stop event for Simulation Engine.
dv - | DEBUG flwr 2024-10-23 14:54:10,096 | ray_actor.py:450 | Terminated 4 actors
dv - | DEBUG flwr 2024-10-23 14:54:10,689 | raybackend.py:184 | Terminated RayBackend
dv - | DEBUG flwr 2024-10-23 14:54:10,690 | run_simulation.py:452 | Stopping Simulation Engine now.
dv - | INFO flwr 2024-10-23 14:54:43,643 | server_app.py:88 | file writing: True
dv - | INFO flwr 2024-10-23 14:54:43,644 | server_app.py:89 | running in fed_acc
dv - | INFO flwr 2024-10-23 14:54:43,644 | server_app.py:90 | min num clients 2
dv - | INFO flwr 2024-10-23 14:54:43,645 | server_app.py:91 | num server rounds 1
dv - | INFO flwr 2024-10-23 14:54:43,645 | server_app.py:92 | config num local epochs 1
dv - | INFO flwr 2024-10-23 14:54:43,646 | server_app.py:93 | advanced logging False
dv - | INFO flwr 2024-10-23 14:54:43,646 | server_app.py:94 | partition: dirichlet
dv - | INFO flwr 2024-10-23 14:54:43,647 | app.py:74 | Starting Flower ServerApp, config: num_rounds=1, no round_timeout
dv - | INFO flwr 2024-10-23 14:54:43,648 | app.py:79 | 
dv - | INFO flwr 2024-10-23 14:54:43,649 | server.py:92 | [INIT]
dv - | INFO flwr 2024-10-23 14:54:43,649 | server.py:277 | Using initial global parameters provided by strategy
dv - | INFO flwr 2024-10-23 14:54:43,650 | server.py:94 | Starting evaluation of initial global parameters
dv - | INFO flwr 2024-10-23 14:54:43,650 | server.py:106 | Evaluation returned no results (`None`)
dv - | INFO flwr 2024-10-23 14:54:43,650 | server.py:112 | 
dv - | INFO flwr 2024-10-23 14:54:43,650 | server.py:113 | [ROUND 1]
dv - | INFO flwr 2024-10-23 14:54:43,651 | server.py:226 | configure_fit: strategy sampled 3 clients (out of 3)
dv - | DEBUG flwr 2024-10-23 14:54:46,678 | raybackend.py:136 | Constructed ActorPool with: 4 actors
dv - | DEBUG flwr 2024-10-23 14:54:46,678 | state_factory.py:50 | Using InMemoryState
dv - | ERROR flwr 2024-10-23 14:54:52,502 | raybackend.py:171 | An exception was raised when processing a message by RayBackend
dv - | ERROR flwr 2024-10-23 14:54:52,503 | vce_api.py:123 | [36mray::ClientAppActor.run()[39m (pid=2332, ip=127.0.0.1, actor_id=a94b9e5348cdd0e8d31e111801000000, repr=<flwr.simulation.ray_transport.ray_actor.ClientAppActor object at 0x000001A061EF0970>)
  File "C:\Users\hughj\Documents\GitHub\asfl\env\lib\site-packages\flwr\client\client_app.py", line 143, in __call__
    return self._call(message, context)
  File "C:\Users\hughj\Documents\GitHub\asfl\env\lib\site-packages\flwr\client\client_app.py", line 126, in ffn
    out_message = handle_legacy_message_from_msgtype(
  File "C:\Users\hughj\Documents\GitHub\asfl\env\lib\site-packages\flwr\client\message_handler\message_handler.py", line 95, in handle_legacy_message_from_msgtype
    client = client_fn(context)
  File "C:\Users\hughj\Documents\GitHub\asfl\asfl\client_app.py", line 80, in client_fn
    trainloader, valloader = load_data(context.run_config, partition_id, num_partitions)
  File "C:\Users\hughj\Documents\GitHub\asfl\asfl\task.py", line 73, in load_data
    raise ValueError("Invalid partitioner: " + node_config["partition"] + " : " + str(node_config["partition"] == "dirichlet"))
ValueError: Invalid partitioner: dirichlet : True

The above exception was the direct cause of the following exception:

[36mray::ClientAppActor.run()[39m (pid=2332, ip=127.0.0.1, actor_id=a94b9e5348cdd0e8d31e111801000000, repr=<flwr.simulation.ray_transport.ray_actor.ClientAppActor object at 0x000001A061EF0970>)
  File "python\ray\_raylet.pyx", line 1883, in ray._raylet.execute_task
  File "python\ray\_raylet.pyx", line 1984, in ray._raylet.execute_task
  File "python\ray\_raylet.pyx", line 1889, in ray._raylet.execute_task
  File "python\ray\_raylet.pyx", line 1830, in ray._raylet.execute_task.function_executor
  File "C:\Users\hughj\Documents\GitHub\asfl\env\lib\site-packages\ray\_private\function_manager.py", line 724, in actor_method_executor
    return method(__ray_actor, *args, **kwargs)
  File "C:\Users\hughj\Documents\GitHub\asfl\env\lib\site-packages\ray\util\tracing\tracing_helper.py", line 467, in _resume_span
    return method(self, *_args, **_kwargs)
  File "C:\Users\hughj\Documents\GitHub\asfl\env\lib\site-packages\flwr\simulation\ray_transport\ray_actor.py", line 63, in run
    raise ClientAppException(str(ex)) from ex
flwr.client.client_app.ClientAppException: 
Exception ClientAppException occurred. Message: Invalid partitioner: dirichlet : True
dv - | ERROR flwr 2024-10-23 14:54:52,507 | vce_api.py:124 | Traceback (most recent call last):
  File "C:\Users\hughj\Documents\GitHub\asfl\env\lib\site-packages\flwr\server\superlink\fleet\vce\vce_api.py", line 112, in worker
    out_mssg, updated_context = backend.process_message(message, context)
  File "C:\Users\hughj\Documents\GitHub\asfl\env\lib\site-packages\flwr\server\superlink\fleet\vce\backend\raybackend.py", line 178, in process_message
    raise ex
  File "C:\Users\hughj\Documents\GitHub\asfl\env\lib\site-packages\flwr\server\superlink\fleet\vce\backend\raybackend.py", line 166, in process_message
    ) = self.pool.fetch_result_and_return_actor_to_pool(future)
  File "C:\Users\hughj\Documents\GitHub\asfl\env\lib\site-packages\flwr\simulation\ray_transport\ray_actor.py", line 477, in fetch_result_and_return_actor_to_pool
    _, out_mssg, updated_context = ray.get(future)
  File "C:\Users\hughj\Documents\GitHub\asfl\env\lib\site-packages\ray\_private\auto_init_hook.py", line 21, in auto_init_wrapper
    return fn(*args, **kwargs)
  File "C:\Users\hughj\Documents\GitHub\asfl\env\lib\site-packages\ray\_private\client_mode_hook.py", line 103, in wrapper
    return func(*args, **kwargs)
  File "C:\Users\hughj\Documents\GitHub\asfl\env\lib\site-packages\ray\_private\worker.py", line 2667, in get
    values, debugger_breakpoint = worker.get_objects(object_refs, timeout=timeout)
  File "C:\Users\hughj\Documents\GitHub\asfl\env\lib\site-packages\ray\_private\worker.py", line 864, in get_objects
    raise value.as_instanceof_cause()
ray.exceptions.RayTaskError(ClientAppException): [36mray::ClientAppActor.run()[39m (pid=2332, ip=127.0.0.1, actor_id=a94b9e5348cdd0e8d31e111801000000, repr=<flwr.simulation.ray_transport.ray_actor.ClientAppActor object at 0x000001A061EF0970>)
  File "C:\Users\hughj\Documents\GitHub\asfl\env\lib\site-packages\flwr\client\client_app.py", line 143, in __call__
    return self._call(message, context)
  File "C:\Users\hughj\Documents\GitHub\asfl\env\lib\site-packages\flwr\client\client_app.py", line 126, in ffn
    out_message = handle_legacy_message_from_msgtype(
  File "C:\Users\hughj\Documents\GitHub\asfl\env\lib\site-packages\flwr\client\message_handler\message_handler.py", line 95, in handle_legacy_message_from_msgtype
    client = client_fn(context)
  File "C:\Users\hughj\Documents\GitHub\asfl\asfl\client_app.py", line 80, in client_fn
    trainloader, valloader = load_data(context.run_config, partition_id, num_partitions)
  File "C:\Users\hughj\Documents\GitHub\asfl\asfl\task.py", line 73, in load_data
    raise ValueError("Invalid partitioner: " + node_config["partition"] + " : " + str(node_config["partition"] == "dirichlet"))
ValueError: Invalid partitioner: dirichlet : True

The above exception was the direct cause of the following exception:

[36mray::ClientAppActor.run()[39m (pid=2332, ip=127.0.0.1, actor_id=a94b9e5348cdd0e8d31e111801000000, repr=<flwr.simulation.ray_transport.ray_actor.ClientAppActor object at 0x000001A061EF0970>)
  File "python\ray\_raylet.pyx", line 1883, in ray._raylet.execute_task
  File "python\ray\_raylet.pyx", line 1984, in ray._raylet.execute_task
  File "python\ray\_raylet.pyx", line 1889, in ray._raylet.execute_task
  File "python\ray\_raylet.pyx", line 1830, in ray._raylet.execute_task.function_executor
  File "C:\Users\hughj\Documents\GitHub\asfl\env\lib\site-packages\ray\_private\function_manager.py", line 724, in actor_method_executor
    return method(__ray_actor, *args, **kwargs)
  File "C:\Users\hughj\Documents\GitHub\asfl\env\lib\site-packages\ray\util\tracing\tracing_helper.py", line 467, in _resume_span
    return method(self, *_args, **_kwargs)
  File "C:\Users\hughj\Documents\GitHub\asfl\env\lib\site-packages\flwr\simulation\ray_transport\ray_actor.py", line 63, in run
    raise ClientAppException(str(ex)) from ex
flwr.client.client_app.ClientAppException: 
Exception ClientAppException occurred. Message: Invalid partitioner: dirichlet : True

dv - | ERROR flwr 2024-10-23 14:54:52,630 | raybackend.py:171 | An exception was raised when processing a message by RayBackend
dv - | ERROR flwr 2024-10-23 14:54:52,631 | raybackend.py:171 | An exception was raised when processing a message by RayBackend
dv - | ERROR flwr 2024-10-23 14:54:52,631 | vce_api.py:123 | [36mray::ClientAppActor.run()[39m (pid=34940, ip=127.0.0.1, actor_id=f554e63283f0f292350bdbfe01000000, repr=<flwr.simulation.ray_transport.ray_actor.ClientAppActor object at 0x000002AA971B0880>)
  File "C:\Users\hughj\Documents\GitHub\asfl\env\lib\site-packages\flwr\client\client_app.py", line 143, in __call__
    return self._call(message, context)
  File "C:\Users\hughj\Documents\GitHub\asfl\env\lib\site-packages\flwr\client\client_app.py", line 126, in ffn
    out_message = handle_legacy_message_from_msgtype(
  File "C:\Users\hughj\Documents\GitHub\asfl\env\lib\site-packages\flwr\client\message_handler\message_handler.py", line 95, in handle_legacy_message_from_msgtype
    client = client_fn(context)
  File "C:\Users\hughj\Documents\GitHub\asfl\asfl\client_app.py", line 80, in client_fn
    trainloader, valloader = load_data(context.run_config, partition_id, num_partitions)
  File "C:\Users\hughj\Documents\GitHub\asfl\asfl\task.py", line 73, in load_data
    raise ValueError("Invalid partitioner: " + node_config["partition"] + " : " + str(node_config["partition"] == "dirichlet"))
ValueError: Invalid partitioner: dirichlet : True

The above exception was the direct cause of the following exception:

[36mray::ClientAppActor.run()[39m (pid=34940, ip=127.0.0.1, actor_id=f554e63283f0f292350bdbfe01000000, repr=<flwr.simulation.ray_transport.ray_actor.ClientAppActor object at 0x000002AA971B0880>)
  File "python\ray\_raylet.pyx", line 1883, in ray._raylet.execute_task
  File "python\ray\_raylet.pyx", line 1984, in ray._raylet.execute_task
  File "python\ray\_raylet.pyx", line 1889, in ray._raylet.execute_task
  File "python\ray\_raylet.pyx", line 1830, in ray._raylet.execute_task.function_executor
  File "C:\Users\hughj\Documents\GitHub\asfl\env\lib\site-packages\ray\_private\function_manager.py", line 724, in actor_method_executor
    return method(__ray_actor, *args, **kwargs)
  File "C:\Users\hughj\Documents\GitHub\asfl\env\lib\site-packages\ray\util\tracing\tracing_helper.py", line 467, in _resume_span
    return method(self, *_args, **_kwargs)
  File "C:\Users\hughj\Documents\GitHub\asfl\env\lib\site-packages\flwr\simulation\ray_transport\ray_actor.py", line 63, in run
    raise ClientAppException(str(ex)) from ex
flwr.client.client_app.ClientAppException: 
Exception ClientAppException occurred. Message: Invalid partitioner: dirichlet : True
dv - | ERROR flwr 2024-10-23 14:54:52,631 | vce_api.py:123 | [36mray::ClientAppActor.run()[39m (pid=17132, ip=127.0.0.1, actor_id=b90b8cba08d22987850ca62301000000, repr=<flwr.simulation.ray_transport.ray_actor.ClientAppActor object at 0x000002142EDA0850>)
  File "C:\Users\hughj\Documents\GitHub\asfl\env\lib\site-packages\flwr\client\client_app.py", line 143, in __call__
    return self._call(message, context)
  File "C:\Users\hughj\Documents\GitHub\asfl\env\lib\site-packages\flwr\client\client_app.py", line 126, in ffn
    out_message = handle_legacy_message_from_msgtype(
  File "C:\Users\hughj\Documents\GitHub\asfl\env\lib\site-packages\flwr\client\message_handler\message_handler.py", line 95, in handle_legacy_message_from_msgtype
    client = client_fn(context)
  File "C:\Users\hughj\Documents\GitHub\asfl\asfl\client_app.py", line 80, in client_fn
    trainloader, valloader = load_data(context.run_config, partition_id, num_partitions)
  File "C:\Users\hughj\Documents\GitHub\asfl\asfl\task.py", line 73, in load_data
    raise ValueError("Invalid partitioner: " + node_config["partition"] + " : " + str(node_config["partition"] == "dirichlet"))
ValueError: Invalid partitioner: dirichlet : True

The above exception was the direct cause of the following exception:

[36mray::ClientAppActor.run()[39m (pid=17132, ip=127.0.0.1, actor_id=b90b8cba08d22987850ca62301000000, repr=<flwr.simulation.ray_transport.ray_actor.ClientAppActor object at 0x000002142EDA0850>)
  File "python\ray\_raylet.pyx", line 1883, in ray._raylet.execute_task
  File "python\ray\_raylet.pyx", line 1984, in ray._raylet.execute_task
  File "python\ray\_raylet.pyx", line 1889, in ray._raylet.execute_task
  File "python\ray\_raylet.pyx", line 1830, in ray._raylet.execute_task.function_executor
  File "C:\Users\hughj\Documents\GitHub\asfl\env\lib\site-packages\ray\_private\function_manager.py", line 724, in actor_method_executor
    return method(__ray_actor, *args, **kwargs)
  File "C:\Users\hughj\Documents\GitHub\asfl\env\lib\site-packages\ray\util\tracing\tracing_helper.py", line 467, in _resume_span
    return method(self, *_args, **_kwargs)
  File "C:\Users\hughj\Documents\GitHub\asfl\env\lib\site-packages\flwr\simulation\ray_transport\ray_actor.py", line 63, in run
    raise ClientAppException(str(ex)) from ex
flwr.client.client_app.ClientAppException: 
Exception ClientAppException occurred. Message: Invalid partitioner: dirichlet : True
dv - | ERROR flwr 2024-10-23 14:54:52,632 | vce_api.py:124 | Traceback (most recent call last):
  File "C:\Users\hughj\Documents\GitHub\asfl\env\lib\site-packages\flwr\server\superlink\fleet\vce\vce_api.py", line 112, in worker
    out_mssg, updated_context = backend.process_message(message, context)
  File "C:\Users\hughj\Documents\GitHub\asfl\env\lib\site-packages\flwr\server\superlink\fleet\vce\backend\raybackend.py", line 178, in process_message
    raise ex
  File "C:\Users\hughj\Documents\GitHub\asfl\env\lib\site-packages\flwr\server\superlink\fleet\vce\backend\raybackend.py", line 166, in process_message
    ) = self.pool.fetch_result_and_return_actor_to_pool(future)
  File "C:\Users\hughj\Documents\GitHub\asfl\env\lib\site-packages\flwr\simulation\ray_transport\ray_actor.py", line 477, in fetch_result_and_return_actor_to_pool
    _, out_mssg, updated_context = ray.get(future)
  File "C:\Users\hughj\Documents\GitHub\asfl\env\lib\site-packages\ray\_private\auto_init_hook.py", line 21, in auto_init_wrapper
    return fn(*args, **kwargs)
  File "C:\Users\hughj\Documents\GitHub\asfl\env\lib\site-packages\ray\_private\client_mode_hook.py", line 103, in wrapper
    return func(*args, **kwargs)
  File "C:\Users\hughj\Documents\GitHub\asfl\env\lib\site-packages\ray\_private\worker.py", line 2667, in get
    values, debugger_breakpoint = worker.get_objects(object_refs, timeout=timeout)
  File "C:\Users\hughj\Documents\GitHub\asfl\env\lib\site-packages\ray\_private\worker.py", line 864, in get_objects
    raise value.as_instanceof_cause()
ray.exceptions.RayTaskError(ClientAppException): [36mray::ClientAppActor.run()[39m (pid=34940, ip=127.0.0.1, actor_id=f554e63283f0f292350bdbfe01000000, repr=<flwr.simulation.ray_transport.ray_actor.ClientAppActor object at 0x000002AA971B0880>)
  File "C:\Users\hughj\Documents\GitHub\asfl\env\lib\site-packages\flwr\client\client_app.py", line 143, in __call__
    return self._call(message, context)
  File "C:\Users\hughj\Documents\GitHub\asfl\env\lib\site-packages\flwr\client\client_app.py", line 126, in ffn
    out_message = handle_legacy_message_from_msgtype(
  File "C:\Users\hughj\Documents\GitHub\asfl\env\lib\site-packages\flwr\client\message_handler\message_handler.py", line 95, in handle_legacy_message_from_msgtype
    client = client_fn(context)
  File "C:\Users\hughj\Documents\GitHub\asfl\asfl\client_app.py", line 80, in client_fn
    trainloader, valloader = load_data(context.run_config, partition_id, num_partitions)
  File "C:\Users\hughj\Documents\GitHub\asfl\asfl\task.py", line 73, in load_data
    raise ValueError("Invalid partitioner: " + node_config["partition"] + " : " + str(node_config["partition"] == "dirichlet"))
ValueError: Invalid partitioner: dirichlet : True

The above exception was the direct cause of the following exception:

[36mray::ClientAppActor.run()[39m (pid=34940, ip=127.0.0.1, actor_id=f554e63283f0f292350bdbfe01000000, repr=<flwr.simulation.ray_transport.ray_actor.ClientAppActor object at 0x000002AA971B0880>)
  File "python\ray\_raylet.pyx", line 1883, in ray._raylet.execute_task
  File "python\ray\_raylet.pyx", line 1984, in ray._raylet.execute_task
  File "python\ray\_raylet.pyx", line 1889, in ray._raylet.execute_task
  File "python\ray\_raylet.pyx", line 1830, in ray._raylet.execute_task.function_executor
  File "C:\Users\hughj\Documents\GitHub\asfl\env\lib\site-packages\ray\_private\function_manager.py", line 724, in actor_method_executor
    return method(__ray_actor, *args, **kwargs)
  File "C:\Users\hughj\Documents\GitHub\asfl\env\lib\site-packages\ray\util\tracing\tracing_helper.py", line 467, in _resume_span
    return method(self, *_args, **_kwargs)
  File "C:\Users\hughj\Documents\GitHub\asfl\env\lib\site-packages\flwr\simulation\ray_transport\ray_actor.py", line 63, in run
    raise ClientAppException(str(ex)) from ex
flwr.client.client_app.ClientAppException: 
Exception ClientAppException occurred. Message: Invalid partitioner: dirichlet : True

dv - | ERROR flwr 2024-10-23 14:54:52,634 | vce_api.py:124 | Traceback (most recent call last):
  File "C:\Users\hughj\Documents\GitHub\asfl\env\lib\site-packages\flwr\server\superlink\fleet\vce\vce_api.py", line 112, in worker
    out_mssg, updated_context = backend.process_message(message, context)
  File "C:\Users\hughj\Documents\GitHub\asfl\env\lib\site-packages\flwr\server\superlink\fleet\vce\backend\raybackend.py", line 178, in process_message
    raise ex
  File "C:\Users\hughj\Documents\GitHub\asfl\env\lib\site-packages\flwr\server\superlink\fleet\vce\backend\raybackend.py", line 166, in process_message
    ) = self.pool.fetch_result_and_return_actor_to_pool(future)
  File "C:\Users\hughj\Documents\GitHub\asfl\env\lib\site-packages\flwr\simulation\ray_transport\ray_actor.py", line 477, in fetch_result_and_return_actor_to_pool
    _, out_mssg, updated_context = ray.get(future)
  File "C:\Users\hughj\Documents\GitHub\asfl\env\lib\site-packages\ray\_private\auto_init_hook.py", line 21, in auto_init_wrapper
    return fn(*args, **kwargs)
  File "C:\Users\hughj\Documents\GitHub\asfl\env\lib\site-packages\ray\_private\client_mode_hook.py", line 103, in wrapper
    return func(*args, **kwargs)
  File "C:\Users\hughj\Documents\GitHub\asfl\env\lib\site-packages\ray\_private\worker.py", line 2667, in get
    values, debugger_breakpoint = worker.get_objects(object_refs, timeout=timeout)
  File "C:\Users\hughj\Documents\GitHub\asfl\env\lib\site-packages\ray\_private\worker.py", line 864, in get_objects
    raise value.as_instanceof_cause()
ray.exceptions.RayTaskError(ClientAppException): [36mray::ClientAppActor.run()[39m (pid=17132, ip=127.0.0.1, actor_id=b90b8cba08d22987850ca62301000000, repr=<flwr.simulation.ray_transport.ray_actor.ClientAppActor object at 0x000002142EDA0850>)
  File "C:\Users\hughj\Documents\GitHub\asfl\env\lib\site-packages\flwr\client\client_app.py", line 143, in __call__
    return self._call(message, context)
  File "C:\Users\hughj\Documents\GitHub\asfl\env\lib\site-packages\flwr\client\client_app.py", line 126, in ffn
    out_message = handle_legacy_message_from_msgtype(
  File "C:\Users\hughj\Documents\GitHub\asfl\env\lib\site-packages\flwr\client\message_handler\message_handler.py", line 95, in handle_legacy_message_from_msgtype
    client = client_fn(context)
  File "C:\Users\hughj\Documents\GitHub\asfl\asfl\client_app.py", line 80, in client_fn
    trainloader, valloader = load_data(context.run_config, partition_id, num_partitions)
  File "C:\Users\hughj\Documents\GitHub\asfl\asfl\task.py", line 73, in load_data
    raise ValueError("Invalid partitioner: " + node_config["partition"] + " : " + str(node_config["partition"] == "dirichlet"))
ValueError: Invalid partitioner: dirichlet : True

The above exception was the direct cause of the following exception:

[36mray::ClientAppActor.run()[39m (pid=17132, ip=127.0.0.1, actor_id=b90b8cba08d22987850ca62301000000, repr=<flwr.simulation.ray_transport.ray_actor.ClientAppActor object at 0x000002142EDA0850>)
  File "python\ray\_raylet.pyx", line 1883, in ray._raylet.execute_task
  File "python\ray\_raylet.pyx", line 1984, in ray._raylet.execute_task
  File "python\ray\_raylet.pyx", line 1889, in ray._raylet.execute_task
  File "python\ray\_raylet.pyx", line 1830, in ray._raylet.execute_task.function_executor
  File "C:\Users\hughj\Documents\GitHub\asfl\env\lib\site-packages\ray\_private\function_manager.py", line 724, in actor_method_executor
    return method(__ray_actor, *args, **kwargs)
  File "C:\Users\hughj\Documents\GitHub\asfl\env\lib\site-packages\ray\util\tracing\tracing_helper.py", line 467, in _resume_span
    return method(self, *_args, **_kwargs)
  File "C:\Users\hughj\Documents\GitHub\asfl\env\lib\site-packages\flwr\simulation\ray_transport\ray_actor.py", line 63, in run
    raise ClientAppException(str(ex)) from ex
flwr.client.client_app.ClientAppException: 
Exception ClientAppException occurred. Message: Invalid partitioner: dirichlet : True

dv - | INFO flwr 2024-10-23 14:54:52,724 | server.py:240 | aggregate_fit: received 0 results and 3 failures
dv - | INFO flwr 2024-10-23 14:54:52,725 | server.py:178 | configure_evaluate: strategy sampled 3 clients (out of 3)
dv - | INFO flwr 2024-10-23 14:54:57,781 | server.py:192 | aggregate_evaluate: received 3 results and 0 failures
dv - | INFO flwr 2024-10-23 14:54:57,782 | fed_custom.py:227 | aggregated accuracy: 0.0871912808719128
dv - | INFO flwr 2024-10-23 14:54:57,782 | server.py:496 | 
dv - | INFO flwr 2024-10-23 14:54:57,783 | server.py:497 | [SUMMARY]
dv - | INFO flwr 2024-10-23 14:54:57,783 | server.py:498 | Run finished 1 round(s) in 14.13s
dv - | INFO flwr 2024-10-23 14:54:57,784 | server.py:500 | 	History (loss, distributed):
dv - | INFO flwr 2024-10-23 14:54:57,784 | server.py:500 | 		round 1: 244.65213478931057
dv - | INFO flwr 2024-10-23 14:54:57,785 | server.py:500 | 	History (metrics, distributed, evaluate):
dv - | INFO flwr 2024-10-23 14:54:57,785 | server.py:500 | 	{'accuracy': [(1, 0.0871912808719128)], 'count': [(1, 3)]}
dv - | INFO flwr 2024-10-23 14:54:57,786 | server.py:501 | 
dv - | DEBUG flwr 2024-10-23 14:54:57,789 | run_serverapp.py:90 | ServerApp finished running.
dv - | DEBUG flwr 2024-10-23 14:54:57,789 | run_simulation.py:349 | ServerApp finished running.
dv - | DEBUG flwr 2024-10-23 14:54:57,789 | run_simulation.py:353 | Triggered stop event for Simulation Engine.
dv - | DEBUG flwr 2024-10-23 14:54:58,789 | ray_actor.py:450 | Terminated 4 actors
dv - | DEBUG flwr 2024-10-23 14:54:59,602 | raybackend.py:184 | Terminated RayBackend
dv - | DEBUG flwr 2024-10-23 14:54:59,603 | run_simulation.py:452 | Stopping Simulation Engine now.
dv - | INFO flwr 2024-10-23 14:55:31,812 | server_app.py:88 | file writing: True
dv - | INFO flwr 2024-10-23 14:55:31,813 | server_app.py:89 | running in fed_acc
dv - | INFO flwr 2024-10-23 14:55:31,814 | server_app.py:90 | min num clients 2
dv - | INFO flwr 2024-10-23 14:55:31,815 | server_app.py:91 | num server rounds 1
dv - | INFO flwr 2024-10-23 14:55:31,815 | server_app.py:92 | config num local epochs 1
dv - | INFO flwr 2024-10-23 14:55:31,816 | server_app.py:93 | advanced logging False
dv - | INFO flwr 2024-10-23 14:55:31,817 | server_app.py:94 | partition: dirichlet
dv - | INFO flwr 2024-10-23 14:55:31,817 | app.py:74 | Starting Flower ServerApp, config: num_rounds=1, no round_timeout
dv - | INFO flwr 2024-10-23 14:55:31,818 | app.py:79 | 
dv - | INFO flwr 2024-10-23 14:55:31,820 | server.py:92 | [INIT]
dv - | INFO flwr 2024-10-23 14:55:31,821 | server.py:277 | Using initial global parameters provided by strategy
dv - | INFO flwr 2024-10-23 14:55:31,821 | server.py:94 | Starting evaluation of initial global parameters
dv - | INFO flwr 2024-10-23 14:55:31,821 | server.py:106 | Evaluation returned no results (`None`)
dv - | INFO flwr 2024-10-23 14:55:31,822 | server.py:112 | 
dv - | INFO flwr 2024-10-23 14:55:31,822 | server.py:113 | [ROUND 1]
dv - | INFO flwr 2024-10-23 14:55:31,823 | server.py:226 | configure_fit: strategy sampled 3 clients (out of 3)
dv - | DEBUG flwr 2024-10-23 14:55:34,852 | raybackend.py:136 | Constructed ActorPool with: 4 actors
dv - | DEBUG flwr 2024-10-23 14:55:34,852 | state_factory.py:50 | Using InMemoryState
dv - | INFO flwr 2024-10-23 14:56:04,101 | server.py:240 | aggregate_fit: received 3 results and 0 failures
dv - | INFO flwr 2024-10-23 14:56:04,104 | fed_acc.py:48 | 4
dv - | INFO flwr 2024-10-23 14:56:04,104 | fed_acc.py:48 | 4
dv - | INFO flwr 2024-10-23 14:56:04,105 | fed_acc.py:48 | 4
dv - | INFO flwr 2024-10-23 14:56:04,105 | dat.py:19 | weighted test: [0.2416013437849944, 0.2289026691830682, 0.2213235294117647]
dv - | INFO flwr 2024-10-23 14:56:04,107 | server.py:178 | configure_evaluate: strategy sampled 3 clients (out of 3)
dv - | INFO flwr 2024-10-23 14:56:06,140 | server.py:192 | aggregate_evaluate: received 3 results and 0 failures
dv - | INFO flwr 2024-10-23 14:56:06,142 | fed_custom.py:227 | aggregated accuracy: 0.10648935106489352
dv - | INFO flwr 2024-10-23 14:56:06,142 | server.py:496 | 
dv - | INFO flwr 2024-10-23 14:56:06,143 | server.py:497 | [SUMMARY]
dv - | INFO flwr 2024-10-23 14:56:06,144 | server.py:498 | Run finished 1 round(s) in 34.32s
dv - | INFO flwr 2024-10-23 14:56:06,145 | server.py:500 | 	History (loss, distributed):
dv - | INFO flwr 2024-10-23 14:56:06,145 | server.py:500 | 		round 1: 244.2156376915447
dv - | INFO flwr 2024-10-23 14:56:06,146 | server.py:500 | 	History (metrics, distributed, evaluate):
dv - | INFO flwr 2024-10-23 14:56:06,147 | server.py:500 | 	{'accuracy': [(1, 0.10648935106489352)], 'count': [(1, 3)]}
dv - | INFO flwr 2024-10-23 14:56:06,147 | server.py:501 | 
dv - | DEBUG flwr 2024-10-23 14:56:06,150 | run_serverapp.py:90 | ServerApp finished running.
dv - | DEBUG flwr 2024-10-23 14:56:06,150 | run_simulation.py:349 | ServerApp finished running.
dv - | DEBUG flwr 2024-10-23 14:56:06,151 | run_simulation.py:353 | Triggered stop event for Simulation Engine.
dv - | DEBUG flwr 2024-10-23 14:56:07,128 | ray_actor.py:450 | Terminated 4 actors
dv - | DEBUG flwr 2024-10-23 14:56:07,929 | raybackend.py:184 | Terminated RayBackend
dv - | DEBUG flwr 2024-10-23 14:56:07,930 | run_simulation.py:452 | Stopping Simulation Engine now.
